Workbook

Sheet 美森360
A1: 应付 | B1: 上海——LB | F1: 费用类型 | G1: 币种 | H1: 单价 | I1: 数量 | J1: 备注 | K1: 统计 | N1: 拆送分段成本（KG） | P1: 组合分段成本（KG） | R1: 整柜直送分段成本 | T1: 拆送分段成本（CBM） | V1: 组合分段成本（CBM） | X1: 整柜直送分段成本（CBM）
B2: 起运港 | C2: 拖车+报关 | F2: 装柜费 | G2: RMB | H2: 500 | I2: 1 | N2: =H2/H12 -> 0.03992016 | P2: =H2/H12 -> 0.03992016 | R2: =H2/H12 -> 0.03992016 | T2: =H2/$B$12 -> 6.6666667 | V2: =H2/B12 -> 6.6666667 | X2: =H2/B12 -> 6.6666667
F3: 拖车费 | G3: RMB | H3: 9000 | I3: 1 | N3: =H3/H12 -> 0.71856287 | P3: =H3/H12 -> 0.71856287 | R3: =H3/H12 -> 0.71856287 | T3: =H3/$B$12 -> 120 | V3: =H3/B12 -> 120 | X3: =H3/B12 -> 120
F4: 报关费 | G4: RMB | H4: 1800 | I4: 1 | N4: =H4/H12 -> 0.14371257 | P4: =H4/H12 -> 0.14371257 | R4: =H4/H12 -> 0.14371257 | T4: =H4/$B$12 -> 24 | V4: =H4/B12 -> 24 | X4: =H4/B12 -> 24
F5: 港杂费RMB部分 | G5: RMB | H5: 3000 | I5: 1 | N5: =H5/H12 -> 0.23952096 | P5: =H5/H12 -> 0.23952096 | R5: =H5/H12 -> 0.23952096 | T5: =H5/$B$12 -> 40 | V5: =H5/B12 -> 40 | X5: =H5/B12 -> 40
F6: 海运费（变动） | G6: USD | H6: 10429 | I6: 1 | N6: =H6*7/H12 -> 5.8285828 | P6: =H6*7/H12 -> 5.8285828 | R6: =H6*J10/H12 -> 5.8285828 | T6: =H6/$B$12*7 -> 973.37333 | V6: =H6*7/B12 -> 973.37333 | X6: =H6*7/B12 -> 973.37333
B7: 目的港 | C7: 提柜+拆柜 | F7: 提拆一口价 | G7: USD | H7: 1480 | I7: 1 | N7: =H7*J10/H12 -> 0.82714571 | T7: =H7/$B$12*7 -> 138.13333
C8: 清关+缴税 | F8: 清关费 | G8: USD | I8: 1 | T8: =H8/$B$12*7 -> 0
F9: 税金 | G9: USD | H9: 1500 | L9: 每板KG | N9: =H9*J10/H12 -> 0.83832335 | P9: =H9*7/H12 -> 0.83832335 | R9: =H9*J10/H12 -> 0.83832335 | T9: =H9/$B$12*7 -> 140 | V9: =H9*J10/B12 -> 140 | X9: =H9*J10/B12 -> 140
A10: 上海-LB | B10: 人民币应付 | G10: RMB | H10: =SUM(H2:H5) -> 14300 | I10: 汇率 | J10: 7 | K10: =H10/J10 -> 2042.8571 | L10: 350 | N10: =(C15*J10)/L10 -> 0.6
A11: 报价：2025/03/16 | B11: 含税KG/CBM | G11: USD | H11: =SUM(H6:H9) -> 13409 | I11: 合计 | J11: =H11+K10 -> 15451.857 | K11: =J11*J10 -> 108163 | L11: CBM
A12: CBM标准 | B12: 75 | E12: CBM计费标准 | F12: =K11/B12 -> 1442.1733 | G12: KG标准 | H12: 12525 | I12: KG计费标准 | J12: =F12/167 -> 8.6357685 | L12: 1.8
B13: 派送费 | C13: 美金/板 | D13: 组合一口价 | E13: 整柜一口价 | F13: 拆送KG含税 | G13: 组合KG | H13: 直送KG | I13: 拆送CBM含税 | J13: 组合CBM | K13: 直送CBM | L13: 直客报价101KG+ | M13: 拆送末端（KG） | N13: 拆送头程（KG） | O13: 组合末端（KG） | P13: 组合头程（KG） | Q13: 整柜直送末端（KG） | R13: 整柜直送头程（KG） | S13: 拆送末端（m³） | T13: 拆送头程（m³） | U13: 组合末端（m³） | V13: 组合头程（m³） | W13: 整柜直送末端（m³） | X13: 整柜直送头程（m³）
A14: 美西 一区 | B14: ONT8 | C14: 30 | D14: 1980 | E14: 1430 | F14: =$J$12+(C14*$J$10/$L$10) -> 9.2357685 | G14: =IF(D14="","",($J$11-$H$7+D14)*$J$10/$H$12) -> 8.9152096 | H14: =IF(E14="","",($J$11-$H$7+E14)*$J$10/$H$12) -> 8.6078244 | I14: =$F$12+(C14*$J$10/$L$12) -> 1558.84 | J14: =IF(D14="","",($J$11-$H$7+D14)*$J$10/$B$12) -> 1488.84 | K14: =IF(E14="","",($J$11-$H$7+E14)*$J$10/$B$12) -> 1437.5067 | L14: 10.1 | M14: =C14*J10/L10 -> 0.6 | N14: =SUM(N2:N9) -> 8.6357685 | O14: =D14*J10/H12 -> 1.1065868 | P14: =(J11-H7)*J10/H12 -> 7.8086228 | Q14: =E14*J10/H12 -> 0.7992016 | R14: =SUM(R2:R9) -> 7.8086228 | S14: =C14*J10/L12 -> 116.66667 | T14: =K11/B12 -> 1442.1733 | U14: =D14*J10/B12 -> 184.8 | V14: =(J11-H7)*J10/B12 -> 1304.04 | W14: =E14*J10/B12 -> 133.46667 | X14: =SUM(X2:X9) -> 1304.04
B15: LGB8 | C15: 30 | D15: 1980 | E15: 1430 | F15: =$J$12+(C15*$J$10/$L$10) -> 9.2357685 | G15: =IF(D15="","",($J$11-$H$7+D15)*$J$10/$H$12) -> 8.9152096 | H15: =IF(E15="","",($J$11-$H$7+E15)*$J$10/$H$12) -> 8.6078244 | I15: =$F$12+(C15*$J$10/$L$12) -> 1558.84 | J15: =IF(D15="","",($J$11-$H$7+D15)*$J$10/$B$12) -> 1488.84 | K15: =IF(E15="","",($J$11-$H$7+E15)*$J$10/$B$12) -> 1437.5067 | L15: 10.1
B16: SBD1 | C16: 35 | D16: 1980 | E16: 1430 | F16: =$J$12+(C16*$J$10/$L$10) -> 9.3357685 | G16: =IF(D16="","",($J$11-$H$7+D16)*$J$10/$H$12) -> 8.9152096 | H16: =IF(E16="","",($J$11-$H$7+E16)*$J$10/$H$12) -> 8.6078244 | I16: =$F$12+(C16*$J$10/$L$12) -> 1578.2844 | J16: =IF(D16="","",($J$11-$H$7+D16)*$J$10/$B$12) -> 1488.84 | K16: =IF(E16="","",($J$11-$H$7+E16)*$J$10/$B$12) -> 1437.5067 | L16: 10.1
B17: LAX9 | C17: 30 | D17: 1980 | E17: 1430 | F17: =$J$12+(C17*$J$10/$L$10) -> 9.2357685 | G17: =IF(D17="","",($J$11-$H$7+D17)*$J$10/$H$12) -> 8.9152096 | H17: =IF(E17="","",($J$11-$H$7+E17)*$J$10/$H$12) -> 8.6078244 | I17: =$F$12+(C17*$J$10/$L$12) -> 1558.84 | J17: =IF(D17="","",($J$11-$H$7+D17)*$J$10/$B$12) -> 1488.84 | K17: =IF(E17="","",($J$11-$H$7+E17)*$J$10/$B$12) -> 1437.5067 | L17: 10.1
A18: 美西 二区 | B18: SMF3 | C18: 70 | D18: 2980 | E18: 2730 | F18: =$J$12+(C18*$J$10/$L$10) -> 10.035768 | G18: =IF(D18="","",($J$11-$H$7+D18)*$J$10/$H$12) -> 9.4740918 | H18: =IF(E18="","",($J$11-$H$7+E18)*$J$10/$H$12) -> 9.3343713 | I18: =$F$12+(C18*$J$10/$L$12) -> 1714.3956 | J18: =IF(D18="","",($J$11-$H$7+D18)*$J$10/$B$12) -> 1582.1733 | K18: =IF(E18="","",($J$11-$H$7+E18)*$J$10/$B$12) -> 1558.84 | L18: 10.9
B19: SCK4 | C19: 70 | D19: 2980 | E19: 2730 | F19: =$J$12+(C19*$J$10/$L$10) -> 10.035768 | G19: =IF(D19="","",($J$11-$H$7+D19)*$J$10/$H$12) -> 9.4740918 | H19: =IF(E19="","",($J$11-$H$7+E19)*$J$10/$H$12) -> 9.3343713 | I19: =$F$12+(C19*$J$10/$L$12) -> 1714.3956 | J19: =IF(D19="","",($J$11-$H$7+D19)*$J$10/$B$12) -> 1582.1733 | K19: =IF(E19="","",($J$11-$H$7+E19)*$J$10/$B$12) -> 1558.84 | L19: 10.9
B20: GYR2 | C20: 70 | D20: 2980 | E20: 2530 | F20: =$J$12+(C20*$J$10/$L$10) -> 10.035768 | G20: =IF(D20="","",($J$11-$H$7+D20)*$J$10/$H$12) -> 9.4740918 | H20: =IF(E20="","",($J$11-$H$7+E20)*$J$10/$H$12) -> 9.2225948 | I20: =$F$12+(C20*$J$10/$L$12) -> 1714.3956 | J20: =IF(D20="","",($J$11-$H$7+D20)*$J$10/$B$12) -> 1582.1733 | K20: =IF(E20="","",($J$11-$H$7+E20)*$J$10/$B$12) -> 1540.1733 | L20: 10.9
B21: GYR3 | C21: 70 | D21: 2980 | E21: 2530 | F21: =$J$12+(C21*$J$10/$L$10) -> 10.035768 | G21: =IF(D21="","",($J$11-$H$7+D21)*$J$10/$H$12) -> 9.4740918 | H21: =IF(E21="","",($J$11-$H$7+E21)*$J$10/$H$12) -> 9.2225948 | I21: =$F$12+(C21*$J$10/$L$12) -> 1714.3956 | J21: =IF(D21="","",($J$11-$H$7+D21)*$J$10/$B$12) -> 1582.1733 | K21: =IF(E21="","",($J$11-$H$7+E21)*$J$10/$B$12) -> 1540.1733 | L21: 10.9
B22: LAS1 | C22: 70 | D22: 2980 | E22: 2430 | F22: =$J$12+(C22*$J$10/$L$10) -> 10.035768 | G22: =IF(D22="","",($J$11-$H$7+D22)*$J$10/$H$12) -> 9.4740918 | H22: =IF(E22="","",($J$11-$H$7+E22)*$J$10/$H$12) -> 9.1667066 | I22: =$F$12+(C22*$J$10/$L$12) -> 1714.3956 | J22: =IF(D22="","",($J$11-$H$7+D22)*$J$10/$B$12) -> 1582.1733 | K22: =IF(E22="","",($J$11-$H$7+E22)*$J$10/$B$12) -> 1530.84 | L22: 10.9
B23: VGT2 | C23: 70 | D23: 2980 | E23: 2430 | F23: =$J$12+(C23*$J$10/$L$10) -> 10.035768 | G23: =IF(D23="","",($J$11-$H$7+D23)*$J$10/$H$12) -> 9.4740918 | H23: =IF(E23="","",($J$11-$H$7+E23)*$J$10/$H$12) -> 9.1667066 | I23: =$F$12+(C23*$J$10/$L$12) -> 1714.3956 | J23: =IF(D23="","",($J$11-$H$7+D23)*$J$10/$B$12) -> 1582.1733 | K23: =IF(E23="","",($J$11-$H$7+E23)*$J$10/$B$12) -> 1530.84 | L23: 10.9
A24: 美西 三区 | B24: POC1 | C24: 55 | D24: 2180 | E24: 1430 | F24: =$J$12+(C24*$J$10/$L$10) -> 9.7357685 | G24: =IF(D24="","",($J$11-$H$7+D24)*$J$10/$H$12) -> 9.026986 | H24: =IF(E24="","",($J$11-$H$7+E24)*$J$10/$H$12) -> 8.6078244 | I24: =$F$12+(C24*$J$10/$L$12) -> 1656.0622 | J24: =IF(D24="","",($J$11-$H$7+D24)*$J$10/$B$12) -> 1507.5067 | K24: =IF(E24="","",($J$11-$H$7+E24)*$J$10/$B$12) -> 1437.5067 | L24: 10.1
B25: POC2 | C25: 55 | D25: 2180 | F25: =$J$12+(C25*$J$10/$L$10) -> 9.7357685 | G25: =IF(D25="","",($J$11-$H$7+D25)*$J$10/$H$12) -> 9.026986 | H25: =IF(E25="","",($J$11-$H$7+E25)*$J$10/$H$12) | I25: =$F$12+(C25*$J$10/$L$12) -> 1656.0622 | J25: =IF(D25="","",($J$11-$H$7+D25)*$J$10/$B$12) -> 1507.5067 | K25: =IF(E25="","",($J$11-$H$7+E25)*$J$10/$B$12) | L25: 10.1
B26: POC3 | C26: 55 | D26: 2180 | E26: 1430 | F26: =$J$12+(C26*$J$10/$L$10) -> 9.7357685 | G26: =IF(D26="","",($J$11-$H$7+D26)*$J$10/$H$12) -> 9.026986 | H26: =IF(E26="","",($J$11-$H$7+E26)*$J$10/$H$12) -> 8.6078244 | I26: =$F$12+(C26*$J$10/$L$12) -> 1656.0622 | J26: =IF(D26="","",($J$11-$H$7+D26)*$J$10/$B$12) -> 1507.5067 | K26: =IF(E26="","",($J$11-$H$7+E26)*$J$10/$B$12) -> 1437.5067 | L26: 10.1
B27: SNA4 | C27: 50 | D27: 2180 | E27: 1480 | F27: =$J$12+(C27*$J$10/$L$10) -> 9.6357685 | G27: =IF(D27="","",($J$11-$H$7+D27)*$J$10/$H$12) -> 9.026986 | H27: =IF(E27="","",($J$11-$H$7+E27)*$J$10/$H$12) -> 8.6357685 | I27: =$F$12+(C27*$J$10/$L$12) -> 1636.6178 | J27: =IF(D27="","",($J$11-$H$7+D27)*$J$10/$B$12) -> 1507.5067 | K27: =IF(E27="","",($J$11-$H$7+E27)*$J$10/$B$12) -> 1442.1733
B28: KRB1 | C28: 50 | D28: 2180 | F28: =$J$12+(C28*$J$10/$L$10) -> 9.6357685 | G28: =IF(D28="","",($J$11-$H$7+D28)*$J$10/$H$12) -> 9.026986 | H28: =IF(E28="","",($J$11-$H$7+E28)*$J$10/$H$12) | I28: =$F$12+(C28*$J$10/$L$12) -> 1636.6178 | J28: =IF(D28="","",($J$11-$H$7+D28)*$J$10/$B$12) -> 1507.5067 | K28: =IF(E28="","",($J$11-$H$7+E28)*$J$10/$B$12)
B29: KRB4 | C29: 50 | D29: 2180 | F29: =$J$12+(C29*$J$10/$L$10) -> 9.6357685 | G29: =IF(D29="","",($J$11-$H$7+D29)*$J$10/$H$12) -> 9.026986 | H29: =IF(E29="","",($J$11-$H$7+E29)*$J$10/$H$12) | I29: =$F$12+(C29*$J$10/$L$12) -> 1636.6178 | J29: =IF(D29="","",($J$11-$H$7+D29)*$J$10/$B$12) -> 1507.5067 | K29: =IF(E29="","",($J$11-$H$7+E29)*$J$10/$B$12)
B30: IUSJ | C30: 65 | D30: 2180 | E30: 1580 | F30: =$J$12+(C30*$J$10/$L$10) -> 9.9357685 | G30: =IF(D30="","",($J$11-$H$7+D30)*$J$10/$H$12) -> 9.026986 | H30: =IF(E30="","",($J$11-$H$7+E30)*$J$10/$H$12) -> 8.6916567 | I30: =$F$12+(C30*$J$10/$L$12) -> 1694.9511 | J30: =IF(D30="","",($J$11-$H$7+D30)*$J$10/$B$12) -> 1507.5067 | K30: =IF(E30="","",($J$11-$H$7+E30)*$J$10/$B$12) -> 1451.5067 | L30: 10.6
B31: IUSP | C31: 65 | D31: 2180 | E31: 1580 | F31: =$J$12+(C31*$J$10/$L$10) -> 9.9357685 | G31: =IF(D31="","",($J$11-$H$7+D31)*$J$10/$H$12) -> 9.026986 | H31: =IF(E31="","",($J$11-$H$7+E31)*$J$10/$H$12) -> 8.6916567 | I31: =$F$12+(C31*$J$10/$L$12) -> 1694.9511 | J31: =IF(D31="","",($J$11-$H$7+D31)*$J$10/$B$12) -> 1507.5067 | K31: =IF(E31="","",($J$11-$H$7+E31)*$J$10/$B$12) -> 1451.5067 | L31: 10.6
B32: IUSQ | C32: 65 | D32: 2180 | E32: 1580 | F32: =$J$12+(C32*$J$10/$L$10) -> 9.9357685 | G32: =IF(D32="","",($J$11-$H$7+D32)*$J$10/$H$12) -> 9.026986 | H32: =IF(E32="","",($J$11-$H$7+E32)*$J$10/$H$12) -> 8.6916567 | I32: =$F$12+(C32*$J$10/$L$12) -> 1694.9511 | J32: =IF(D32="","",($J$11-$H$7+D32)*$J$10/$B$12) -> 1507.5067 | K32: =IF(E32="","",($J$11-$H$7+E32)*$J$10/$B$12) -> 1451.5067 | L32: 10.6
A33: 美西 四区 | B33: GEU3 | C33: 85 | D33: 3180 | E33: 2750 | F33: =$J$12+(C33*$J$10/$L$10) -> 10.335768 | G33: =IF(D33="","",($J$11-$H$7+D33)*$J$10/$H$12) -> 9.5858683 | H33: =IF(E33="","",($J$11-$H$7+E33)*$J$10/$H$12) -> 9.3455489 | I33: =$F$12+(C33*$J$10/$L$12) -> 1772.7289 | J33: =IF(D33="","",($J$11-$H$7+D33)*$J$10/$B$12) -> 1600.84 | K33: =IF(E33="","",($J$11-$H$7+E33)*$J$10/$B$12) -> 1560.7067 | L33: 10.9
B34: GEU2 | C34: 85 | D34: 3180 | E34: 2750 | F34: =$J$12+(C34*$J$10/$L$10) -> 10.335768 | G34: =IF(D34="","",($J$11-$H$7+D34)*$J$10/$H$12) -> 9.5858683 | H34: =IF(E34="","",($J$11-$H$7+E34)*$J$10/$H$12) -> 9.3455489 | I34: =$F$12+(C34*$J$10/$L$12) -> 1772.7289 | J34: =IF(D34="","",($J$11-$H$7+D34)*$J$10/$B$12) -> 1600.84 | K34: =IF(E34="","",($J$11-$H$7+E34)*$J$10/$B$12) -> 1560.7067 | L34: 10.9
B35: MIT2 | C35: 85 | D35: 3180 | E35: 2500 | F35: =$J$12+(C35*$J$10/$L$10) -> 10.335768 | G35: =IF(D35="","",($J$11-$H$7+D35)*$J$10/$H$12) -> 9.5858683 | H35: =IF(E35="","",($J$11-$H$7+E35)*$J$10/$H$12) -> 9.2058283 | I35: =$F$12+(C35*$J$10/$L$12) -> 1772.7289 | J35: =IF(D35="","",($J$11-$H$7+D35)*$J$10/$B$12) -> 1600.84 | K35: =IF(E35="","",($J$11-$H$7+E35)*$J$10/$B$12) -> 1537.3733 | L35: 10.9
B36: OAK3 | C36: 85 | D36: 3180 | F36: =$J$12+(C36*$J$10/$L$10) -> 10.335768 | G36: =IF(D36="","",($J$11-$H$7+D36)*$J$10/$H$12) -> 9.5858683 | H36: =IF(E36="","",($J$11-$H$7+E36)*$J$10/$H$12) | I36: =$F$12+(C36*$J$10/$L$12) -> 1772.7289 | J36: =IF(D36="","",($J$11-$H$7+D36)*$J$10/$B$12) -> 1600.84 | K36: =IF(E36="","",($J$11-$H$7+E36)*$J$10/$B$12)
B37: LAS6 | C37: 85 | D37: 3180 | E37: 2480 | F37: =$J$12+(C37*$J$10/$L$10) -> 10.335768 | G37: =IF(D37="","",($J$11-$H$7+D37)*$J$10/$H$12) -> 9.5858683 | H37: =IF(E37="","",($J$11-$H$7+E37)*$J$10/$H$12) -> 9.1946507 | I37: =$F$12+(C37*$J$10/$L$12) -> 1772.7289 | J37: =IF(D37="","",($J$11-$H$7+D37)*$J$10/$B$12) -> 1600.84 | K37: =IF(E37="","",($J$11-$H$7+E37)*$J$10/$B$12) -> 1535.5067
B38: SMF6 | C38: 85 | D38: 3180 | F38: =$J$12+(C38*$J$10/$L$10) -> 10.335768 | G38: =IF(D38="","",($J$11-$H$7+D38)*$J$10/$H$12) -> 9.5858683 | H38: =IF(E38="","",($J$11-$H$7+E38)*$J$10/$H$12) | I38: =$F$12+(C38*$J$10/$L$12) -> 1772.7289 | J38: =IF(D38="","",($J$11-$H$7+D38)*$J$10/$B$12) -> 1600.84 | K38: =IF(E38="","",($J$11-$H$7+E38)*$J$10/$B$12)
B39: SCK8 | C39: 85 | D39: 3180 | F39: =$J$12+(C39*$J$10/$L$10) -> 10.335768 | G39: =IF(D39="","",($J$11-$H$7+D39)*$J$10/$H$12) -> 9.5858683 | H39: =IF(E39="","",($J$11-$H$7+E39)*$J$10/$H$12) | I39: =$F$12+(C39*$J$10/$L$12) -> 1772.7289 | J39: =IF(D39="","",($J$11-$H$7+D39)*$J$10/$B$12) -> 1600.84 | K39: =IF(E39="","",($J$11-$H$7+E39)*$J$10/$B$12) | L39: 10.9
B40: GEU5 | C40: 85 | D40: 3180 | E40: 2750 | F40: =$J$12+(C40*$J$10/$L$10) -> 10.335768 | G40: =IF(D40="","",($J$11-$H$7+D40)*$J$10/$H$12) -> 9.5858683 | H40: =IF(E40="","",($J$11-$H$7+E40)*$J$10/$H$12) -> 9.3455489 | I40: =$F$12+(C40*$J$10/$L$12) -> 1772.7289 | J40: =IF(D40="","",($J$11-$H$7+D40)*$J$10/$B$12) -> 1600.84 | K40: =IF(E40="","",($J$11-$H$7+E40)*$J$10/$B$12) -> 1560.7067
...

Sheet 美森432
A1: 应付 | B1: 上海——LB | F1: 费用类型 | G1: 币种 | H1: 单价 | I1: 数量 | J1: 备注 | K1: 统计
B2: 起运港 | C2: 拖车+报关 | F2: 装柜费 | G2: RMB | H2: 500 | I2: 1
F3: 拖车费 | G3: RMB | H3: 9000 | I3: 1
F4: 报关费 | G4: RMB | H4: 1800 | I4: 1
F5: 港杂费RMB部分 | G5: RMB | H5: 3000 | I5: 1
F6: 海运费（变动） | G6: USD | H6: 9104 | I6: 1
B7: 目的港 | C7: 提柜+拆柜 | F7: 提拆一口价 | G7: USD | H7: 1480 | I7: 1
C8: 清关+缴税 | F8: 清关费 | G8: USD | I8: 1
F9: 税金 | G9: USD | H9: 1800 | I9: 1 | L9: 每板KG
A10: 上海-LB | B10: 人民币应付 | G10: RMB | H10: =SUM(H2:H5) -> 14300 | I10: 汇率 | J10: 7 | K10: =H10/J10 -> 2042.8571 | L10: 350
A11: 报价：2025/03/16 | B11: 含税KG/CBM | G11: USD | H11: =SUM(H6:H9) -> 12384 | I11: 合计 | J11: =H11+K10 -> 14426.857 | K11: =J11*J10 -> 100988 | L11: CBM
A12: CBM标准 | B12: 75 | E12: CBM计费标准 | F12: =K11/B12 -> 1346.5067 | G12: KG标准 | H12: 12525 | I12: KG计费标准 | J12: =F12/167 -> 8.0629142 | L12: 1.8
B13: 派送费 | C13: 美金/板 | D13: 组合一口价 | E13: 整柜一口价 | F13: 拆送KG含税 | G13: 组合KG | H13: 直送KG | I13: 拆送CBM含税 | J13: 组合CBM | K13: 直送CBM | L13: 直客报价101KG+
A14: 美西 一区 | B14: ONT8 | C14: 30 | D14: 1980 | E14: 1430 | F14: =$J$12+(C14*$J$10/$L$10) -> 8.6629142 | G14: =IF(D14="","",($J$11-$H$7+D14)*$J$10/$H$12) -> 8.3423553 | H14: =IF(E14="","",($J$11-$H$7+E14)*$J$10/$H$12) -> 8.0349701 | I14: =$F$12+(C14*$J$10/$L$12) -> 1463.1733 | J14: =IF(D14="","",($J$11-$H$7+D14)*$J$10/$B$12) -> 1393.1733 | K14: =IF(E14="","",($J$11-$H$7+E14)*$J$10/$B$12) -> 1341.84 | L14: 9.8
B15: LGB8 | C15: 30 | D15: 1980 | E15: 1430 | F15: =$J$12+(C15*$J$10/$L$10) -> 8.6629142 | G15: =IF(D15="","",($J$11-$H$7+D15)*$J$10/$H$12) -> 8.3423553 | H15: =IF(E15="","",($J$11-$H$7+E15)*$J$10/$H$12) -> 8.0349701 | I15: =$F$12+(C15*$J$10/$L$12) -> 1463.1733 | J15: =IF(D15="","",($J$11-$H$7+D15)*$J$10/$B$12) -> 1393.1733 | K15: =IF(E15="","",($J$11-$H$7+E15)*$J$10/$B$12) -> 1341.84 | L15: 9.8
B16: SBD1 | C16: 35 | D16: 1980 | E16: 1430 | F16: =$J$12+(C16*$J$10/$L$10) -> 8.7629142 | G16: =IF(D16="","",($J$11-$H$7+D16)*$J$10/$H$12) -> 8.3423553 | H16: =IF(E16="","",($J$11-$H$7+E16)*$J$10/$H$12) -> 8.0349701 | I16: =$F$12+(C16*$J$10/$L$12) -> 1482.6178 | J16: =IF(D16="","",($J$11-$H$7+D16)*$J$10/$B$12) -> 1393.1733 | K16: =IF(E16="","",($J$11-$H$7+E16)*$J$10/$B$12) -> 1341.84 | L16: 9.8
B17: LAX9 | C17: 30 | D17: 1980 | E17: 1430 | F17: =$J$12+(C17*$J$10/$L$10) -> 8.6629142 | G17: =IF(D17="","",($J$11-$H$7+D17)*$J$10/$H$12) -> 8.3423553 | H17: =IF(E17="","",($J$11-$H$7+E17)*$J$10/$H$12) -> 8.0349701 | I17: =$F$12+(C17*$J$10/$L$12) -> 1463.1733 | J17: =IF(D17="","",($J$11-$H$7+D17)*$J$10/$B$12) -> 1393.1733 | K17: =IF(E17="","",($J$11-$H$7+E17)*$J$10/$B$12) -> 1341.84 | L17: 9.8
A18: 美西 二区 | B18: SMF3 | C18: 70 | D18: 2980 | E18: 2730 | F18: =$J$12+(C18*$J$10/$L$10) -> 9.4629142 | G18: =IF(D18="","",($J$11-$H$7+D18)*$J$10/$H$12) -> 8.9012375 | H18: =IF(E18="","",($J$11-$H$7+E18)*$J$10/$H$12) -> 8.761517 | I18: =$F$12+(C18*$J$10/$L$12) -> 1618.7289 | J18: =IF(D18="","",($J$11-$H$7+D18)*$J$10/$B$12) -> 1486.5067 | K18: =IF(E18="","",($J$11-$H$7+E18)*$J$10/$B$12) -> 1463.1733 | L18: 10.6
B19: SCK4 | C19: 70 | D19: 2980 | E19: 2730 | F19: =$J$12+(C19*$J$10/$L$10) -> 9.4629142 | G19: =IF(D19="","",($J$11-$H$7+D19)*$J$10/$H$12) -> 8.9012375 | H19: =IF(E19="","",($J$11-$H$7+E19)*$J$10/$H$12) -> 8.761517 | I19: =$F$12+(C19*$J$10/$L$12) -> 1618.7289 | J19: =IF(D19="","",($J$11-$H$7+D19)*$J$10/$B$12) -> 1486.5067 | K19: =IF(E19="","",($J$11-$H$7+E19)*$J$10/$B$12) -> 1463.1733 | L19: 10.6
B20: GYR2 | C20: 70 | D20: 2980 | E20: 2530 | F20: =$J$12+(C20*$J$10/$L$10) -> 9.4629142 | G20: =IF(D20="","",($J$11-$H$7+D20)*$J$10/$H$12) -> 8.9012375 | H20: =IF(E20="","",($J$11-$H$7+E20)*$J$10/$H$12) -> 8.6497405 | I20: =$F$12+(C20*$J$10/$L$12) -> 1618.7289 | J20: =IF(D20="","",($J$11-$H$7+D20)*$J$10/$B$12) -> 1486.5067 | K20: =IF(E20="","",($J$11-$H$7+E20)*$J$10/$B$12) -> 1444.5067 | L20: 10.6
B21: GYR3 | C21: 70 | D21: 2980 | E21: 2530 | F21: =$J$12+(C21*$J$10/$L$10) -> 9.4629142 | G21: =IF(D21="","",($J$11-$H$7+D21)*$J$10/$H$12) -> 8.9012375 | H21: =IF(E21="","",($J$11-$H$7+E21)*$J$10/$H$12) -> 8.6497405 | I21: =$F$12+(C21*$J$10/$L$12) -> 1618.7289 | J21: =IF(D21="","",($J$11-$H$7+D21)*$J$10/$B$12) -> 1486.5067 | K21: =IF(E21="","",($J$11-$H$7+E21)*$J$10/$B$12) -> 1444.5067 | L21: 10.6
B22: LAS1 | C22: 70 | D22: 2980 | E22: 2430 | F22: =$J$12+(C22*$J$10/$L$10) -> 9.4629142 | G22: =IF(D22="","",($J$11-$H$7+D22)*$J$10/$H$12) -> 8.9012375 | H22: =IF(E22="","",($J$11-$H$7+E22)*$J$10/$H$12) -> 8.5938523 | I22: =$F$12+(C22*$J$10/$L$12) -> 1618.7289 | J22: =IF(D22="","",($J$11-$H$7+D22)*$J$10/$B$12) -> 1486.5067 | K22: =IF(E22="","",($J$11-$H$7+E22)*$J$10/$B$12) -> 1435.1733 | L22: 10.6
B23: VGT2 | C23: 70 | D23: 2980 | E23: 2430 | F23: =$J$12+(C23*$J$10/$L$10) -> 9.4629142 | G23: =IF(D23="","",($J$11-$H$7+D23)*$J$10/$H$12) -> 8.9012375 | H23: =IF(E23="","",($J$11-$H$7+E23)*$J$10/$H$12) -> 8.5938523 | I23: =$F$12+(C23*$J$10/$L$12) -> 1618.7289 | J23: =IF(D23="","",($J$11-$H$7+D23)*$J$10/$B$12) -> 1486.5067 | K23: =IF(E23="","",($J$11-$H$7+E23)*$J$10/$B$12) -> 1435.1733 | L23: 10.6
A24: 美西 三区 | B24: POC1 | C24: 55 | D24: 2180 | E24: 1430 | F24: =$J$12+(C24*$J$10/$L$10) -> 9.1629142 | G24: =IF(D24="","",($J$11-$H$7+D24)*$J$10/$H$12) -> 8.4541317 | H24: =IF(E24="","",($J$11-$H$7+E24)*$J$10/$H$12) -> 8.0349701 | I24: =$F$12+(C24*$J$10/$L$12) -> 1560.3956 | J24: =IF(D24="","",($J$11-$H$7+D24)*$J$10/$B$12) -> 1411.84 | K24: =IF(E24="","",($J$11-$H$7+E24)*$J$10/$B$12) -> 1341.84 | L24: 9.8
B25: POC2 | C25: 55 | D25: 2180 | F25: =$J$12+(C25*$J$10/$L$10) -> 9.1629142 | G25: =IF(D25="","",($J$11-$H$7+D25)*$J$10/$H$12) -> 8.4541317 | H25: =IF(E25="","",($J$11-$H$7+E25)*$J$10/$H$12) | I25: =$F$12+(C25*$J$10/$L$12) -> 1560.3956 | J25: =IF(D25="","",($J$11-$H$7+D25)*$J$10/$B$12) -> 1411.84 | K25: =IF(E25="","",($J$11-$H$7+E25)*$J$10/$B$12) | L25: 9.8
B26: POC3 | C26: 55 | D26: 2180 | E26: 1430 | F26: =$J$12+(C26*$J$10/$L$10) -> 9.1629142 | G26: =IF(D26="","",($J$11-$H$7+D26)*$J$10/$H$12) -> 8.4541317 | H26: =IF(E26="","",($J$11-$H$7+E26)*$J$10/$H$12) -> 8.0349701 | I26: =$F$12+(C26*$J$10/$L$12) -> 1560.3956 | J26: =IF(D26="","",($J$11-$H$7+D26)*$J$10/$B$12) -> 1411.84 | K26: =IF(E26="","",($J$11-$H$7+E26)*$J$10/$B$12) -> 1341.84 | L26: 9.8
B27: SNA4 | C27: 50 | D27: 2180 | E27: 1480 | F27: =$J$12+(C27*$J$10/$L$10) -> 9.0629142 | G27: =IF(D27="","",($J$11-$H$7+D27)*$J$10/$H$12) -> 8.4541317 | H27: =IF(E27="","",($J$11-$H$7+E27)*$J$10/$H$12) -> 8.0629142 | I27: =$F$12+(C27*$J$10/$L$12) -> 1540.9511 | J27: =IF(D27="","",($J$11-$H$7+D27)*$J$10/$B$12) -> 1411.84 | K27: =IF(E27="","",($J$11-$H$7+E27)*$J$10/$B$12) -> 1346.5067
B28: KRB1 | C28: 50 | D28: 2180 | F28: =$J$12+(C28*$J$10/$L$10) -> 9.0629142 | G28: =IF(D28="","",($J$11-$H$7+D28)*$J$10/$H$12) -> 8.4541317 | H28: =IF(E28="","",($J$11-$H$7+E28)*$J$10/$H$12) | I28: =$F$12+(C28*$J$10/$L$12) -> 1540.9511 | J28: =IF(D28="","",($J$11-$H$7+D28)*$J$10/$B$12) -> 1411.84 | K28: =IF(E28="","",($J$11-$H$7+E28)*$J$10/$B$12)
B29: KRB4 | C29: 50 | D29: 2180 | F29: =$J$12+(C29*$J$10/$L$10) -> 9.0629142 | G29: =IF(D29="","",($J$11-$H$7+D29)*$J$10/$H$12) -> 8.4541317 | H29: =IF(E29="","",($J$11-$H$7+E29)*$J$10/$H$12) | I29: =$F$12+(C29*$J$10/$L$12) -> 1540.9511 | J29: =IF(D29="","",($J$11-$H$7+D29)*$J$10/$B$12) -> 1411.84 | K29: =IF(E29="","",($J$11-$H$7+E29)*$J$10/$B$12)
B30: IUSJ | C30: 65 | D30: 2180 | E30: 1580 | F30: =$J$12+(C30*$J$10/$L$10) -> 9.3629142 | G30: =IF(D30="","",($J$11-$H$7+D30)*$J$10/$H$12) -> 8.4541317 | H30: =IF(E30="","",($J$11-$H$7+E30)*$J$10/$H$12) -> 8.1188024 | I30: =$F$12+(C30*$J$10/$L$12) -> 1599.2844 | J30: =IF(D30="","",($J$11-$H$7+D30)*$J$10/$B$12) -> 1411.84 | K30: =IF(E30="","",($J$11-$H$7+E30)*$J$10/$B$12) -> 1355.84 | L30: 10.3
B31: IUSP | C31: 65 | D31: 2180 | E31: 1580 | F31: =$J$12+(C31*$J$10/$L$10) -> 9.3629142 | G31: =IF(D31="","",($J$11-$H$7+D31)*$J$10/$H$12) -> 8.4541317 | H31: =IF(E31="","",($J$11-$H$7+E31)*$J$10/$H$12) -> 8.1188024 | I31: =$F$12+(C31*$J$10/$L$12) -> 1599.2844 | J31: =IF(D31="","",($J$11-$H$7+D31)*$J$10/$B$12) -> 1411.84 | K31: =IF(E31="","",($J$11-$H$7+E31)*$J$10/$B$12) -> 1355.84 | L31: 10.3
B32: IUSQ | C32: 65 | D32: 2180 | E32: 1580 | F32: =$J$12+(C32*$J$10/$L$10) -> 9.3629142 | G32: =IF(D32="","",($J$11-$H$7+D32)*$J$10/$H$12) -> 8.4541317 | H32: =IF(E32="","",($J$11-$H$7+E32)*$J$10/$H$12) -> 8.1188024 | I32: =$F$12+(C32*$J$10/$L$12) -> 1599.2844 | J32: =IF(D32="","",($J$11-$H$7+D32)*$J$10/$B$12) -> 1411.84 | K32: =IF(E32="","",($J$11-$H$7+E32)*$J$10/$B$12) -> 1355.84 | L32: 10.3
A33: 美西 四区 | B33: GEU3 | C33: 85 | D33: 3180 | E33: 2750 | F33: =$J$12+(C33*$J$10/$L$10) -> 9.7629142 | G33: =IF(D33="","",($J$11-$H$7+D33)*$J$10/$H$12) -> 9.013014 | H33: =IF(E33="","",($J$11-$H$7+E33)*$J$10/$H$12) -> 8.7726946 | I33: =$F$12+(C33*$J$10/$L$12) -> 1677.0622 | J33: =IF(D33="","",($J$11-$H$7+D33)*$J$10/$B$12) -> 1505.1733 | K33: =IF(E33="","",($J$11-$H$7+E33)*$J$10/$B$12) -> 1465.04 | L33: 10.6
B34: GEU2 | C34: 85 | D34: 3180 | E34: 2750 | F34: =$J$12+(C34*$J$10/$L$10) -> 9.7629142 | G34: =IF(D34="","",($J$11-$H$7+D34)*$J$10/$H$12) -> 9.013014 | H34: =IF(E34="","",($J$11-$H$7+E34)*$J$10/$H$12) -> 8.7726946 | I34: =$F$12+(C34*$J$10/$L$12) -> 1677.0622 | J34: =IF(D34="","",($J$11-$H$7+D34)*$J$10/$B$12) -> 1505.1733 | K34: =IF(E34="","",($J$11-$H$7+E34)*$J$10/$B$12) -> 1465.04 | L34: 10.6
B35: MIT2 | C35: 85 | D35: 3180 | E35: 2500 | F35: =$J$12+(C35*$J$10/$L$10) -> 9.7629142 | G35: =IF(D35="","",($J$11-$H$7+D35)*$J$10/$H$12) -> 9.013014 | H35: =IF(E35="","",($J$11-$H$7+E35)*$J$10/$H$12) -> 8.6329741 | I35: =$F$12+(C35*$J$10/$L$12) -> 1677.0622 | J35: =IF(D35="","",($J$11-$H$7+D35)*$J$10/$B$12) -> 1505.1733 | K35: =IF(E35="","",($J$11-$H$7+E35)*$J$10/$B$12) -> 1441.7067 | L35: 10.6
B36: OAK3 | C36: 85 | D36: 3180 | F36: =$J$12+(C36*$J$10/$L$10) -> 9.7629142 | G36: =IF(D36="","",($J$11-$H$7+D36)*$J$10/$H$12) -> 9.013014 | H36: =IF(E36="","",($J$11-$H$7+E36)*$J$10/$H$12) | I36: =$F$12+(C36*$J$10/$L$12) -> 1677.0622 | J36: =IF(D36="","",($J$11-$H$7+D36)*$J$10/$B$12) -> 1505.1733 | K36: =IF(E36="","",($J$11-$H$7+E36)*$J$10/$B$12)
B37: LAS6 | C37: 85 | D37: 3180 | E37: 2480 | F37: =$J$12+(C37*$J$10/$L$10) -> 9.7629142 | G37: =IF(D37="","",($J$11-$H$7+D37)*$J$10/$H$12) -> 9.013014 | H37: =IF(E37="","",($J$11-$H$7+E37)*$J$10/$H$12) -> 8.6217964 | I37: =$F$12+(C37*$J$10/$L$12) -> 1677.0622 | J37: =IF(D37="","",($J$11-$H$7+D37)*$J$10/$B$12) -> 1505.1733 | K37: =IF(E37="","",($J$11-$H$7+E37)*$J$10/$B$12) -> 1439.84
B38: SMF6 | C38: 85 | D38: 3180 | F38: =$J$12+(C38*$J$10/$L$10) -> 9.7629142 | G38: =IF(D38="","",($J$11-$H$7+D38)*$J$10/$H$12) -> 9.013014 | H38: =IF(E38="","",($J$11-$H$7+E38)*$J$10/$H$12) | I38: =$F$12+(C38*$J$10/$L$12) -> 1677.0622 | J38: =IF(D38="","",($J$11-$H$7+D38)*$J$10/$B$12) -> 1505.1733 | K38: =IF(E38="","",($J$11-$H$7+E38)*$J$10/$B$12)
B39: SCK8 | C39: 85 | D39: 3180 | F39: =$J$12+(C39*$J$10/$L$10) -> 9.7629142 | G39: =IF(D39="","",($J$11-$H$7+D39)*$J$10/$H$12) -> 9.013014 | H39: =IF(E39="","",($J$11-$H$7+E39)*$J$10/$H$12) | I39: =$F$12+(C39*$J$10/$L$12) -> 1677.0622 | J39: =IF(D39="","",($J$11-$H$7+D39)*$J$10/$B$12) -> 1505.1733 | K39: =IF(E39="","",($J$11-$H$7+E39)*$J$10/$B$12) | L39: 10.6
B40: GEU5 | C40: 85 | D40: 3180 | E40: 2750 | F40: =$J$12+(C40*$J$10/$L$10) -> 9.7629142 | G40: =IF(D40="","",($J$11-$H$7+D40)*$J$10/$H$12) -> 9.013014 | H40: =IF(E40="","",($J$11-$H$7+E40)*$J$10/$H$12) -> 8.7726946 | I40: =$F$12+(C40*$J$10/$L$12) -> 1677.0622 | J40: =IF(D40="","",($J$11-$H$7+D40)*$J$10/$B$12) -> 1505.1733 | K40: =IF(E40="","",($J$11-$H$7+E40)*$J$10/$B$12) -> 1465.04
...

Sheet EX456
A1: 应付 | B1: 盐田——LA | F1: 费用类型 | G1: 币种 | H1: 单价 | I1: 数量 | J1: 备注 | K1: 统计
B2: 起运港 | C2: 拖车+报关 | F2: 装柜费 | G2: RMB | H2: 500 | I2: 1
F3: 拖车费 | G3: RMB | H3: 1950 | I3: 1
F4: 报关费 | G4: RMB | H4: 500 | I4: 0 | J4: 实报实销 | K4: 100/票
F5: 港杂费RMB部分 | G5: RMB | H5: 3000 | I5: 1
F6: 海运费（变动） | G6: USD | H6: 5000 | I6: 1
B7: 目的港 | C7: 提柜+拆柜 | F7: 提拆一口价 | G7: USD | H7: 1400 | I7: 1
C8: 清关+缴税 | F8: 清关费 | G8: USD | I8: 1
F9: 税金 | G9: USD | H9: 1500 | L9: 每板KG
A10: 盐田-LA | B10: 人民币应付 | G10: RMB | H10: =SUM(H2:H5) -> 5950 | I10: 汇率 | J10: 7 | K10: =H10/J10 -> 850 | L10: 350
A11: 报价：2025/03/16 | B11: 含税/CBM | G11: USD | H11: =SUM(H6:H9) -> 7900 | I11: 合计 | J11: =H11+K10 -> 8750 | K11: =J11*J10 -> 61250 | L11: CBM
A12: CBM标准 | B12: 75 | E12: CBM计费标准 | F12: =K11/B12 -> 816.66667 | G12: KG标准 | H12: 12525 | I12: KG计费标准 | J12: =F12/167 -> 4.8902196 | L12: 1.8
B13: 派送费 | C13: 美金/板 | D13: 组合一口价 | E13: 整柜一口价 | F13: 拆送KG含税 | G13: 组合KG | H13: 直送KG | I13: 拆送CBM含税 | J13: 组合CBM | K13: 直送CBM | L13: 直客报价101KG+
A14: 美西 一区 | B14: ONT8 | C14: 30 | D14: 1980 | E14: 1430 | F14: =$J$12+(C14*$J$10/$L$10) -> 5.4902196 | G14: =IF(D14="","",($J$11-$H$7+D14)*$J$10/$H$12) -> 5.2143713 | H14: =IF(E14="","",($J$11-$H$7+E14)*$J$10/$H$12) -> 4.906986 | I14: =$F$12+(C14*$J$10/$L$12) -> 933.33333 | J14: =IF(D14="","",($J$11-$H$7+D14)*$J$10/$B$12) -> 870.8 | K14: =IF(E14="","",($J$11-$H$7+E14)*$J$10/$B$12) -> 819.46667 | L14: 6.4
B15: LGB8 | C15: 30 | D15: 1980 | E15: 1430 | F15: =$J$12+(C15*$J$10/$L$10) -> 5.4902196 | G15: =IF(D15="","",($J$11-$H$7+D15)*$J$10/$H$12) -> 5.2143713 | H15: =IF(E15="","",($J$11-$H$7+E15)*$J$10/$H$12) -> 4.906986 | I15: =$F$12+(C15*$J$10/$L$12) -> 933.33333 | J15: =IF(D15="","",($J$11-$H$7+D15)*$J$10/$B$12) -> 870.8 | K15: =IF(E15="","",($J$11-$H$7+E15)*$J$10/$B$12) -> 819.46667 | L15: 6.4
B16: SBD1 | C16: 35 | D16: 1980 | E16: 1430 | F16: =$J$12+(C16*$J$10/$L$10) -> 5.5902196 | G16: =IF(D16="","",($J$11-$H$7+D16)*$J$10/$H$12) -> 5.2143713 | H16: =IF(E16="","",($J$11-$H$7+E16)*$J$10/$H$12) -> 4.906986 | I16: =$F$12+(C16*$J$10/$L$12) -> 952.77778 | J16: =IF(D16="","",($J$11-$H$7+D16)*$J$10/$B$12) -> 870.8 | K16: =IF(E16="","",($J$11-$H$7+E16)*$J$10/$B$12) -> 819.46667 | L16: 6.4
B17: LAX9 | C17: 30 | D17: 1980 | E17: 1430 | F17: =$J$12+(C17*$J$10/$L$10) -> 5.4902196 | G17: =IF(D17="","",($J$11-$H$7+D17)*$J$10/$H$12) -> 5.2143713 | H17: =IF(E17="","",($J$11-$H$7+E17)*$J$10/$H$12) -> 4.906986 | I17: =$F$12+(C17*$J$10/$L$12) -> 933.33333 | J17: =IF(D17="","",($J$11-$H$7+D17)*$J$10/$B$12) -> 870.8 | K17: =IF(E17="","",($J$11-$H$7+E17)*$J$10/$B$12) -> 819.46667 | L17: 6.4
A18: 美西 二区 | B18: SMF3 | C18: 70 | D18: 2980 | E18: 2730 | F18: =$J$12+(C18*$J$10/$L$10) -> 6.2902196 | G18: =IF(D18="","",($J$11-$H$7+D18)*$J$10/$H$12) -> 5.7732535 | H18: =IF(E18="","",($J$11-$H$7+E18)*$J$10/$H$12) -> 5.6335329 | I18: =$F$12+(C18*$J$10/$L$12) -> 1088.8889 | J18: =IF(D18="","",($J$11-$H$7+D18)*$J$10/$B$12) -> 964.13333 | K18: =IF(E18="","",($J$11-$H$7+E18)*$J$10/$B$12) -> 940.8 | L18: 7.2
B19: SCK4 | C19: 70 | D19: 2980 | E19: 2730 | F19: =$J$12+(C19*$J$10/$L$10) -> 6.2902196 | G19: =IF(D19="","",($J$11-$H$7+D19)*$J$10/$H$12) -> 5.7732535 | H19: =IF(E19="","",($J$11-$H$7+E19)*$J$10/$H$12) -> 5.6335329 | I19: =$F$12+(C19*$J$10/$L$12) -> 1088.8889 | J19: =IF(D19="","",($J$11-$H$7+D19)*$J$10/$B$12) -> 964.13333 | K19: =IF(E19="","",($J$11-$H$7+E19)*$J$10/$B$12) -> 940.8 | L19: 7.2
B20: GYR2 | C20: 70 | D20: 2980 | E20: 2530 | F20: =$J$12+(C20*$J$10/$L$10) -> 6.2902196 | G20: =IF(D20="","",($J$11-$H$7+D20)*$J$10/$H$12) -> 5.7732535 | H20: =IF(E20="","",($J$11-$H$7+E20)*$J$10/$H$12) -> 5.5217565 | I20: =$F$12+(C20*$J$10/$L$12) -> 1088.8889 | J20: =IF(D20="","",($J$11-$H$7+D20)*$J$10/$B$12) -> 964.13333 | K20: =IF(E20="","",($J$11-$H$7+E20)*$J$10/$B$12) -> 922.13333 | L20: 7.2
B21: GYR3 | C21: 70 | D21: 2980 | E21: 2530 | F21: =$J$12+(C21*$J$10/$L$10) -> 6.2902196 | G21: =IF(D21="","",($J$11-$H$7+D21)*$J$10/$H$12) -> 5.7732535 | H21: =IF(E21="","",($J$11-$H$7+E21)*$J$10/$H$12) -> 5.5217565 | I21: =$F$12+(C21*$J$10/$L$12) -> 1088.8889 | J21: =IF(D21="","",($J$11-$H$7+D21)*$J$10/$B$12) -> 964.13333 | K21: =IF(E21="","",($J$11-$H$7+E21)*$J$10/$B$12) -> 922.13333 | L21: 7.2
B22: LAS1 | C22: 70 | D22: 2980 | E22: 2430 | F22: =$J$12+(C22*$J$10/$L$10) -> 6.2902196 | G22: =IF(D22="","",($J$11-$H$7+D22)*$J$10/$H$12) -> 5.7732535 | H22: =IF(E22="","",($J$11-$H$7+E22)*$J$10/$H$12) -> 5.4658683 | I22: =$F$12+(C22*$J$10/$L$12) -> 1088.8889 | J22: =IF(D22="","",($J$11-$H$7+D22)*$J$10/$B$12) -> 964.13333 | K22: =IF(E22="","",($J$11-$H$7+E22)*$J$10/$B$12) -> 912.8 | L22: 7.2
B23: VGT2 | C23: 70 | D23: 2980 | E23: 2430 | F23: =$J$12+(C23*$J$10/$L$10) -> 6.2902196 | G23: =IF(D23="","",($J$11-$H$7+D23)*$J$10/$H$12) -> 5.7732535 | H23: =IF(E23="","",($J$11-$H$7+E23)*$J$10/$H$12) -> 5.4658683 | I23: =$F$12+(C23*$J$10/$L$12) -> 1088.8889 | J23: =IF(D23="","",($J$11-$H$7+D23)*$J$10/$B$12) -> 964.13333 | K23: =IF(E23="","",($J$11-$H$7+E23)*$J$10/$B$12) -> 912.8 | L23: 7.2
A24: 美西 三区 | B24: POC1 | C24: 55 | D24: 2180 | E24: 1430 | F24: =$J$12+(C24*$J$10/$L$10) -> 5.9902196 | G24: =IF(D24="","",($J$11-$H$7+D24)*$J$10/$H$12) -> 5.3261477 | H24: =IF(E24="","",($J$11-$H$7+E24)*$J$10/$H$12) -> 4.906986 | I24: =$F$12+(C24*$J$10/$L$12) -> 1030.5556 | J24: =IF(D24="","",($J$11-$H$7+D24)*$J$10/$B$12) -> 889.46667 | K24: =IF(E24="","",($J$11-$H$7+E24)*$J$10/$B$12) -> 819.46667 | L24: 6.4
B25: POC2 | C25: 55 | D25: 2180 | F25: =$J$12+(C25*$J$10/$L$10) -> 5.9902196 | G25: =IF(D25="","",($J$11-$H$7+D25)*$J$10/$H$12) -> 5.3261477 | H25: =IF(E25="","",($J$11-$H$7+E25)*$J$10/$H$12) | I25: =$F$12+(C25*$J$10/$L$12) -> 1030.5556 | J25: =IF(D25="","",($J$11-$H$7+D25)*$J$10/$B$12) -> 889.46667 | K25: =IF(E25="","",($J$11-$H$7+E25)*$J$10/$B$12) | L25: 6.4
B26: POC3 | C26: 55 | D26: 2180 | E26: 1430 | F26: =$J$12+(C26*$J$10/$L$10) -> 5.9902196 | G26: =IF(D26="","",($J$11-$H$7+D26)*$J$10/$H$12) -> 5.3261477 | H26: =IF(E26="","",($J$11-$H$7+E26)*$J$10/$H$12) -> 4.906986 | I26: =$F$12+(C26*$J$10/$L$12) -> 1030.5556 | J26: =IF(D26="","",($J$11-$H$7+D26)*$J$10/$B$12) -> 889.46667 | K26: =IF(E26="","",($J$11-$H$7+E26)*$J$10/$B$12) -> 819.46667 | L26: 6.4
B27: SNA4 | C27: 50 | D27: 2180 | E27: 1480 | F27: =$J$12+(C27*$J$10/$L$10) -> 5.8902196 | G27: =IF(D27="","",($J$11-$H$7+D27)*$J$10/$H$12) -> 5.3261477 | H27: =IF(E27="","",($J$11-$H$7+E27)*$J$10/$H$12) -> 4.9349301 | I27: =$F$12+(C27*$J$10/$L$12) -> 1011.1111 | J27: =IF(D27="","",($J$11-$H$7+D27)*$J$10/$B$12) -> 889.46667 | K27: =IF(E27="","",($J$11-$H$7+E27)*$J$10/$B$12) -> 824.13333
B28: KRB1 | C28: 50 | D28: 2180 | F28: =$J$12+(C28*$J$10/$L$10) -> 5.8902196 | G28: =IF(D28="","",($J$11-$H$7+D28)*$J$10/$H$12) -> 5.3261477 | H28: =IF(E28="","",($J$11-$H$7+E28)*$J$10/$H$12) | I28: =$F$12+(C28*$J$10/$L$12) -> 1011.1111 | J28: =IF(D28="","",($J$11-$H$7+D28)*$J$10/$B$12) -> 889.46667 | K28: =IF(E28="","",($J$11-$H$7+E28)*$J$10/$B$12)
B29: KRB4 | C29: 50 | D29: 2180 | F29: =$J$12+(C29*$J$10/$L$10) -> 5.8902196 | G29: =IF(D29="","",($J$11-$H$7+D29)*$J$10/$H$12) -> 5.3261477 | H29: =IF(E29="","",($J$11-$H$7+E29)*$J$10/$H$12) | I29: =$F$12+(C29*$J$10/$L$12) -> 1011.1111 | J29: =IF(D29="","",($J$11-$H$7+D29)*$J$10/$B$12) -> 889.46667 | K29: =IF(E29="","",($J$11-$H$7+E29)*$J$10/$B$12)
B30: IUSJ | C30: 65 | D30: 2180 | E30: 1580 | F30: =$J$12+(C30*$J$10/$L$10) -> 6.1902196 | G30: =IF(D30="","",($J$11-$H$7+D30)*$J$10/$H$12) -> 5.3261477 | H30: =IF(E30="","",($J$11-$H$7+E30)*$J$10/$H$12) -> 4.9908184 | I30: =$F$12+(C30*$J$10/$L$12) -> 1069.4444 | J30: =IF(D30="","",($J$11-$H$7+D30)*$J$10/$B$12) -> 889.46667 | K30: =IF(E30="","",($J$11-$H$7+E30)*$J$10/$B$12) -> 833.46667 | L30: 6.9
B31: IUSP | C31: 65 | D31: 2180 | E31: 1580 | F31: =$J$12+(C31*$J$10/$L$10) -> 6.1902196 | G31: =IF(D31="","",($J$11-$H$7+D31)*$J$10/$H$12) -> 5.3261477 | H31: =IF(E31="","",($J$11-$H$7+E31)*$J$10/$H$12) -> 4.9908184 | I31: =$F$12+(C31*$J$10/$L$12) -> 1069.4444 | J31: =IF(D31="","",($J$11-$H$7+D31)*$J$10/$B$12) -> 889.46667 | K31: =IF(E31="","",($J$11-$H$7+E31)*$J$10/$B$12) -> 833.46667 | L31: 6.9
B32: IUSQ | C32: 65 | D32: 2180 | E32: 1580 | F32: =$J$12+(C32*$J$10/$L$10) -> 6.1902196 | G32: =IF(D32="","",($J$11-$H$7+D32)*$J$10/$H$12) -> 5.3261477 | H32: =IF(E32="","",($J$11-$H$7+E32)*$J$10/$H$12) -> 4.9908184 | I32: =$F$12+(C32*$J$10/$L$12) -> 1069.4444 | J32: =IF(D32="","",($J$11-$H$7+D32)*$J$10/$B$12) -> 889.46667 | K32: =IF(E32="","",($J$11-$H$7+E32)*$J$10/$B$12) -> 833.46667 | L32: 6.9
A33: 美西 四区 | B33: GEU3 | C33: 85 | D33: 3180 | E33: 2750 | F33: =$J$12+(C33*$J$10/$L$10) -> 6.5902196 | G33: =IF(D33="","",($J$11-$H$7+D33)*$J$10/$H$12) -> 5.8850299 | H33: =IF(E33="","",($J$11-$H$7+E33)*$J$10/$H$12) -> 5.6447106 | I33: =$F$12+(C33*$J$10/$L$12) -> 1147.2222 | J33: =IF(D33="","",($J$11-$H$7+D33)*$J$10/$B$12) -> 982.8 | K33: =IF(E33="","",($J$11-$H$7+E33)*$J$10/$B$12) -> 942.66667 | L33: 7.2
B34: QXY8 | C34: 86 | D34: 3181 | E34: 2751 | F34: =$J$12+(C34*$J$10/$L$10) -> 6.6102196 | G34: =IF(D34="","",($J$11-$H$7+D34)*$J$10/$H$12) -> 5.8855888 | H34: =IF(E34="","",($J$11-$H$7+E34)*$J$10/$H$12) -> 5.6452695 | I34: =$F$12+(C34*$J$10/$L$12) -> 1151.1111 | J34: =IF(D34="","",($J$11-$H$7+D34)*$J$10/$B$12) -> 982.89333 | K34: =IF(E34="","",($J$11-$H$7+E34)*$J$10/$B$12) -> 942.76 | L34: 7.2
B35: GEU2 | C35: 85 | D35: 3180 | E35: 2750 | F35: =$J$12+(C35*$J$10/$L$10) -> 6.5902196 | G35: =IF(D35="","",($J$11-$H$7+D35)*$J$10/$H$12) -> 5.8850299 | H35: =IF(E35="","",($J$11-$H$7+E35)*$J$10/$H$12) -> 5.6447106 | I35: =$F$12+(C35*$J$10/$L$12) -> 1147.2222 | J35: =IF(D35="","",($J$11-$H$7+D35)*$J$10/$B$12) -> 982.8 | K35: =IF(E35="","",($J$11-$H$7+E35)*$J$10/$B$12) -> 942.66667 | L35: 7.2
B36: GEU5 | C36: 85 | D36: 3180 | E36: 2750 | F36: =$J$12+(C36*$J$10/$L$10) -> 6.5902196 | G36: =IF(D36="","",($J$11-$H$7+D36)*$J$10/$H$12) -> 5.8850299 | H36: =IF(E36="","",($J$11-$H$7+E36)*$J$10/$H$12) -> 5.6447106 | I36: =$F$12+(C36*$J$10/$L$12) -> 1147.2222 | J36: =IF(D36="","",($J$11-$H$7+D36)*$J$10/$B$12) -> 982.8 | K36: =IF(E36="","",($J$11-$H$7+E36)*$J$10/$B$12) -> 942.66667
B37: MIT2 | C37: 85 | D37: 3180 | E37: 2500 | F37: =$J$12+(C37*$J$10/$L$10) -> 6.5902196 | G37: =IF(D37="","",($J$11-$H$7+D37)*$J$10/$H$12) -> 5.8850299 | H37: =IF(E37="","",($J$11-$H$7+E37)*$J$10/$H$12) -> 5.50499 | I37: =$F$12+(C37*$J$10/$L$12) -> 1147.2222 | J37: =IF(D37="","",($J$11-$H$7+D37)*$J$10/$B$12) -> 982.8 | K37: =IF(E37="","",($J$11-$H$7+E37)*$J$10/$B$12) -> 919.33333 | L37: 7.2
B38: OAK3 | C38: 85 | D38: 3180 | F38: =$J$12+(C38*$J$10/$L$10) -> 6.5902196 | G38: =IF(D38="","",($J$11-$H$7+D38)*$J$10/$H$12) -> 5.8850299 | H38: =IF(E38="","",($J$11-$H$7+E38)*$J$10/$H$12) | I38: =$F$12+(C38*$J$10/$L$12) -> 1147.2222 | J38: =IF(D38="","",($J$11-$H$7+D38)*$J$10/$B$12) -> 982.8 | K38: =IF(E38="","",($J$11-$H$7+E38)*$J$10/$B$12)
B39: LAS6 | C39: 85 | D39: 3180 | E39: 2480 | F39: =$J$12+(C39*$J$10/$L$10) -> 6.5902196 | G39: =IF(D39="","",($J$11-$H$7+D39)*$J$10/$H$12) -> 5.8850299 | H39: =IF(E39="","",($J$11-$H$7+E39)*$J$10/$H$12) -> 5.4938124 | I39: =$F$12+(C39*$J$10/$L$12) -> 1147.2222 | J39: =IF(D39="","",($J$11-$H$7+D39)*$J$10/$B$12) -> 982.8 | K39: =IF(E39="","",($J$11-$H$7+E39)*$J$10/$B$12) -> 917.46667
B40: SMF6 | C40: 85 | D40: 3180 | F40: =$J$12+(C40*$J$10/$L$10) -> 6.5902196 | G40: =IF(D40="","",($J$11-$H$7+D40)*$J$10/$H$12) -> 5.8850299 | H40: =IF(E40="","",($J$11-$H$7+E40)*$J$10/$H$12) | I40: =$F$12+(C40*$J$10/$L$12) -> 1147.2222 | J40: =IF(D40="","",($J$11-$H$7+D40)*$J$10/$B$12) -> 982.8 | K40: =IF(E40="","",($J$11-$H$7+E40)*$J$10/$B$12)
...

Sheet 洛杉矶600
A1: 应付 | B1: 盐田——LB | F1: 费用类型 | G1: 币种 | H1: 单价 | I1: 数量 | J1: 备注 | K1: 统计
B2: 起运港 | C2: 拖车+报关 | F2: 装柜费 | G2: RMB | H2: 500 | I2: 1
F3: 拖车费 | G3: RMB | H3: 1950 | I3: 1
F4: 报关费 | G4: RMB | H4: 500 | I4: 0 | J4: 实报实销 | K4: 100/票
F5: 港杂费RMB部分 | G5: RMB | H5: 3000 | I5: 1
F6: 海运费（变动） | G6: USD | H6: 2850 | I6: 1
B7: 目的港 | C7: 提柜+拆柜 | F7: 提拆一口价 | G7: USD | H7: 1400 | I7: 1
C8: 清关+缴税 | F8: 清关费 | G8: USD | I8: 1
F9: 税金 | G9: USD | H9: 1300 | I9: 1 | L9: 每板KG
A10: 盐田-LB/LA | B10: 人民币应付 | G10: RMB | H10: =SUM(H2:H5) -> 5950 | I10: 汇率 | J10: 7 | K10: =H10/J10 -> 850 | L10: 350
A11: 报价：2025/03/16 | B11: 含税/CBM | G11: USD | H11: =SUM(H6:H9) -> 5550 | I11: 合计 | J11: =H11+K10 -> 6400 | K11: =J11*J10 -> 44800 | L11: CBM
A12: CBM标准 | B12: 75 | E12: CBM计费标准 | F12: =K11/B12 -> 597.33333 | G12: KG标准 | H12: =B12*167 -> 12525 | I12: KG计费标准 | J12: =F12/167 -> 3.5768463 | L12: 1.8
B13: 派送费 | C13: 美金/板 | D13: 组合一口价 | E13: 整柜一口价 | F13: 拆送KG含税 | G13: 组合KG | H13: 直送KG | I13: 拆送CBM含税 | J13: 组合CBM | K13: 直送CBM | L13: 直客报价101KG+
A14: 美西 组合一 | B14: ONT8 | C14: 30 | D14: 1900 | E14: 1350 | F14: =$J$12+(C14*$J$10/$L$10) -> 4.1768463 | G14: =IF(D14="","",($J$11-$H$7+D14)*$J$10/$H$12) -> 3.8562874 | H14: =IF(E14="","",($J$11-$H$7+E14)*$J$10/$H$12) -> 3.5489022 | I14: =$F$12+(C14*$J$10/$L$12) -> 714 | J14: =IF(D14="","",($J$11-$H$7+D14)*$J$10/$B$12) -> 644 | K14: =IF(E14="","",($J$11-$H$7+E14)*$J$10/$B$12) -> 592.66667 | L14: 4.8
B15: LGB8 | C15: 30 | D15: 1900 | E15: 1350 | F15: =$J$12+(C15*$J$10/$L$10) -> 4.1768463 | G15: =IF(D15="","",($J$11-$H$7+D15)*$J$10/$H$12) -> 3.8562874 | H15: =IF(E15="","",($J$11-$H$7+E15)*$J$10/$H$12) -> 3.5489022 | I15: =$F$12+(C15*$J$10/$L$12) -> 714 | J15: =IF(D15="","",($J$11-$H$7+D15)*$J$10/$B$12) -> 644 | K15: =IF(E15="","",($J$11-$H$7+E15)*$J$10/$B$12) -> 592.66667 | L15: 4.8
B16: LAX9 | C16: 30 | D16: 1900 | E16: 1350 | F16: =$J$12+(C16*$J$10/$L$10) -> 4.1768463 | G16: =IF(D16="","",($J$11-$H$7+D16)*$J$10/$H$12) -> 3.8562874 | H16: =IF(E16="","",($J$11-$H$7+E16)*$J$10/$H$12) -> 3.5489022 | I16: =$F$12+(C16*$J$10/$L$12) -> 714 | J16: =IF(D16="","",($J$11-$H$7+D16)*$J$10/$B$12) -> 644 | K16: =IF(E16="","",($J$11-$H$7+E16)*$J$10/$B$12) -> 592.66667 | L16: 4.8
B17: SBD1 | C17: 30 | D17: 1900 | E17: 1350 | F17: =$J$12+(C17*$J$10/$L$10) -> 4.1768463 | G17: =IF(D17="","",($J$11-$H$7+D17)*$J$10/$H$12) -> 3.8562874 | H17: =IF(E17="","",($J$11-$H$7+E17)*$J$10/$H$12) -> 3.5489022 | I17: =$F$12+(C17*$J$10/$L$12) -> 714 | J17: =IF(D17="","",($J$11-$H$7+D17)*$J$10/$B$12) -> 644 | K17: =IF(E17="","",($J$11-$H$7+E17)*$J$10/$B$12) -> 592.66667 | L17: 4.8
B18: POC1 | C18: 35 | D18: 1900 | E18: 1350 | F18: =$J$12+(C18*$J$10/$L$10) -> 4.2768463 | G18: =IF(D18="","",($J$11-$H$7+D18)*$J$10/$H$12) -> 3.8562874 | H18: =IF(E18="","",($J$11-$H$7+E18)*$J$10/$H$12) -> 3.5489022 | I18: =$F$12+(C18*$J$10/$L$12) -> 733.44444 | J18: =IF(D18="","",($J$11-$H$7+D18)*$J$10/$B$12) -> 644 | K18: =IF(E18="","",($J$11-$H$7+E18)*$J$10/$B$12) -> 592.66667 | L18: 4.8
B19: POC3 | C19: 35 | D19: 1900 | E19: 1350 | F19: =$J$12+(C19*$J$10/$L$10) -> 4.2768463 | G19: =IF(D19="","",($J$11-$H$7+D19)*$J$10/$H$12) -> 3.8562874 | H19: =IF(E19="","",($J$11-$H$7+E19)*$J$10/$H$12) -> 3.5489022 | I19: =$F$12+(C19*$J$10/$L$12) -> 733.44444 | J19: =IF(D19="","",($J$11-$H$7+D19)*$J$10/$B$12) -> 644 | K19: =IF(E19="","",($J$11-$H$7+E19)*$J$10/$B$12) -> 592.66667 | L19: 4.8
A20: 美西 组合二 | B20: SMF3 | C20: 70 | D20: 2800 | E20: 2550 | F20: =$J$12+(C20*$J$10/$L$10) -> 4.9768463 | G20: =IF(D20="","",($J$11-$H$7+D20)*$J$10/$H$12) -> 4.3592814 | H20: =IF(E20="","",($J$11-$H$7+E20)*$J$10/$H$12) -> 4.2195609 | I20: =$F$12+(C20*$J$10/$L$12) -> 869.55556 | J20: =IF(D20="","",($J$11-$H$7+D20)*$J$10/$B$12) -> 728 | K20: =IF(E20="","",($J$11-$H$7+E20)*$J$10/$B$12) -> 704.66667 | L20: 5.6
B21: SCK4 | C21: 70 | D21: 2800 | E21: 2550 | F21: =$J$12+(C21*$J$10/$L$10) -> 4.9768463 | G21: =IF(D21="","",($J$11-$H$7+D21)*$J$10/$H$12) -> 4.3592814 | H21: =IF(E21="","",($J$11-$H$7+E21)*$J$10/$H$12) -> 4.2195609 | I21: =$F$12+(C21*$J$10/$L$12) -> 869.55556 | J21: =IF(D21="","",($J$11-$H$7+D21)*$J$10/$B$12) -> 728 | K21: =IF(E21="","",($J$11-$H$7+E21)*$J$10/$B$12) -> 704.66667 | L21: 5.6
B22: GYR2 | C22: 70 | D22: 2800 | E22: 2450 | F22: =$J$12+(C22*$J$10/$L$10) -> 4.9768463 | G22: =IF(D22="","",($J$11-$H$7+D22)*$J$10/$H$12) -> 4.3592814 | H22: =IF(E22="","",($J$11-$H$7+E22)*$J$10/$H$12) -> 4.1636727 | I22: =$F$12+(C22*$J$10/$L$12) -> 869.55556 | J22: =IF(D22="","",($J$11-$H$7+D22)*$J$10/$B$12) -> 728 | K22: =IF(E22="","",($J$11-$H$7+E22)*$J$10/$B$12) -> 695.33333 | L22: 5.6
B23: GYR3 | C23: 70 | D23: 2800 | E23: 2450 | F23: =$J$12+(C23*$J$10/$L$10) -> 4.9768463 | G23: =IF(D23="","",($J$11-$H$7+D23)*$J$10/$H$12) -> 4.3592814 | H23: =IF(E23="","",($J$11-$H$7+E23)*$J$10/$H$12) -> 4.1636727 | I23: =$F$12+(C23*$J$10/$L$12) -> 869.55556 | J23: =IF(D23="","",($J$11-$H$7+D23)*$J$10/$B$12) -> 728 | K23: =IF(E23="","",($J$11-$H$7+E23)*$J$10/$B$12) -> 695.33333 | L23: 5.6
B24: GEU2 | C24: 70 | D24: 2800 | E24: 2450 | F24: =$J$12+(C24*$J$10/$L$10) -> 4.9768463 | G24: =IF(D24="","",($J$11-$H$7+D24)*$J$10/$H$12) -> 4.3592814 | H24: =IF(E24="","",($J$11-$H$7+E24)*$J$10/$H$12) -> 4.1636727 | I24: =$F$12+(C24*$J$10/$L$12) -> 869.55556 | J24: =IF(D24="","",($J$11-$H$7+D24)*$J$10/$B$12) -> 728 | K24: =IF(E24="","",($J$11-$H$7+E24)*$J$10/$B$12) -> 695.33333 | L24: 5.6
B25: GEU3 | C25: 70 | D25: 2800 | E25: 2450 | F25: =$J$12+(C25*$J$10/$L$10) -> 4.9768463 | G25: =IF(D25="","",($J$11-$H$7+D25)*$J$10/$H$12) -> 4.3592814 | H25: =IF(E25="","",($J$11-$H$7+E25)*$J$10/$H$12) -> 4.1636727 | I25: =$F$12+(C25*$J$10/$L$12) -> 869.55556 | J25: =IF(D25="","",($J$11-$H$7+D25)*$J$10/$B$12) -> 728 | K25: =IF(E25="","",($J$11-$H$7+E25)*$J$10/$B$12) -> 695.33333 | L25: 5.6
B26: GEU5 | C26: 70 | D26: 2800 | E26: 2450 | F26: =$J$12+(C26*$J$10/$L$10) -> 4.9768463 | G26: =IF(D26="","",($J$11-$H$7+D26)*$J$10/$H$12) -> 4.3592814 | H26: =IF(E26="","",($J$11-$H$7+E26)*$J$10/$H$12) -> 4.1636727 | I26: =$F$12+(C26*$J$10/$L$12) -> 869.55556 | J26: =IF(D26="","",($J$11-$H$7+D26)*$J$10/$B$12) -> 728 | K26: =IF(E26="","",($J$11-$H$7+E26)*$J$10/$B$12) -> 695.33333
B27: LAS1 | C27: 70 | D27: 2800 | E27: 2250 | F27: =$J$12+(C27*$J$10/$L$10) -> 4.9768463 | G27: =IF(D27="","",($J$11-$H$7+D27)*$J$10/$H$12) -> 4.3592814 | H27: =IF(E27="","",($J$11-$H$7+E27)*$J$10/$H$12) -> 4.0518962 | I27: =$F$12+(C27*$J$10/$L$12) -> 869.55556 | J27: =IF(D27="","",($J$11-$H$7+D27)*$J$10/$B$12) -> 728 | K27: =IF(E27="","",($J$11-$H$7+E27)*$J$10/$B$12) -> 676.66667 | L27: 5.6
B28: VGT2 | C28: 70 | D28: 2800 | E28: 2250 | F28: =$J$12+(C28*$J$10/$L$10) -> 4.9768463 | G28: =IF(D28="","",($J$11-$H$7+D28)*$J$10/$H$12) -> 4.3592814 | H28: =IF(E28="","",($J$11-$H$7+E28)*$J$10/$H$12) -> 4.0518962 | I28: =$F$12+(C28*$J$10/$L$12) -> 869.55556 | J28: =IF(D28="","",($J$11-$H$7+D28)*$J$10/$B$12) -> 728 | K28: =IF(E28="","",($J$11-$H$7+E28)*$J$10/$B$12) -> 676.66667 | L28: 5.6
B29: MIT2 | C29: 70 | D29: 2800 | E29: 2050 | F29: =$J$12+(C29*$J$10/$L$10) -> 4.9768463 | G29: =IF(D29="","",($J$11-$H$7+D29)*$J$10/$H$12) -> 4.3592814 | H29: =IF(E29="","",($J$11-$H$7+E29)*$J$10/$H$12) -> 3.9401198 | I29: =$F$12+(C29*$J$10/$L$12) -> 869.55556 | J29: =IF(D29="","",($J$11-$H$7+D29)*$J$10/$B$12) -> 728 | K29: =IF(E29="","",($J$11-$H$7+E29)*$J$10/$B$12) -> 658 | L29: 5.6
B30: TCY1 | C30: 70 | D30: 2800 | E30: 2550 | F30: =$J$12+(C30*$J$10/$L$10) -> 4.9768463 | G30: =IF(D30="","",($J$11-$H$7+D30)*$J$10/$H$12) -> 4.3592814 | H30: =IF(E30="","",($J$11-$H$7+E30)*$J$10/$H$12) -> 4.2195609 | I30: =$F$12+(C30*$J$10/$L$12) -> 869.55556 | J30: =IF(D30="","",($J$11-$H$7+D30)*$J$10/$B$12) -> 728 | K30: =IF(E30="","",($J$11-$H$7+E30)*$J$10/$B$12) -> 704.66667 | L30: 5.6
B31: TCY2 | C31: 70 | D31: 2800 | E31: 2550 | F31: =$J$12+(C31*$J$10/$L$10) -> 4.9768463 | G31: =IF(D31="","",($J$11-$H$7+D31)*$J$10/$H$12) -> 4.3592814 | H31: =IF(E31="","",($J$11-$H$7+E31)*$J$10/$H$12) -> 4.2195609 | I31: =$F$12+(C31*$J$10/$L$12) -> 869.55556 | J31: =IF(D31="","",($J$11-$H$7+D31)*$J$10/$B$12) -> 728 | K31: =IF(E31="","",($J$11-$H$7+E31)*$J$10/$B$12) -> 704.66667 | L31: 5.6
B32: QXY8 | C32: 71 | D32: 2800 | E32: 2550 | F32: =$J$12+(C32*$J$10/$L$10) -> 4.9968463 | G32: =IF(D32="","",($J$11-$H$7+D32)*$J$10/$H$12) -> 4.3592814 | H32: =IF(E32="","",($J$11-$H$7+E32)*$J$10/$H$12) -> 4.2195609 | I32: =$F$12+(C32*$J$10/$L$12) -> 873.44444 | J32: =IF(D32="","",($J$11-$H$7+D32)*$J$10/$B$12) -> 728 | K32: =IF(E32="","",($J$11-$H$7+E32)*$J$10/$B$12) -> 704.66667 | L32: 5.7
B33: SCK8 | C33: 80 | D33: 2800 | E33: 2550 | F33: =$J$12+(C33*$J$10/$L$10) -> 5.1768463 | G33: =IF(D33="","",($J$11-$H$7+D33)*$J$10/$H$12) -> 4.3592814 | H33: =IF(E33="","",($J$11-$H$7+E33)*$J$10/$H$12) -> 4.2195609 | I33: =$F$12+(C33*$J$10/$L$12) -> 908.44444 | J33: =IF(D33="","",($J$11-$H$7+D33)*$J$10/$B$12) -> 728 | K33: =IF(E33="","",($J$11-$H$7+E33)*$J$10/$B$12) -> 704.66667 | L33: 5.6
B34: HLI2 | C34: 80 | D34: 2800 | F34: =$J$12+(C34*$J$10/$L$10) -> 5.1768463 | G34: =IF(D34="","",($J$11-$H$7+D34)*$J$10/$H$12) -> 4.3592814 | H34: =IF(E34="","",($J$11-$H$7+E34)*$J$10/$H$12) | I34: =$F$12+(C34*$J$10/$L$12) -> 908.44444 | J34: =IF(D34="","",($J$11-$H$7+D34)*$J$10/$B$12) -> 728 | K34: =IF(E34="","",($J$11-$H$7+E34)*$J$10/$B$12) | L34: 5.6
A35: 美西 组合三 | B35: FTW1 | C35: 170 | D35: 5400 | F35: =$J$12+(C35*$J$10/$L$10) -> 6.9768463 | G35: =IF(D35="","",($J$11-$H$7+D35)*$J$10/$H$12) -> 5.8123752 | H35: =IF(E35="","",($J$11-$H$7+E35)*$J$10/$H$12) | I35: =$F$12+(C35*$J$10/$L$12) -> 1258.4444 | J35: =IF(D35="","",($J$11-$H$7+D35)*$J$10/$B$12) -> 970.66667 | K35: =IF(E35="","",($J$11-$H$7+E35)*$J$10/$B$12) | L35: 7.1
B36: FTW5 | C36: 170 | D36: 5400 | F36: =$J$12+(C36*$J$10/$L$10) -> 6.9768463 | G36: =IF(D36="","",($J$11-$H$7+D36)*$J$10/$H$12) -> 5.8123752 | H36: =IF(E36="","",($J$11-$H$7+E36)*$J$10/$H$12) | I36: =$F$12+(C36*$J$10/$L$12) -> 1258.4444 | J36: =IF(D36="","",($J$11-$H$7+D36)*$J$10/$B$12) -> 970.66667 | K36: =IF(E36="","",($J$11-$H$7+E36)*$J$10/$B$12) | L36: 7.4
B37: SAT1 | C37: 180 | D37: 5400 | F37: =$J$12+(C37*$J$10/$L$10) -> 7.1768463 | G37: =IF(D37="","",($J$11-$H$7+D37)*$J$10/$H$12) -> 5.8123752 | H37: =IF(E37="","",($J$11-$H$7+E37)*$J$10/$H$12) | I37: =$F$12+(C37*$J$10/$L$12) -> 1297.3333 | J37: =IF(D37="","",($J$11-$H$7+D37)*$J$10/$B$12) -> 970.66667 | K37: =IF(E37="","",($J$11-$H$7+E37)*$J$10/$B$12) | L37: 7.4
B38: SAT4 | C38: 180 | D38: 5400 | F38: =$J$12+(C38*$J$10/$L$10) -> 7.1768463 | G38: =IF(D38="","",($J$11-$H$7+D38)*$J$10/$H$12) -> 5.8123752 | H38: =IF(E38="","",($J$11-$H$7+E38)*$J$10/$H$12) | I38: =$F$12+(C38*$J$10/$L$12) -> 1297.3333 | J38: =IF(D38="","",($J$11-$H$7+D38)*$J$10/$B$12) -> 970.66667 | K38: =IF(E38="","",($J$11-$H$7+E38)*$J$10/$B$12) | L38: 7.4
B39: AMA1 | C39: 170 | D39: 5400 | F39: =$J$12+(C39*$J$10/$L$10) -> 6.9768463 | G39: =IF(D39="","",($J$11-$H$7+D39)*$J$10/$H$12) -> 5.8123752 | H39: =IF(E39="","",($J$11-$H$7+E39)*$J$10/$H$12) | I39: =$F$12+(C39*$J$10/$L$12) -> 1258.4444 | J39: =IF(D39="","",($J$11-$H$7+D39)*$J$10/$B$12) -> 970.66667 | K39: =IF(E39="","",($J$11-$H$7+E39)*$J$10/$B$12)
B40: DFW6 | C40: 170 | D40: 5400 | F40: =$J$12+(C40*$J$10/$L$10) -> 6.9768463 | G40: =IF(D40="","",($J$11-$H$7+D40)*$J$10/$H$12) -> 5.8123752 | H40: =IF(E40="","",($J$11-$H$7+E40)*$J$10/$H$12) | I40: =$F$12+(C40*$J$10/$L$12) -> 1258.4444 | J40: =IF(D40="","",($J$11-$H$7+D40)*$J$10/$B$12) -> 970.66667 | K40: =IF(E40="","",($J$11-$H$7+E40)*$J$10/$B$12) | L40: 7.4
...

Sheet 奥克兰744
A1: 应付 | B1: 盐田——OAK | F1: 费用类型 | G1: 币种 | H1: 单价 | I1: 数量 | J1: 备注 | K1: 统计
B2: 起运港 | C2: 拖车+报关 | F2: 装柜费 | G2: RMB | H2: 500 | I2: 1
F3: 拖车费 | G3: RMB | H3: 1950 | I3: 1
F4: 报关费 | G4: RMB | H4: 500 | I4: 0 | J4: 实报实销 | K4: 100/票
F5: 港杂费RMB部分 | G5: RMB | H5: 2800 | I5: 1
F6: 海运费（变动） | G6: USD | H6: 2850 | I6: 1
B7: 目的港 | C7: 提柜+拆柜 | F7: 提拆一口价 | G7: USD | H7: 1500 | I7: 1
C8: 清关+缴税 | F8: 清关费 | G8: USD | I8: 1
F9: 税金 | G9: USD | H9: 1500 | I9: 1 | L9: 每板KG
A10: 盐田—OAK | B10: 人民币应付 | G10: RMB | H10: =SUM(H2:H5) -> 5750 | I10: 汇率 | J10: 7 | K10: =H10/J10 -> 821.42857 | L10: 350
A11: 报价：2025/03/16 | B11: 含税/CBM | G11: USD | H11: =SUM(H6:H9) -> 5850 | I11: 合计 | J11: =H11+K10 -> 6671.4286 | K11: =J11*J10 -> 46700 | L11: CBM
A12: CBM标准 | B12: 75 | E12: CBM计费标准 | F12: =K11/B12 -> 622.66667 | G12: KG标准 | H12: 12500 | I12: KG计费标准 | J12: =F12/167 -> 3.7285429 | L12: 1.8
B13: 派送费 | C13: 美金/板 | D13: 组合一口价 | E13: 整柜一口价 | F13: 拆送KG含税 | G13: 组合KG | H13: 直送KG | I13: 拆送CBM含税 | J13: 组合CBM | K13: 直送CBM | L13: 直客报价101KG+
A14: 奥克兰 | B14: SCK4 | C14: 30 | D14: 2100 | E14: 1100 | F14: =$J$12+(C14*$J$10/$L$10) -> 4.3285429 | G14: =IF(D14="","",($J$11-$H$7+D14)*$J$10/$H$12) -> 4.072 | H14: =IF(E14="","",($J$11-$H$7+E14)*$J$10/$H$12) -> 3.512 | I14: =$F$12+(C14*$J$10/$L$12) -> 739.33333 | J14: =IF(D14="","",($J$11-$H$7+D14)*$J$10/$B$12) -> 678.66667 | K14: =IF(E14="","",($J$11-$H$7+E14)*$J$10/$B$12) -> 585.33333 | L14: 5.5
B15: SMF3 | C15: 30 | D15: 2100 | E15: 1100 | F15: =$J$12+(C15*$J$10/$L$10) -> 4.3285429 | G15: =IF(D15="","",($J$11-$H$7+D15)*$J$10/$H$12) -> 4.072 | H15: =IF(E15="","",($J$11-$H$7+E15)*$J$10/$H$12) -> 3.512 | I15: =$F$12+(C15*$J$10/$L$12) -> 739.33333 | J15: =IF(D15="","",($J$11-$H$7+D15)*$J$10/$B$12) -> 678.66667 | K15: =IF(E15="","",($J$11-$H$7+E15)*$J$10/$B$12) -> 585.33333 | L15: 5.5
B16: TCY2 | C16: 45 | D16: 2100 | E16: 1100 | F16: =$J$12+(C16*$J$10/$L$10) -> 4.6285429 | G16: =IF(D16="","",($J$11-$H$7+D16)*$J$10/$H$12)+36/167 -> 4.2875689 | H16: =IF(E16="","",($J$11-$H$7+E16)*$J$10/$H$12) -> 3.512 | I16: =$F$12+(C16*$J$10/$L$12) -> 797.66667 | J16: =IF(D16="","",($J$11-$H$7+D16)*$J$10/$B$12) -> 678.66667 | K16: =IF(E16="","",($J$11-$H$7+E16)*$J$10/$B$12) -> 585.33333 | L16: 5.9
B17: TCY1 | C17: 45 | D17: 2100 | E17: 1100 | F17: =$J$12+(C17*$J$10/$L$10) -> 4.6285429 | G17: =IF(D17="","",($J$11-$H$7+D17)*$J$10/$H$12)+36/167 -> 4.2875689 | H17: =IF(E17="","",($J$11-$H$7+E17)*$J$10/$H$12) -> 3.512 | I17: =$F$12+(C17*$J$10/$L$12) -> 797.66667 | J17: =IF(D17="","",($J$11-$H$7+D17)*$J$10/$B$12) -> 678.66667 | K17: =IF(E17="","",($J$11-$H$7+E17)*$J$10/$B$12) -> 585.33333 | L17: 5.9
B18: HLI2 | C18: 45 | D18: 2100 | E18: 1300 | F18: =$J$12+(C18*$J$10/$L$10) -> 4.6285429 | G18: =IF(D18="","",($J$11-$H$7+D18)*$J$10/$H$12)+72/167 -> 4.5031377 | H18: =IF(E18="","",($J$11-$H$7+E18)*$J$10/$H$12) -> 3.624 | I18: =$F$12+(C18*$J$10/$L$12) -> 797.66667 | J18: =IF(D18="","",($J$11-$H$7+D18)*$J$10/$B$12) -> 678.66667 | K18: =IF(E18="","",($J$11-$H$7+E18)*$J$10/$B$12) -> 604 | L18: 6
B19: SCK1 | C19: 30 | D19: 2100 | E19: 1100 | F19: =$J$12+(C19*$J$10/$L$10) -> 4.3285429 | G19: =IF(D19="","",($J$11-$H$7+D19)*$J$10/$H$12) -> 4.072 | H19: =IF(E19="","",($J$11-$H$7+E19)*$J$10/$H$12) -> 3.512 | I19: =$F$12+(C19*$J$10/$L$12) -> 739.33333 | J19: =IF(D19="","",($J$11-$H$7+D19)*$J$10/$B$12) -> 678.66667 | K19: =IF(E19="","",($J$11-$H$7+E19)*$J$10/$B$12) -> 585.33333 | L19: 5.5
B20: SCK3 | C20: 30 | D20: 2100 | E20: 1100 | F20: =$J$12+(C20*$J$10/$L$10) -> 4.3285429 | G20: =IF(D20="","",($J$11-$H$7+D20)*$J$10/$H$12) -> 4.072 | H20: =IF(E20="","",($J$11-$H$7+E20)*$J$10/$H$12) -> 3.512 | I20: =$F$12+(C20*$J$10/$L$12) -> 739.33333 | J20: =IF(D20="","",($J$11-$H$7+D20)*$J$10/$B$12) -> 678.66667 | K20: =IF(E20="","",($J$11-$H$7+E20)*$J$10/$B$12) -> 585.33333 | L20: 5.5
B21: OAK3 | C21: 30 | D21: 2100 | E21: 1100 | F21: =$J$12+(C21*$J$10/$L$10) -> 4.3285429 | G21: =IF(D21="","",($J$11-$H$7+D21)*$J$10/$H$12) -> 4.072 | H21: =IF(E21="","",($J$11-$H$7+E21)*$J$10/$H$12) -> 3.512 | I21: =$F$12+(C21*$J$10/$L$12) -> 739.33333 | J21: =IF(D21="","",($J$11-$H$7+D21)*$J$10/$B$12) -> 678.66667 | K21: =IF(E21="","",($J$11-$H$7+E21)*$J$10/$B$12) -> 585.33333 | L21: 5.5
B22: QXY5 | C22: 40 | D22: 2100 | F22: =$J$12+(C22*$J$10/$L$10) -> 4.5285429 | G22: =IF(D22="","",($J$11-$H$7+D22)*$J$10/$H$12)+36/167 -> 4.2875689 | H22: =IF(E22="","",($J$11-$H$7+E22)*$J$10/$H$12) | I22: =$F$12+(C22*$J$10/$L$12) -> 778.22222 | J22: =IF(D22="","",($J$11-$H$7+D22)*$J$10/$B$12) -> 678.66667 | K22: =IF(E22="","",($J$11-$H$7+E22)*$J$10/$B$12) | L22: 5.9
B23: SJC7 | C23: 30 | D23: 2100 | E23: 1100 | F23: =$J$12+(C23*$J$10/$L$10) -> 4.3285429 | G23: =IF(D23="","",($J$11-$H$7+D23)*$J$10/$H$12) -> 4.072 | H23: =IF(E23="","",($J$11-$H$7+E23)*$J$10/$H$12) -> 3.512 | I23: =$F$12+(C23*$J$10/$L$12) -> 739.33333 | J23: =IF(D23="","",($J$11-$H$7+D23)*$J$10/$B$12) -> 678.66667 | K23: =IF(E23="","",($J$11-$H$7+E23)*$J$10/$B$12) -> 585.33333
B24: SCK8 | C24: 40 | D24: 2100 | E24: 1100 | F24: =$J$12+(C24*$J$10/$L$10) -> 4.5285429 | G24: =IF(D24="","",($J$11-$H$7+D24)*$J$10/$H$12)+36/167 -> 4.2875689 | H24: =IF(E24="","",($J$11-$H$7+E24)*$J$10/$H$12) -> 3.512 | I24: =$F$12+(C24*$J$10/$L$12) -> 778.22222 | J24: =IF(D24="","",($J$11-$H$7+D24)*$J$10/$B$12)+60 -> 738.66667 | K24: =IF(E24="","",($J$11-$H$7+E24)*$J$10/$B$12) -> 585.33333 | L24: 5.9
B25: SMF7 | C25: 45 | D25: 2100 | E25: 1250 | F25: =$J$12+(C25*$J$10/$L$10) -> 4.6285429 | G25: =IF(D25="","",($J$11-$H$7+D25)*$J$10/$H$12)+54/167 -> 4.3953533 | H25: =IF(E25="","",($J$11-$H$7+E25)*$J$10/$H$12) -> 3.596 | I25: =$F$12+(C25*$J$10/$L$12) -> 797.66667 | J25: =IF(D25="","",($J$11-$H$7+D25)*$J$10/$B$12) -> 678.66667 | K25: =IF(E25="","",($J$11-$H$7+E25)*$J$10/$B$12) -> 599.33333 | L25: 5.9
B26: MCE1 | C26: 40 | D26: 2100 | E26: 1300 | F26: =$J$12+(C26*$J$10/$L$10) -> 4.5285429 | G26: =IF(D26="","",($J$11-$H$7+D26)*$J$10/$H$12)+54/167 -> 4.3953533 | H26: =IF(E26="","",($J$11-$H$7+E26)*$J$10/$H$12) -> 3.624 | I26: =$F$12+(C26*$J$10/$L$12) -> 778.22222 | J26: =IF(D26="","",($J$11-$H$7+D26)*$J$10/$B$12) -> 678.66667 | K26: =IF(E26="","",($J$11-$H$7+E26)*$J$10/$B$12) -> 604 | L26: 5.9
B27: SMF6 | C27: 45 | D27: 2100 | E27: 1300 | F27: =$J$12+(C27*$J$10/$L$10) -> 4.6285429 | G27: =IF(D27="","",($J$11-$H$7+D27)*$J$10/$H$12)+54/167 -> 4.3953533 | H27: =IF(E27="","",($J$11-$H$7+E27)*$J$10/$H$12) -> 3.624 | I27: =$F$12+(C27*$J$10/$L$12) -> 797.66667 | J27: =IF(D27="","",($J$11-$H$7+D27)*$J$10/$B$12) -> 678.66667 | K27: =IF(E27="","",($J$11-$H$7+E27)*$J$10/$B$12) -> 604 | L27: 5.9
B28: MCC1 | D28: 2100 | F28: =$J$12+(C28*$J$10/$L$10) -> 3.7285429 | G28: =IF(D28="","",($J$11-$H$7+D28)*$J$10/$H$12)+72/167 -> 4.5031377 | H28: =IF(E28="","",($J$11-$H$7+E28)*$J$10/$H$12) | I28: =$F$12+(C28*$J$10/$L$12) -> 622.66667 | J28: =IF(D28="","",($J$11-$H$7+D28)*$J$10/$B$12) -> 678.66667 | K28: =IF(E28="","",($J$11-$H$7+E28)*$J$10/$B$12) | L28: 6
B29: FAT2 | C29: 60 | D29: 2100 | E29: 1850 | F29: =$J$12+(C29*$J$10/$L$10) -> 4.9285429 | G29: =IF(D29="","",($J$11-$H$7+D29)*$J$10/$H$12)+72/167 -> 4.5031377 | H29: =IF(E29="","",($J$11-$H$7+E29)*$J$10/$H$12) -> 3.932 | I29: =$F$12+(C29*$J$10/$L$12) -> 856 | J29: =IF(D29="","",($J$11-$H$7+D29)*$J$10/$B$12) -> 678.66667 | K29: =IF(E29="","",($J$11-$H$7+E29)*$J$10/$B$12) -> 655.33333 | L29: 6

Sheet 西雅图788
A1: 应付 | B1: 盐田——西雅图 | F1: 费用类型 | G1: 币种 | H1: 单价 | I1: 数量 | J1: 备注 | K1: 统计
B2: 起运港 | C2: 拖车+报关 | F2: 装柜费 | G2: RMB | H2: 500 | I2: 1
F3: 拖车费 | G3: RMB | H3: 1950 | I3: 1
F4: 报关费 | G4: RMB | H4: 500 | I4: 0 | J4: 实报实销 | K4: 100/票
F5: 港杂费RMB部分 | G5: RMB | H5: 2800 | I5: 1
F6: 海运费（变动） | G6: USD | H6: 2850 | I6: 1
B7: 目的港 | C7: 提柜+拆柜 | F7: 提拆一口价 | G7: USD | H7: 2000 | I7: 1
C8: 清关+缴税 | F8: 清关费 | G8: USD | I8: 1
F9: 税金 | G9: USD | H9: 1500 | I9: 1 | L9: 每板KG
A10: 盐田—西雅图 | B10: 人民币应付 | G10: RMB | H10: =SUM(H2:H5) -> 5750 | I10: 汇率 | J10: 7 | K10: =H10/J10 -> 821.42857 | L10: 350
A11: 报价：2025/03/16 | B11: 含税/CBM | G11: USD | H11: =SUM(H6:H9) -> 6350 | I11: 合计 | J11: =H11+K10 -> 7171.4286 | K11: =J11*J10 -> 50200 | L11: CBM
A12: CBM标准 | B12: 75 | E12: CBM计费标准 | F12: =K11/B12 -> 669.33333 | G12: KG标准 | H12: 12500 | I12: KG计费标准 | J12: =K11/H12 -> 4.016 | L12: 1.8
B13: 派送费 | C13: 美金/板 | D13: 组合一口价 | E13: 整柜一口价 | F13: 拆送KG含税 | G13: 组合KG | H13: 直送KG | I13: 拆送CBM含税 | J13: 组合CBM | K13: 直送CBM | L13: 直客报价101KG+
A14: 西雅图拆送 | B14: BFI3 | C14: 45 | F14: =$J$12+(C14*$J$10/$L$10) -> 4.916 | G14: =IF(D14="","",($J$11-$H$7+D14)*$J$10/$H$12) | H14: =IF(E14="","",($J$11-$H$7+E14)*$J$10/$H$12) | I14: =$F$12+(C14*$J$10/$L$12) -> 844.33333 | J14: =IF(D14="","",($J$11-$H$7+D14)*$J$10/$B$12) | K14: =IF(E14="","",($J$11-$H$7+E14)*$J$10/$B$12) | L14: 6.1
B15: BFI7 | C15: 45 | F15: =$J$12+(C15*$J$10/$L$10) -> 4.916 | G15: =IF(D15="","",($J$11-$H$7+D15)*$J$10/$H$12) | H15: =IF(E15="","",($J$11-$H$7+E15)*$J$10/$H$12) | I15: =$F$12+(C15*$J$10/$L$12) -> 844.33333 | J15: =IF(D15="","",($J$11-$H$7+D15)*$J$10/$B$12) | K15: =IF(E15="","",($J$11-$H$7+E15)*$J$10/$B$12) | L15: 6.1
B16: PDX6 | C16: 65 | F16: =$J$12+(C16*$J$10/$L$10) -> 5.316 | G16: =IF(D16="","",($J$11-$H$7+D16)*$J$10/$H$12) | H16: =IF(E16="","",($J$11-$H$7+E16)*$J$10/$H$12) | I16: =$F$12+(C16*$J$10/$L$12) -> 922.11111 | J16: =IF(D16="","",($J$11-$H$7+D16)*$J$10/$B$12) | K16: =IF(E16="","",($J$11-$H$7+E16)*$J$10/$B$12) | L16: 6.6
B17: PDX7 | C17: 65 | F17: =$J$12+(C17*$J$10/$L$10) -> 5.316 | G17: =IF(D17="","",($J$11-$H$7+D17)*$J$10/$H$12) | H17: =IF(E17="","",($J$11-$H$7+E17)*$J$10/$H$12) | I17: =$F$12+(C17*$J$10/$L$12) -> 922.11111 | J17: =IF(D17="","",($J$11-$H$7+D17)*$J$10/$B$12) | K17: =IF(E17="","",($J$11-$H$7+E17)*$J$10/$B$12) | L17: 6.6
B18: PSC2 | C18: 65 | D18: 3250 | F18: =$J$12+(C18*$J$10/$L$10) -> 5.316 | G18: =IF(D18="","",($J$11-$H$7+D18)*$J$10/$H$12) -> 4.716 | H18: =IF(E18="","",($J$11-$H$7+E18)*$J$10/$H$12) | I18: =$F$12+(C18*$J$10/$L$12) -> 922.11111 | J18: =IF(D18="","",($J$11-$H$7+D18)*$J$10/$B$12) -> 786 | K18: =IF(E18="","",($J$11-$H$7+E18)*$J$10/$B$12) | L18: 6.4
B19: GEG2 | C19: 85 | F19: =$J$12+(C19*$J$10/$L$10) -> 5.716 | G19: =IF(D19="","",($J$11-$H$7+D19)*$J$10/$H$12) | H19: =IF(E19="","",($J$11-$H$7+E19)*$J$10/$H$12) | I19: =$F$12+(C19*$J$10/$L$12) -> 999.88889 | J19: =IF(D19="","",($J$11-$H$7+D19)*$J$10/$B$12) | K19: =IF(E19="","",($J$11-$H$7+E19)*$J$10/$B$12) | L19: 7

Sheet 芝加哥840
A1: 应付 | B1: 盐田——CHI | F1: 费用类型 | G1: 币种 | H1: 单价 | I1: 数量 | J1: 备注 | K1: 统计
B2: 起运港 | C2: 拖车+报关 | F2: 装柜费 | G2: RMB | H2: 500 | I2: 1
F3: 拖车费 | G3: RMB | H3: 1950 | I3: 1 | J3: 广州+东莞 | K3: 2450
F4: 报关费 | G4: RMB | H4: 500 | I4: 0 | J4: 实报实销 | K4: 100/票
F5: 港杂费RMB部分 | G5: RMB | H5: 2800 | I5: 1
F6: 海运费（变动） | G6: USD | H6: 5150 | I6: 1 | J6: OA舱位
B7: 目的港 | C7: 提柜+拆柜 | F7: 提拆一口价 | G7: USD | H7: 1500 | I7: 1
C8: 清关+缴税 | F8: 清关费 | G8: USD | I8: 1
F9: 税金 | G9: USD | H9: 1500 | I9: 1 | L9: 每板KG
A10: 盐田——CHI | B10: 人民币应付 | G10: RMB | H10: =SUM(H2:H5) -> 5750 | I10: 汇率 | J10: 7 | K10: =H10/J10 -> 821.42857 | L10: 350
A11: 报价：2025/03/16 | B11: 含税/CBM | G11: USD | H11: =SUM(H6:H9) -> 8150 | I11: 合计 | J11: =H11+K10 -> 8971.4286 | K11: =J11*J10 -> 62800 | L11: CBM
A12: CBM标准 | B12: 75 | E12: CBM计费标准 | F12: =K11/B12 -> 837.33333 | G12: KG标准 | H12: 12500 | I12: KG计费标准 | J12: =K11/H12 -> 5.024 | L12: 1.8
B13: 派送费 | C13: 美金/板 | D13: 组合一口价 | E13: 整柜一口价 | F13: 拆送KG含税 | G13: 组合KG | H13: 直送KG | I13: 拆送CBM含税 | J13: 组合CBM | K13: 直送CBM | L13: 直客报价101KG+
A14: 芝 加 哥 一区 | B14: MDW2 | C14: 45 | D14: 2600 | E14: 1850 | F14: =$J$12+(C14*$J$10/$L$10) -> 5.924 | G14: =IF(D14="","",($J$11-$H$7+D14)*$J$10/$H$12) -> 5.64 | H14: =IF(E14="","",($J$11-$H$7+E14)*$J$10/$H$12) -> 5.22 | I14: =$F$12+(C14*$J$10/$L$12) -> 1012.3333 | J14: =IF(D14="","",($J$11-$H$7+D14)*$J$10/$B$12) -> 940 | K14: =IF(E14="","",($J$11-$H$7+E14)*$J$10/$B$12) -> 870 | L14: 7
B15: ORD2 | C15: 40 | D15: 2600 | F15: =$J$12+(C15*$J$10/$L$10) -> 5.824 | G15: =IF(D15="","",($J$11-$H$7+D15)*$J$10/$H$12) -> 5.64 | H15: =IF(E15="","",($J$11-$H$7+E15)*$J$10/$H$12) | I15: =$F$12+(C15*$J$10/$L$12) -> 992.88889 | J15: =IF(D15="","",($J$11-$H$7+D15)*$J$10/$B$12) -> 940 | K15: =IF(E15="","",($J$11-$H$7+E15)*$J$10/$B$12) | L15: 7
