Workbook

Sheet 报价主页
A2: 渠道名称 | B2: 渠道代码 | C2: 进入价格 | D2: 渠道优势说明 | E2: 最快提取/送仓时间 | F2: 备注
A3: 国际快递 | B3: US-GZ | C3: 点击进入 | D3: 大陆自主账号，自主打单，自主发货，一手操作 | E3: 当天提取 | F3: 自主账号
A4: 美国空运240 | B4: USMAF | C4: 点击进入 | D4: 大陆优质航班，时效稳定，整板拆派 | E4: 5-10个自然日提取 | F4: 每周航班
A5: 美森360 | B5: USMS360 | C5: 点击进入 | D5: 飞点旗舰产品，美森CLX服务，360小时延误赔付 | E5: 12-15个自然日提取 | F5: 美线最快方案
A6: 美森432 | B6: USMS432 | C6: 点击进入 | D6: 飞点尖端产品，美森MAX快航服务，对标市场限时达，432小时延误赔付 | E6: 13-17个自然日提取 | F6: 快船首选方案
A7: EX456 | B7: US456 | C7: 点击进入 | D7: ZIM/合德/CMA快提服务，目的港专属通道优先提柜，时效比肩美森MAX，456小时延误赔付 | E7: 14-18个自然日提取 | F7: 华东华南美线优质服务
A8: 快船600 | B8: USOA600 | C8: 点击进入 | D8: COSCO/OOCL/EMC保舱服务，提供甩柜、600小时时效延误双重理赔服务 | E8: 20-25个自然日送仓 | F8: 美西保舱服务,极致性价比
A9: 玩具普船FBA专线 | B9: USWJZX | C9: 点击进入 | D9: 玩具卖家备货性价比首选 | E9: 22-32个自然日 | F9: 玩具产品性价比首选方案
A10: 奥克兰744 | B10: US744 | C10: 点击进入 | D10: 奥克兰低成本之王，开船744小时提取 | E10: 26-34个自然日 | F10: 奥克兰低成本方案
A11: 洛杉矶768 | B11: USW768 | C11: 点击进入 | D11: 美西低成本之王，开船768小时送仓 | E11: 24-32个自然日送仓 | F11: 美西低成本方案
A12: 西雅图788 | B12: US788 | C12: 点击进入 | D12: 美西低成本之王，西雅图港口直提，开船788小时送仓 | E12: 28-37个自然日 | F12: 美西低成本方案
A13: 芝加哥840 | B13: US840 | C13: 点击进入 | D13: 芝加哥仓点性价比之王，LB港口卸船后优先上火车中转芝加哥，开船840小时送仓 | E13: 30-35个自然日 | F13: 美中低成本方案
... A19: 海运快递派 | B19: USKD | C19: 点击进入 | D19: 快递派专线渠道 | E19: 12-15自然日提取 | F19: 最快12-15自然日提取
A20: 报价表有效期：2026/1/19起
A21: 发货前请查看注意事项！
A22: 收货流程：通过我司系统下单→贴外箱唛→群上通知收货→核对出货数据→出货后不接受异议【为了正常转运，请及时支付已出账单运费】
A23: 我司自助下单系统：http://gzfdgy.nextsls.com/wos
A24: 飞点官网：https://freedomscm.com/
A25: 公司总部地址：广州市白云区云城南四路239号云图汇1栋505室飞点跨境供应链（商务接待，不收货） 深圳办公室：深圳市龙岗区双子塔东塔45层4503C号飞点跨境供应链（商务接待，不收货） 佛山办公室：佛山市南海区桂城街道招商置地中心1座1020号飞点跨境供应链（商务接待，不收货） 中山办公室：中山市东区博爱路28号远洋广场2幢1605号飞点跨境供应链（商务接待，不收货） 汕头办公室：汕头市澄海区下窖华新路西二巷1号二楼飞点跨境供应链（商务接待，不收货）
A26: 广州仓：广州市花都区花东镇启源大道6号5栋一楼整层（飞点跨境供应链） 金华仓：浙江省金华市金东区金义综合保税区S2仓C区飞点跨境供应链（园区入口：广顺南路与集贤路交汇处） 澄海仓：汕头市澄海区金鸿公路宝奥城内1-117~132号门(飞点跨境供应链) 东莞仓：广东省东莞市凤观路42号孔雀源物流园D栋（飞点跨境供应链） 中山仓：中山市火炬开发区兴业路27号金辉工业园区8号仓（飞点跨境供应链）

Sheet 海运船期表
A2: 渠道 | B2: 船司 | C2: 航线 | D2: 出发港 | E2: 目的港 | F2: 截单时间 | I2: 预计 开船时间 | J2: 预计 到港时间 | K2: 航程 (自然日） | L2: 最快提取/送仓时间 （开船后第二天算起）
F3: 珠三角 | G3: 汕头 | H3: 义乌
A4: 美森360 | B4: MATSON | C4: CLX | D4: 上海港 | E4: 长滩港 | F4: 46046 | G4: 46046 | H4: 46047 | I4: 46050 | J4: 46061 | K4: 11 | L4: 46063
A5: 美森432 | B5: MATSON | C5: MAX | D5: 上海港 | E5: 长滩港 | F5: 46047 | G5: 46047 | H5: 46048 | I5: 46051 | J5: 46062 | K5: 11 | L5: 46064
A6: EX456 | B6: ZIM/HEDE | C6: ZEX/2601E | D6: 盐田港/南沙港 | E6: 洛杉矶港 | F6: 46047 | G6: 46046 | H6: 46046 | I6: 46050 | J6: 46064 | K6: 14 | L6: 46067
A7: 快船600 | B7: COSCO | C7: SEA/SEA3 | D7: 盐田港 | E7: 长滩港 | F7: 46045 | G7: 46044 | H7: 46044 | I7: 46051 | J7: 46068 | K7: 17 | L7: 46074
B8: COSCO | C8: SEA | D8: 南沙港 | E8: 长滩港 | F8: 46047 | G8: 46046 | H8: 46046 | I8: 46056 | J8: 46074 | K8: 18 | L8: 46081
B9: COSCO | C9: AAC/AAC2 | D9: 宁波港 | E9: 长滩港 | F9: 46046 | G9: 46046 | H9: 46047 | I9: 46056 | J9: 46070 | K9: 14 | L9: 46077
A10: TY720 | B10: COSCO | C10: SEA/SEA3 | D10: 盐田港 | E10: 洛杉矶港 | F10: 46045 | G10: 46044 | H10: 46044 | I10: 46051 | J10: 46068 | K10: 17 | L10: 46075
B11: COSCO | C11: AAC/AAC2 | D11: 宁波港 | E11: 洛杉矶港 | F11: 46046 | G11: 46046 | H11: 46047 | I11: 46056 | J11: 46070 | K11: 14 | L11: 46077
A12: 奥克兰744 | B12: EMC | C12: AAS3 | D12: 盐田港 | E12: 奥克兰港 | F12: 46047 | G12: 46046 | H12: 46046 | I12: 46062 | J12: 46081 | K12: 19 | L12: 46088
B13: EMC | C13: AAC2 | D13: 宁波港 | E13: 奥克兰港 | F13: 46046 | G13: 46046 | H13: 46047 | I13: 46056 | J13: 46079 | K13: 23 | L13: 46086
A14: 洛杉矶768 | B14: COSCO/YML | C14: SEA/PS7 | D14: 南沙港 | E14: 长滩港 | F14: 46047 | G14: 46046 | H14: 46046 | I14: 46063 | J14: 46080 | K14: 17 | L14: 46087
B15: COSCO/YML | C15: SEA/PS3 | D15: 盐田港 | E15: 长滩港 | F15: 46047 | G15: 46046 | H15: 46046 | I15: 46058 | J15: 46074 | K15: 16 | L15: 46081
B16: COSCO/YML | C16: AAC/AAC4/PS5 | D16: 宁波港 | E16: 长滩港 | F16: 46046 | G16: 46046 | H16: 46047 | I16: 46063 | J16: 46077 | K16: 14 | L16: 46084
A17: 西雅图788 | B17: COSCO | C17: MPNM | D17: 盐田港 | E17: 西雅图港 | F17: 46047 | G17: 46046 | H17: 46046 | I17: 46069 | J17: 46097 | K17: 28 | L17: 46104
B18: COSCO | C18: MPNM | D18: 宁波港 | E18: 西雅图港 | F18: 46046 | G18: 46046 | H18: 46047 | I18: 46074 | J18: 46097 | K18: 23 | L18: 46104
A19: 芝加哥840 | B19: COSCO | C19: SEA/SEA3 | D19: 盐田港 | E19: 芝加哥 | F19: 46046 | G19: 46045 | H19: 46045 | I19: 46056 | J19: 46085 | K19: 29 | L19: 46092
B20: COSCO/EMC | C20: AAC2 | D20: 宁波港 | E20: 芝加哥 | F20: 46045 | G20: 46045 | H20: 46046 | I20: 46056 | J20: 46084 | K20: 28 | L20: 46091
A21: 休斯顿866 | B21: COSCO | C21: GME | D21: 盐田港 | E21: 休斯顿港 | F21: 46047 | G21: 46046 | H21: 46046 | I21: 46055 | J21: 46080 | K21: 25 | L21: 46087
B22: COSCO | C22: GME | D22: 宁波港 | E22: 休斯顿港 | F22: 46046 | G22: 46046 | H22: 46047 | I22: 46057 | J22: 46087 | K22: 30 | L22: 46094
A23: 萨凡纳888 | B23: COSCO/EMC | C23: AWE3/AWE4 | D23: 盐田港 | E23: 萨凡纳港 | F23: 46047 | G23: 46046 | H23: 46046 | I23: 46055 | J23: 46086 | K23: 31 | L23: 46093
B24: COSCO/EMC | C24: AWE2/AWE1 | D24: 宁波港 | E24: 萨凡纳港 | F24: 46046 | G24: 46046 | H24: 46047 | I24: 46058 | J24: 46087 | K24: 29 | L24: 46094
A25: 纽约960 | B25: COSCO/EMC | C25: AWE3/AWE4 | D25: 盐田港 | E25: 纽约港 | F25: 46047 | G25: 46046 | H25: 46046 | I25: 46054 | J25: 46087 | K25: 33 | L25: 46094
B26: COSCO/EMC | C26: AWE2/AWE1 | D26: 宁波港 | E26: 纽约港 | F26: 46046 | G26: 46046 | H26: 46047 | I26: 46065 | J26: 46096 | K26: 31 | L26: 46103
A27: 自主装柜 | 海运市场优质后端 | 信誉清关 | 快捷海运转运派送 船期来自船司官网，最终船司可能会有调整，包括但不限于出现延期或者空班等情况，最终时效以实际开船时间为准 本表最终解释权归飞点供应链所有
A28: 用 心 承 载 每 一 份 托 付

Sheet 注意事项
B2: 发货前须知
B3: 如确认在我司发货，即认可我司条款
B4: 为了准确快捷入库，发货前尽量配合贴好入仓标签/FBA标签/SKU标签等，因未贴标签或未及时告知导致仓库未能及时入库延误船期的我司概不负责！国内贴标费1元/张
B5: 国内段运输发票与报关费发票所示价格均不含税，如需开具发票，请提前跟我司客服咨询税点信息。
B6: 自2025年5月12日起 符合美国清关第232条款的钢铁制品、铝制品关税附加费加收0.5元/KG；
B7: 1、所有货物，内包装，及外包装必须有产地标识“MADE IN CHINA”否则我司拒收，软包装如产品破损，或丢失不予理赔
B8: 2、有申报不符、带电、带磁、带电机产品，违禁品，敏感品，未向我司如实申报，瞒报，少报，导致整批货物延误， 此情况极其恶劣，此类货物未申报/申报不符视为冲货，我司将追究其责任，并罚款5000RMB以上。
B9: 3、出货后若有拦截件情况，免仓期7天，超免仓期后未操作需要预收一个月仓储费，若超一个月继续存仓则需要继续再预收下一个月仓储费，以此类推。仓储费：30天内：1美金/方/天；30天-60天内：2美金/天/方；60天-90天3美金/方/天，90天以上：5美金/方/天，不足1方按1方计算。
B10: 索赔流程
B11: 一、索赔标准（签订合同）
B12: 货物在国外（境外）未提取派送前和货物提取派送后丢失、短少、污染、损坏的赔偿方案，赔偿标准： 1）丢件赔偿：海运，海外仓，未提取上网经核实丢件，按照采购价值进行赔偿，赔偿最高为3倍运费且不退运费。 2）空派未提取上网经核实丢件，按照采购价值进行赔偿，赔偿最高为1.5倍运费且不退运费。 3）空派、海派已上网提取丢件，按采购价值赔偿最高不超过100美金/票。（非整箱丢失，内装物品短少，不予赔偿。） 4）头程国际快递丢件赔偿，可协助向快递官方索赔，按官方赔偿金额赔偿。 5）、高货值产品，如客户另外要求亦可自购保险,请发货前仔细阅读,否则视为同意此规定.
B13: 二、索赔标准（未签订合同） 赔偿方案:（选择此渠道发货表示默认我司的赔偿标准） 1）、在国际运输过程中如货物丢失或者扣关（如因侵权问题，我司不承担任何责任并且保留追究发件人因此带来对我司的损失的赔偿）按海运RMB20/KG赔偿，空运RMB20/KG赔偿，不退运费. 2）、提取后丢失或其他问题，协助跟服务商申请索赔，不承诺索赔成功。索赔受理期限为自入库起 30 个自然日内，逾期不予受理。按申报价值赔偿(最高不超（100USD/票);入亚马逊仓的货物网上显示未签收的需提供后台数据方可开查。 3）、同一航次一票货部份提取,剩下部份超过30个工作日未提取可直接申请赔偿.如遇自然灾害以及不可抗因素，本公司将不做任何赔偿！ 如客户另外要求亦可自购保险,请发货前仔细阅读,否则视为同意此规定. 4）、一票多件的货物只要有其中部分有UPS/FEDEX提取信息,其他子单未更新的都属于UPS/FEDEX更新取件问题，不计入提取延误赔偿。 5）、高货值产品，如客户另外要求亦可自购保险,请发货前仔细阅读,否则视为同意此规定.
... B87: 1、珠三角地区：距离入库仓库地址的距离对应的收货重量--30公里-200kg起、50公里-300kg起、70公里-400kg起、100公里500kg起。 2、华东及汕头仓库单询。 3、未达到标准可自行送货或分摊收货费用。

Sheet 国际快递
A2: 美国快递
A3: UPS包税
C4: 珠三角交货价 | F4: 汕头交货价 | I4: 义乌交货价
A5: 国家地区 | B5: 渠道 | C5: 实重23kg+ | D5: 47-72 kg | E5: 73-99 kg | F5: 实重23kg+ | G5: 47-72 kg | H5: 73-99 kg | I5: 实重23kg+ | J5: 47-72 kg | K5: 73-99 kg | L5: 操作要求 | M5: 提取时效 | N5: 备注 | O5: 计重方式
A6: 美国全境 （偏远地区另计） | B6: 大陆UPS红单特快/5000 | C6: 70 | D6: 69.5 | E6: 69 | F6: 70.5 | G6: 70 | H6: 69.5 | I6: 71 | J6: 70.5 | K6: 70 | L6: 单箱8KG起 单箱计费 操作费150元/票 | M6: 特快服务不排仓 不限量 | N6: 私人地址35元/件 带电产品、偏远地区单询 | O6: 体积重/5000，单箱计重
A7: 美国全境 （偏远地区另计） | B7: 大陆UPS红单/5000 | C7: 61 | D7: 60.5 | E7: 60 | F7: 61.5 | G7: 61 | H7: 60.5 | I7: 62 | J7: 61.5 | K7: 61 | M7: 不排仓 不限量
A8: 美国全境 （偏远地区另计） | B8: 香港UPS红单/5000 | C8: 63 | D8: 62.5 | E8: 62 | F8: 64 | G8: 63.5 | H8: 63 | I8: 64 | J8: 63.5 | K8: 63 | M8: 不排仓 不限量 | N8: 私人地址35元/件 偏远地区单询
A9: DHL
A10: 国家地区 | B10: 渠道 | C10: 实重31kg+ | D10: 47-72 kg | E10: 73-99 kg | F10: 实重31kg+ | G10: 47-72 kg | H10: 73-99 kg | I10: 实重31kg+ | J10: 47-72 kg | K10: 73-99 kg | L10: 操作要求 | M10: 提取时效 | N10: 备注 | O10: 计重方式
A11: 美国全境 （偏远地区另计） | B11: 大陆DHL/5000 | C11: * | D11: * | E11: * | F11: * | G11: * | H11: * | I11: * | J11: * | K11: * | L11: 单箱8KG起 单箱计费 | M11: 不排仓 不限量 | N11: 仅限普货和FBA地址 私人地址35元/件 偏远地区单询 | O11: 体积重/5000，单箱计重
A12: 美国全境 （偏远地区另计） | B12: 香港DHL/5000 | C12: * | D12: * | E12: * | F12: * | G12: * | H12: * | I12: * | J12: * | K12: * | N12: 仅限普货和FBA地址 私人地址35元/件 带电产品、偏远地区单询
A13: 自主渠道，自主打单，当天出单号 （已含旺季附加费、燃油、关税）（带电产品单询）
A14: 附加费及要求
A15: UPS代理发货申明：提取后官方时效延误，产品清关问题，产生关税及其它附加费用由客户承担。
A16: 特别提醒：汕头、义乌交货价格以货物实际到广州仓时间报价表价格为准。
A17: 1、单箱重量不得超过24KG，超过24KG需加收超重费，单询
A18: 2、单箱计重，DHL渠道以0.5为一个进位数，如21.23KG，计算为21.5KG；UPS渠道以1为一个进位数，如21.23KG，计算为22KG。
A19: 3、整票以1为一个计费数.整票如50.3，UPS计算为51KG
A20: 4、单箱最低计费重8KG 超过单边120CM需超长费，单询
A21: 5、单票超5个品名以上+30RMB/个
A22: 6、超大件可单询！
A23: 国内贴标费 | G23: 1元/张 | J23: 为了准确快捷入库，请尽量配合贴好入仓标签/FBA标签/SKU标签等，因未贴标签或未及时告知导致仓库未能及时入库延误船期的我司概不负责
A24: 注： 为了您的货物安全顺利到达目的地，大陆渠道只接普货，坚决不收牌子货、违禁品；带电带磁、请走香港渠道，违者扣货，罚款5000元，由于货物问题，产生一切费用由客户承担！
A25: 注意事项：提取后，丢失，损坏或延误，我司只负责协助申请赔偿，具体赔偿方案与金额以UPS官方为准！

Sheet 美国空运240
A2: 美国空运240
A3: 快递派(大陆航班）
C4: 珠三角交货价 | G4: 汕头交货价 | K4: 义乌交货价
A5: 邮编开头 重量段 | C5: 12KG+ | D5: 21KG+ | E5: 51KG+ | F5: 101KG+ | G5: 12KG+ | H5: 21KG+ | I5: 51KG+ | J5: 101KG+ | K5: 12KG+ | L5: 21KG+ | M5: 51KG+ | N5: 101KG+ | O5: 承诺提取时效 交货后第二天算起
A6: 8,9 | C6: 40 | D6: 39 | E6: 38 | F6: 37 | G6: 41 | H6: 40 | I6: 39 | J6: 38 | K6: 41 | L6: 40 | M6: 39 | N6: 38 | O6: 5-12个自然日
A7: 6,7 | C7: 41 | D7: 40 | E7: 39 | F7: 38 | G7: 42 | H7: 41 | I7: 40 | J7: 39 | K7: 42 | L7: 41 | M7: 40 | N7: 39
A8: 4,5 | C8: 42 | D8: 41 | E8: 40 | F8: 39 | G8: 43 | H8: 42 | I8: 41 | J8: 40 | K8: 43 | L8: 42 | M8: 41 | N8: 40
A9: 0,1,2,3 | C9: 43 | D9: 42 | E9: 41 | F9: 40 | G9: 44 | H9: 43 | I9: 42 | J9: 41 | K9: 44 | L9: 43 | M9: 42 | N9: 41
A10: 卡派(大陆航班）
C11: 珠三角交货价 | G11: 汕头交货价 | K11: 义乌交货价
A12: 仓库 重量段 | C12: 12KG+ | E12: 201KG+ | F12: 501KG+ | G12: 12KG+ | I12: 201KG+ | J12: 501KG+ | K12: 12KG+ | M12: 201KG+ | N12: 501KG+ | O12: 参考签收时效 交货后第二天算起
A13: ONT8/LGB8 SBD1/JOT1/POC1/POC3 | C13: * | E13: 41.5 | F13: 41 | G13: * | I13: 42.5 | J13: 42 | K13: * | M13: 43.5 | N13: 43 | O13: 7-15个自然日
A14: SMF3/GYR3 GYR2/SCK4/MIT2/QXY5/GEU3/GEU2/GEU5 | C14: * | E14: 42.5 | F14: 42 | G14: * | I14: 43.5 | J14: 43 | K14: * | M14: 44.5 | N14: 44 | O14: 8-16个自然日
A15: 空派交货第二天算起5-12个自然日提取，第13个自然日起未提取按1元/kg/自然日赔付，单票最高赔付3元/kg/自然日。因不可抗力因素和查验即取消超时赔付服务 单箱最低12KG起 | J15: 空卡交货后第二天算起7-15天签收
A16: 美国空运240（带电/化妆品）
A17: 快递派(香港航班）
C18: 珠三角交货价 | G18: 汕头交货价 | K18: 义乌交货价
A19: 邮编开头 重量段 | C19: 12KG+ | D19: 21KG+ | E19: 51KG+ | F19: 101KG+ | G19: 12KG+ | H19: 21KG+ | I19: 51KG+ | J19: 101KG+ | K19: 12KG+ | L19: 21KG+ | M19: 51KG+ | N19: 101KG+ | O19: 提取时效 交货后第二天算起
A20: 8,9 | C20: * | D20: * | E20: * | F20: * | G20: * | H20: * | I20: * | J20: * | K20: * | L20: * | M20: * | N20: * | O20: 7-14个自然日
A21: 6,7 | C21: * | D21: * | E21: * | F21: * | G21: * | H21: * | I21: * | J21: * | K21: * | L21: * | M21: * | N21: *
A22: 4,5 | C22: * | D22: * | E22: * | F22: * | G22: * | H22: * | I22: * | J22: * | K22: * | L22: * | M22: * | N22: *
A23: 0,1,2,3 | C23: * | D23: * | E23: * | F23: * | G23: * | H23: * | I23: * | J23: * | K23: * | L23: * | M23: * | N23: *
A24: 交货第二天算起7-14个自然日提取，第15个自然日起未提取按1元/kg/自然日赔付，单票最高赔付3元/kg/自然日。因不可抗力因素和查验即取消超时赔付服务 单箱最低12KG起
A25: 特别提醒：汕头、义乌交货价格以货物实际到广州仓时间报价表价格为准。
A26: 赔付条款如遇海关检查/节假日/PO失效或亚马逊推约等不可控因素等原因即取消赔付服务
A27: 附加费及要求
A28: 单独报关件单询！单票超5个品名以上+50RMB/个，偏远费+2RMB/KG，单箱计费重12KG起，尾端UPS/FEDEX派送，非FBA商业地址+1元KG，住宅地址+2KG
A29: 注明：每周报价表为实时报价，不可控因素或市场变化调节过大时，升或降以到仓价格为准
A30: 包税附加费，未列明产品请跟业务联系
A31: 需加收产品及杂费 | G31: 加收金额 | J31: 备注
A32: 除高价值，高关税产品，其余普通产品无附加费 | G32: 无附加费 | J32: 由于产品本身专利或知识产权问题产生扣关，货物退回等后续问题由客户承担，我司保留追究的权力
A33: 纺织品，笔（铅笔不接）、鞋子、服装（穿戴）、包包、蓝牙产品（有标志不接）、玩具类（必须有CPC类证书） | G33: 单询 | J33: FDA类产品，海关可能会查验。由于客户提供错误的FDA ID. 产生扣关，关税，货物退回等后续问题由客户承担，我司并保留追究的权力
A34: 化工品（指甲胶、精油、口红、眼影，卸妆水、洗发水等） | G34: 单询 | J34: 提供真实有效期内商检、MSDS认证视为普货，无需附加费（证书是否有效以相关部门是否认可为准）
A35: 国内贴标费 | G35: 1元/张 | J35: 为了准确快捷入库，请尽量配合贴好入仓标签/FBA标签/SKU标签等，因未贴标签或未及时告知导致仓库未能及时入库延误船期的我司概不负责
A36: 报价未注明的产品，请将提供产品信息给我司客服或业务进行核实是否有附加费 | G36: 待确定 | J36: 因美对华加增2000亿美金关税影响，请单独询问销售
A37: 汽车灯 | J37: 4元/kg，低消50元/票
A38: 普通带磁产品 | J38: 2元/KG，封顶200元
A39: 超5个品名；第6个品名开始收取 | J39: 50元/品名
A40: 马达，电机类产品 | J40: 500元/品名
A41: 木、竹、藤制品 | J41: 100元/票
...

Sheet 价格快查表
B2: 渠道价格快速查找 | BO2: 渠道价格快速查找
B3: 输入右边信息 | C3: 国内交货仓 | D3: 平台 | E3: 目的仓/邮编开头 | F3: 计费方式 | G3: 送仓方式 | BL3: 输入右边信息 | BM3: 国内交货仓 | BO3: 目的仓/邮编开头 | BP3: 计费方式 | BQ3: 送仓方式
C4: 珠三角 | D4: 亚马逊 | E4: 8 | F4: KG | G4: 卡派 | BM4: =C4 | BN4: =D4 | BO4: =E4 | BP4: =F4 | BQ4: =G4
B5: 渠道 | C5: 渠道单价 (KG/CBM) | D5: 参考时效 （开船后） | E5: ETD | F5: ETA | G5: 航行日 | BL5: 渠道 | BM5: 渠道单价 (KG/CBM) | BN5: 参考时效 （开船后） | BO5: ETD | BP5: ETA | BQ5: 航行日
B6: 美森360 | C6: =BM6 | D6: =BN6 | E6: =BO6 | F6: =BP6 | G6: =BQ6 | BL6: 美森360 | BM6: =IFERROR(IF(E4="","-",IF(AND($G$4="卡派",$F$4="KG",$C$4="珠三角",$D$4="亚马逊"),CONCATENATE("8KG+："&VLOOKUP("*"&$E$4&"*",'美西特快专线'!$A$6:$E$18,2,0)," 101KG+："&VLOOKUP("*"&$E$4&"*",'美西特快专线'!$A$6:$E$18,3,0)),IF(AND($G$4="卡派",$F$4="KG",$C$4="汕头仓",$D$4="亚马逊"),CONCATENATE("8KG+："&VLOOKUP("*"&$E$4&"*",'美西特快专线'!$A$6:$E$18,2,0)," 101KG+："&VLOOKUP("*"&$E$4&"*",'美西特快专线'!$A$6:$E$18,3,0)),IF(AND($G$4="卡派",$F$4="KG",$C$4="义乌仓",$D$4="亚马逊"),CONCATENATE("8KG+："&VLOOKUP("*"&$E$4&"*",'美西特快专线'!$A$6:$E$18,4,0)," 101KG+："&VLOOKUP("*"&$E$4&"*",'美西特快专线'!$A$6:$E$18,5,0)),IF(AND($G$4="卡派",$F$4="按方不包税",$C$4="珠三角",$D$4="亚马逊"),CONCATENATE("2CBM+："&VLOOKUP("*"&$E$4&"*",'按方不包税'!$A$6:$C$12,2,0)),IF(AND($G$4="卡派",$F$4="按方不包税",$C$4="汕头仓",$D$4="亚马逊"),CONCATENATE("2CBM+："&VLOOKUP("*"&$E$4&"*",'按方不包税'!$A$6:$C$12,2,0)),IF(AND($G$4="卡派",$F$4="按方不包税",$C$4="义乌仓",$D$4="亚马逊"),CONCATENATE("2CBM+："&VLOOKUP("*"&$E$4&"*",'按方不包税'!$A$6:$C$12,3,0)),IF(AND($G$4="卡派",$F$4="KG",$C$4="珠三角",$D$4="沃尔玛专线"),CONCATENATE("501KG+："&VLOOKUP("*"&$E$4&"*",'沃尔玛专线'!$A$6:$G$7,4,0)," 3001KG+："&VLOOKUP("*"&$E$4&"*",'沃尔玛专线'!$A$6:$G$7,5,0)," 5001KG+："&VLOOKUP("*"&$E$4&"*",'沃尔玛专线'!$A$6:$G$7,6,0)),IF(AND($G$4="卡派",$F$4="KG",$C$4="汕头仓",$D$4="沃尔玛专线"),CONCATENATE("501KG+："&VLOOKUP("*"&$E$4&"*",'沃尔玛专线'!$A$6:$G$7,4,0)," 3001KG+："&VLOOKUP("*"&$E$4&"*",'沃尔玛专线'!$A$6:$G$7,5,0)," 5001KG+："&VLOOKUP("*"&$E$4&"*",'沃尔玛专线'!$A$6:$G$7,6,0)),IF(AND($G$4="卡派",$F$4="KG",$C$4="义乌仓",$D$4="沃尔玛专线"),CONCATENATE("501KG+："&VLOOKUP("*"&$E$4&"*",'沃尔玛专线'!$A$6:$G$7,4,0)," 3001KG+："&VLOOKUP("*"&$E$4&"*",'沃尔玛专线'!$A$6:$G$7,5,0)," 5001KG+："&VLOOKUP("*"&$E$4&"*",'沃尔玛专线'!$A$6:$G$7,6,0)),IF(AND($G$4="快递派",$F$4="KG",$C$4="珠三角",$D$4="亚马逊"),CONCATENATE("12KG+："&VLOOKUP("*"&$E$4&"*",'海运快递派'!$A$5:$E$8,3,0)," 51KG+："&VLOOKUP("*"&$E$4&"*",'海运快递派'!$A$5:$E$8,4,0)," 101KG+："&VLOOKUP("*"&$E$4&"*",'海运快递派'!$A$5:$E$8,5,0)),IF(AND($G$4="快递派",$F$4="KG",$C$4="汕头仓",$D$4="亚马逊"),CONCATENATE("12KG+："&VLOOKUP("*"&$E$4&"*",'海运快递派'!$A$5:$E$8,3,0)," 51KG+："&VLOOKUP("*"&$E$4&"*",'海运快递派'!$A$5:$E$8,4,0)," 101KG+："&VLOOKUP("*"&$E$4&"*",'海运快递派'!$A$5:$E$8,5,0)),IF(AND($G$4="快递派",$F$4="KG",$C$4="义乌仓",$D$4="亚马逊"),CONCATENATE("12KG+："&VLOOKUP("*"&$E$4&"*",'海运快递派'!$A$5:$E$8,3,0)," 51KG+："&VLOOKUP("*"&$E$4&"*",'海运快递派'!$A$5:$E$8,4,0)," 101KG+："&VLOOKUP("*"&$E$4&"*",'海运快递派'!$A$5:$E$8,5,0)),"-"))))))))))))),"-") | BN6: =IFERROR(IF($E$4="","-",IF(AND($G$4="卡派",$F$4="KG",$C$4="珠三角",$D$4="亚马逊"),VLOOKUP("*"&$E$4&"*",'美西特快专线'!$A$6:$F$18,6,0),IF(AND($G$4="卡派",$F$4="KG",$C$4="汕头仓",$D$4="亚马逊"),VLOOKUP("*"&$E$4&"*",'美西特快专线'!$A$6:$F$18,6,0),IF(AND($G$4="卡派",$F$4="KG",$C$4="义乌仓",$D$4="亚马逊"),VLOOKUP("*"&$E$4&"*",'美西特快专线'!$A$6:$F$18,6,0),IF(AND($G$4="卡派",$F$4="按方不包税",$C$4="珠三角",$D$4="亚马逊"),VLOOKUP("*"&$E$4&"*",'按方不包税'!$A$6:$E$12,4,0),IF(AND($G$4="卡派",$F$4="按方不包税",$C$4="汕头仓",$D$4="亚马逊"),VLOOKUP("*"&$E$4&"*",'按方不包税'!$A$6:$E$12,4,0),IF(AND($G$4="卡派",$F$4="按方不包税",$C$4="义乌仓",$D$4="亚马逊"),VLOOKUP("*"&$E$4&"*",'按方不包税'!$A$6:$E$12,4,0),IF(AND($G$4="卡派",$F$4="KG",$C$4="珠三角",$D$4="沃尔玛专线"),VLOOKUP("*"&$E$4&"*",'沃尔玛专线'!$A$6:$G$7,7,0),IF(AND($G$4="卡派",$F$4="KG",$C$4="汕头仓",$D$4="沃尔玛专线"),VLOOKUP("*"&$E$4&"*",'沃尔玛专线'!$A$6:$G$7,7,0),IF(AND($G$4="卡派",$F$4="KG",$C$4="义乌仓",$D$4="沃尔玛专线"),VLOOKUP("*"&$E$4&"*",'沃尔玛专线'!$A$6:$G$7,7,0),IF(AND($G$4="快递派",$F$4="KG",$C$4="珠三角",$D$4="亚马逊"),VLOOKUP("*"&$E$4&"*",'海运快递派'!$A$5:$F$8,6,0),IF(AND($G$4="快递派",$F$4="KG",$C$4="汕头仓",$D$4="亚马逊"),VLOOKUP("*"&$E$4&"*",'海运快递派'!$A$5:$F$8,6,0),IF(AND($G$4="快递派",$F$4="KG",$C$4="义乌仓",$D$4="亚马逊"),VLOOKUP("*"&$E$4&"*",'海运快递派'!$A$5:$F$8,6,0),"-"))))))))))))),"-") | BO6: =CONCATENATE('海运船期表'!$B$4,"-"&'海运船期表'!$C$4," : ",TEXT('海运船期表'!$I$4,"MM-DD")) | BP6: =CONCATENATE('海运船期表'!$B$4,"-"&'海运船期表'!$C$4," : ",TEXT('海运船期表'!$J$4,"MM-DD")) | BQ6: ='海运船期表'!$K$4
B7: 美森432 | C7: =BM7 | D7: =BN7 | E7: =BO7 | F7: =BP7 | G7: =BQ7 | BL7: 美森432 | BM7: =IFERROR(IF(E4="","-",IF(AND($G$4="卡派",$F$4="KG",$C$4="珠三角",$D$4="亚马逊"),CONCATENATE("8KG+："&VLOOKUP("*"&$E$4&"*",'美西特快专线'!$A$6:$M$18,9,0)," 101KG+："&VLOOKUP("*"&$E$4&"*",'美西特快专线'!$A$6:$M$18,10,0)),IF(AND($G$4="卡派",$F$4="KG",$C$4="汕头仓",$D$4="亚马逊"),CONCATENATE("8KG+："&VLOOKUP("*"&$E$4&"*",'美西特快专线'!$A$6:$M$18,9,0)," 101KG+："&VLOOKUP("*"&$E$4&"*",'美西特快专线'!$A$6:$M$18,10,0)),IF(AND($G$4="卡派",$F$4="KG",$C$4="义乌仓",$D$4="亚马逊"),CONCATENATE("8KG+："&VLOOKUP("*"&$E$4&"*",'美西特快专线'!$A$6:$M$18,11,0)," 101KG+："&VLOOKUP("*"&$E$4&"*",'美西特快专线'!$A$6:$M$18,12,0)),IF(AND($G$4="卡派",$F$4="按方不包税",$C$4="珠三角",$D$4="亚马逊"),CONCATENATE("2CBM+："&VLOOKUP("*"&$E$4&"*",'按方不包税'!$A$17:$E$23,2,0)),IF(AND($G$4="卡派",$F$4="按方不包税",$C$4="汕头仓",$D$4="亚马逊"),CONCATENATE("2CBM+："&VLOOKUP("*"&$E$4&"*",'按方不包税'!$A$17:$E$23,2,0)),IF(AND($G$4="卡派",$F$4="按方不包税",$C$4="义乌仓",$D$4="亚马逊"),CONCATENATE("2CBM+："&VLOOKUP("*"&$E$4&"*",'按方不包税'!$A$17:$E$23,3,0)),IF(AND($G$4="卡派",$F$4="KG",$C$4="珠三角",$D$4="沃尔玛专线"),CONCATENATE("501KG+："&VLOOKUP("*"&$E$4&"*",'沃尔玛专线'!$A$8:$G$9,4,0)," 3001KG+："&VLOOKUP("*"&$E$4&"*",'沃尔玛专线'!$A$8:$G$9,5,0)," 5001KG+："&VLOOKUP("*"&$E$4&"*",'沃尔玛专线'!$A$8:$G$9,6,0)),IF(AND($G$4="卡派",$F$4="KG",$C$4="汕头仓",$D$4="沃尔玛专线"),CONCATENATE("501KG+："&VLOOKUP("*"&$E$4&"*",'沃尔玛专线'!$A$8:$G$9,4,0)," 3001KG+："&VLOOKUP("*"&$E$4&"*",'沃尔玛专线'!$A$8:$G$9,5,0)," 5001KG+："&VLOOKUP("*"&$E$4&"*",'沃尔玛专线'!$A$8:$G$9,6,0)),IF(AND($G$4="卡派",$F$4="KG",$C$4="义乌仓",$D$4="沃尔玛专线"),CONCATENATE("501KG+："&VLOOKUP("*"&$E$4&"*",'沃尔玛专线'!$A$8:$G$9,0)," 3001KG+："&VLOOKUP("*"&$E$4&"*",'沃尔玛专线'!$A$8:$G$9,5,0)," 5001KG+："&VLOOKUP("*"&$E$4&"*",'沃尔玛专线'!$A$8:$G$9,6,0)),IF(AND($G$4="快递派",$F$4="KG",$C$4="珠三角",$D$4="亚马逊"),CONCATENATE("12KG+："&VLOOKUP("*"&$E$4&"*",'海运快递派'!$A$13:$F$16,3,0)," 51KG+："&VLOOKUP("*"&$E$4&"*",'海运快递派'!$A$13:$F$16,4,0)," 101KG+："&VLOOKUP("*"&$E$4&"*",'海运快递派'!$A$13:$F$16,5,0)),IF(AND($G$4="快递派",$F$4="KG",$C$4="汕头仓",$D$4="亚马逊"),CONCATENATE("12KG+："&VLOOKUP("*"&$E$4&"*",'海运快递派'!$A$13:$F$16,3,0)," 51KG+："&VLOOKUP("*"&$E$4&"*",'海运快递派'!$A$13:$F$16,4,0)," 101KG+："&VLOOKUP("*"&$E$4&"*",'海运快递派'!$A$13:$F$16,5,0)),IF(AND($G$4="快递派",$F$4="KG",$C$4="义乌仓",$D$4="亚马逊"),CONCATENATE("12KG+："&VLOOKUP("*"&$E$4&"*",'海运快递派'!$A$13:$F$16,3,0)," 51KG+："&VLOOKUP("*"&$E$4&"*",'海运快递派'!$A$13:$F$16,4,0)," 101KG+："&VLOOKUP("*"&$E$4&"*",'海运快递派'!$A$13:$F$16,5,0)),"-"))))))))))))),"-") | BN7: =IFERROR(IF($E$4="","-",IF(AND($G$4="卡派",$F$4="KG",$C$4="珠三角",$D$4="亚马逊"),VLOOKUP("*"&$E$4&"*",'美西特快专线'!$A$6:$M$18,13,0),IF(AND($G$4="卡派",$F$4="KG",$C$4="汕头仓",$D$4="亚马逊"),VLOOKUP("*"&$E$4&"*",'美西特快专线'!$A$6:$M$18,13,0),IF(AND($G$4="卡派",$F$4="KG",$C$4="义乌仓",$D$4="亚马逊"),VLOOKUP("*"&$E$4&"*",'美西特快专线'!$A$6:$M$18,13,0),IF(AND($G$4="卡派",$F$4="按方不包税",$C$4="珠三角",$D$4="亚马逊"),VLOOKUP("*"&$E$4&"*",'按方不包税'!$A$17:$E$23,4,0),IF(AND($G$4="卡派",$F$4="按方不包税",$C$4="汕头仓",$D$4="亚马逊"),VLOOKUP("*"&$E$4&"*",'按方不包税'!$A$17:$E$23,4,0),IF(AND($G$4="卡派",$F$4="按方不包税",$C$4="义乌仓",$D$4="亚马逊"),VLOOKUP("*"&$E$4&"*",'按方不包税'!$A$17:$E$23,4,0),IF(AND($G$4="卡派",$F$4="KG",$C$4="珠三角",$D$4="沃尔玛专线"),VLOOKUP("*"&$E$4&"*",'沃尔玛专线'!$A$8:$G$9,7,0),IF(AND($G$4="卡派",$F$4="KG",$C$4="汕头仓",$D$4="沃尔玛专线"),VLOOKUP("*"&$E$4&"*",'沃尔玛专线'!$A$8:$G$9,7,0),IF(AND($G$4="卡派",$F$4="KG",$C$4="义乌仓",$D$4="沃尔玛专线"),VLOOKUP("*"&$E$4&"*",'沃尔玛专线'!$A$8:$G$9,7,0),IF(AND($G$4="快递派",$F$4="KG",$C$4="珠三角",$D$4="亚马逊"),VLOOKUP("*"&$E$4&"*",'海运快递派'!$A$13:$F$16,6,0),IF(AND($G$4="快递派",$F$4="KG",$C$4="汕头仓",$D$4="亚马逊"),VLOOKUP("*"&$E$4&"*",'海运快递派'!$A$13:$F$16,6,0),IF(AND($G$4="快递派",$F$4="KG",$C$4="义乌仓",$D$4="亚马逊"),VLOOKUP("*"&$E$4&"*",'海运快递派'!$A$13:$F$16,6,0),"-"))))))))))))),"-") | BO7: =CONCATENATE('海运船期表'!$B$5,"-"&'海运船期表'!$C$5," : ",TEXT('海运船期表'!$I$5,"MM-DD")) | BP7: =CONCATENATE('海运船期表'!$B$5,"-"&'海运船期表'!$C$5," : ",TEXT('海运船期表'!$J$5,"MM-DD")) | BQ7: ='海运船期表'!$K$5
B8: EX456 | C8: =BM8 | D8: =BN8 | E8: =BO8 | F8: =BP8 | G8: =BQ8 | BL8: EX456 | BM8: =IFERROR(IF($E$4="","-",IF(AND($G$4="卡派",$F$4="KG",$C$4="珠三角",$D$4="亚马逊"),CONCATENATE("8KG+："&VLOOKUP("*"&$E$4&"*",'美西特快专线'!$A$6:$R$18,16,0)," 101KG+："&VLOOKUP("*"&$E$4&"*",'美西特快专线'!$A$6:$R$18,17,0)),IF(AND($G$4="卡派",$F$4="KG",$C$4="汕头仓",$D$4="亚马逊"),CONCATENATE("8KG+："&VLOOKUP("*"&$E$4&"*",'美西特快专线'!$A$6:$R$18,16,0)," 101KG+："&VLOOKUP("*"&$E$4&"*",'美西特快专线'!$A$6:$R$18,17,0)),IF(AND($G$4="卡派",$F$4="KG",$C$4="义乌仓",$D$4="亚马逊"),CONCATENATE("8KG+："&VLOOKUP("*"&$E$4&"*",'美西特快专线'!$A$6:$R$18,16,0)," 101KG+："&VLOOKUP("*"&$E$4&"*",'美西特快专线'!$A$6:$R$18,17,0)),IF(AND($G$4="卡派",$F$4="按方不包税",$C$4="珠三角",$D$4="亚马逊"),CONCATENATE("2CBM+："&VLOOKUP("*"&$E$4&"*",'按方不包税'!$A$28:$E$34,2,0)),IF(AND($G$4="卡派",$F$4="按方不包税",$C$4="汕头仓",$D$4="亚马逊"),CONCATENATE("2CBM+："&VLOOKUP("*"&$E$4&"*",'按方不包税'!$A$28:$E$34,2,0)),IF(AND($G$4="卡派",$F$4="按方不包税",$C$4="义乌仓",$D$4="亚马逊"),CONCATENATE("2CBM+："&VLOOKUP("*"&$E$4&"*",'按方不包税'!$A$28:$E$34,2,0)),IF(AND($G$4="卡派",$F$4="KG",$C$4="珠三角",$D$4="沃尔玛专线"),CONCATENATE("501KG+："&VLOOKUP("*"&$E$4&"*",'沃尔玛专线'!$A$10:$G$11,4,0)," 3001KG+："&VLOOKUP("*"&$E$4&"*",'沃尔玛专线'!$A$10:$G$11,5,0)," 5001KG+："&VLOOKUP("*"&$E$4&"*",'沃尔玛专线'!$A$10:$G$11,6,0)),IF(AND($G$4="卡派",$F$4="KG",$C$4="汕头仓",$D$4="沃尔玛专线"),CONCATENATE("501KG+："&VLOOKUP("*"&$E$4&"*",'沃尔玛专线'!$A$10:$G$11,7,0)," 3001KG+："&VLOOKUP("*"&$E$4&"*",'沃尔玛专线'!$A$10:$G$11,9,0)," 5001KG+："&VLOOKUP("*"&$E$4&"*",'沃尔玛专线'!$A$10:$G$11,9,0)),IF(AND($G$4="卡派",$F$4="KG",$C$4="义乌仓",$D$4="沃尔玛专线"),CONCATENATE("501KG+："&VLOOKUP("*"&$E$4&"*",'沃尔玛专线'!$A$10:$G$11,10,0)," 3001KG+："&VLOOKUP("*"&$E$4&"*",'沃尔玛专线'!$A$10:$G$11,11,0)," 5001KG+："&VLOOKUP("*"&$E$4&"*",'沃尔玛专线'!$A$10:$G$11,12,0)),IF(AND($G$4="快递派",$F$4="KG",$C$4="珠三角",$D$4="亚马逊"),CONCATENATE("12KG+："&VLOOKUP("*"&$E$4&"*",'海运快递派'!$A$21:$F$24,3,0)," 51KG+："&VLOOKUP("*"&$E$4&"*",'海运快递派'!$A$21:$F$24,4,0)," 101KG+："&VLOOKUP("*"&$E$4&"*",'海运快递派'!$A$21:$F$24,5,0)),IF(AND($G$4="快递派",$F$4="KG",$C$4="汕头仓",$D$4="亚马逊"),CONCATENATE("12KG+："&VLOOKUP("*"&$E$4&"*",'海运快递派'!$A$21:$F$24,3,0)," 51KG+："&VLOOKUP("*"&$E$4&"*",'海运快递派'!$A$21:$F$24,4,0)," 101KG+："&VLOOKUP("*"&$E$4&"*",'海运快递派'!$A$21:$F$24,5,0)),IF(AND($G$4="快递派",$F$4="KG",$C$4="义乌仓",$D$4="亚马逊"),CONCATENATE("12KG+："&VLOOKUP("*"&$E$4&"*",'海运快递派'!$A$21:$F$24,3,0)," 51KG+："&VLOOKUP("*"&$E$4&"*",'海运快递派'!$A$21:$F$24,4,0)," 101KG+："&VLOOKUP("*"&$E$4&"*",'海运快递派'!$A$21:$F$24,5,0)),"-"))))))))))))),"-") | BN8: =IFERROR(IF($E$4="","-",IF(AND($G$4="卡派",$F$4="KG",$C$4="珠三角",$D$4="亚马逊"),VLOOKUP("*"&$E$4&"*",'美西特快专线'!$A$6:$R$18,18,0),IF(AND($G$4="卡派",$F$4="KG",$C$4="汕头仓",$D$4="亚马逊"),VLOOKUP("*"&$E$4&"*",'美西特快专线'!$A$6:$R$18,18,0),IF(AND($G$4="卡派",$F$4="KG",$C$4="义乌仓",$D$4="亚马逊"),VLOOKUP("*"&$E$4&"*",'美西特快专线'!$A$6:$R$18,18,0),IF(AND($G$4="卡派",$F$4="按方不包税",$C$4="珠三角",$D$4="亚马逊"),VLOOKUP("*"&$E$4&"*",'按方不包税'!$A$28:$E$34,4,0),IF(AND($G$4="卡派",$F$4="按方不包税",$C$4="汕头仓",$D$4="亚马逊"),VLOOKUP("*"&$E$4&"*",'按方不包税'!$A$28:$E$34,4,0),IF(AND($G$4="卡派",$F$4="按方不包税",$C$4="义乌仓",$D$4="亚马逊"),VLOOKUP("*"&$E$4&"*",'按方不包税'!$A$28:$E$34,4,0),IF(AND($G$4="卡派",$F$4="KG",$C$4="珠三角",$D$4="沃尔玛专线"),VLOOKUP("*"&$E$4&"*",'沃尔玛专线'!$A$10:$G$11,7,0),IF(AND($G$4="卡派",$F$4="KG",$C$4="汕头仓",$D$4="沃尔玛专线"),VLOOKUP("*"&$E$4&"*",'沃尔玛专线'!$A$10:$G$11,7,0),IF(AND($G$4="卡派",$F$4="KG",$C$4="义乌仓",$D$4="沃尔玛专线"),VLOOKUP("*"&$E$4&"*",'沃尔玛专线'!$A$10:$G$11,7,0),IF(AND($G$4="快递派",$F$4="KG",$C$4="珠三角",$D$4="亚马逊"),VLOOKUP("*"&$E$4&"*",'海运快递派'!$A$21:$F$24,6,0),IF(AND($G$4="快递派",$F$4="KG",$C$4="汕头仓",$D$4="亚马逊"),VLOOKUP("*"&$E$4&"*",'海运快递派'!$A$21:$F$24,6,0),IF(AND($G$4="快递派",$F$4="KG",$C$4="义乌仓",$D$4="亚马逊"),VLOOKUP("*"&$E$4&"*",'海运快递派'!$A$21:$F$24,6,0),"-"))))))))))))),"-") | BO8: =CONCATENATE('海运船期表'!$B$6,"-"&'海运船期表'!$C$6," : ",TEXT('海运船期表'!$I$6,"MM-DD")) | BP8: =CONCATENATE('海运船期表'!$B$6,"-"&'海运船期表'!$C$6," : ",TEXT('海运船期表'!$J$6,"MM-DD")) | BQ8: ='海运船期表'!$K$6
B9: 快船600 | C9: =BM9 | D9: =BN9 | E9: =BO9 | F9: =BP9 | G9: =BQ9 | BL9: 快船600 | BM9: =IFERROR(IF($E$4="","-",IF(AND($G$4="卡派",$F$4="KG",$C$4="珠三角",$D$4="亚马逊"),CONCATENATE("8KG+："&VLOOKUP("*"&$E$4&"*",'美西快船专线'!$A$7:$E$19,2,0)," 101KG+："&VLOOKUP("*"&$E$4&"*",'美西快船专线'!$A$7:$E$19,3,0)),IF(AND($G$4="卡派",$F$4="KG",$C$4="汕头仓",$D$4="亚马逊"),CONCATENATE("8KG+："&VLOOKUP("*"&$E$4&"*",'美西快船专线'!$A$7:$E$19,2,0)," 101KG+："&VLOOKUP("*"&$E$4&"*",'美西快船专线'!$A$7:$E$19,3,0)),IF(AND($G$4="卡派",$F$4="KG",$C$4="义乌仓",$D$4="亚马逊"),CONCATENATE("8KG+："&VLOOKUP("*"&$E$4&"*",'美西快船专线'!$A$7:$E$19,2,0)," 101KG+："&VLOOKUP("*"&$E$4&"*",'美西快船专线'!$A$7:$E$19,3,0)),IF(AND($G$4="卡派",$F$4="按方不包税",$C$4="珠三角",$D$4="亚马逊"),CONCATENATE("2CBM+："&VLOOKUP("*"&$E$4&"*",'按方不包税'!$A$40:$E$48,2,0)),IF(AND($G$4="卡派",$F$4="按方不包税",$C$4="汕头仓",$D$4="亚马逊"),CONCATENATE("2CBM+："&VLOOKUP("*"&$E$4&"*",'按方不包税'!$A$40:$E$48,2,0)),IF(AND($G$4="卡派",$F$4="按方不包税",$C$4="义乌仓",$D$4="亚马逊"),CONCATENATE("2CBM+："&VLOOKUP("*"&$E$4&"*",'按方不包税'!$A$40:$E$48,2,0)),IF(AND($G$4="卡派",$F$4="KG",$C$4="珠三角",$D$4="沃尔玛专线"),CONCATENATE("501KG+："&VLOOKUP("*"&$E$4&"*",'沃尔玛专线'!$A$12:$G$13,4,0)," 3001KG+："&VLOOKUP("*"&$E$4&"*",'沃尔玛专线'!$A$12:$G$13,5,0)," 5001KG+："&VLOOKUP("*"&$E$4&"*",'沃尔玛专线'!$A$12:$G$13,6,0)),IF(AND($G$4="卡派",$F$4="KG",$C$4="汕头仓",$D$4="沃尔玛专线"),CONCATENATE("501KG+："&VLOOKUP("*"&$E$4&"*",'沃尔玛专线'!$A$12:$G$13,7,0)," 3001KG+："&VLOOKUP("*"&$E$4&"*",'沃尔玛专线'!$A$12:$G$13,9,0)," 5001KG+："&VLOOKUP("*"&$E$4&"*",'沃尔玛专线'!$A$12:$G$13,9,0)),IF(AND($G$4="卡派",$F$4="KG",$C$4="义乌仓",$D$4="沃尔玛专线"),CONCATENATE("501KG+："&VLOOKUP("*"&$E$4&"*",'沃尔玛专线'!$A$12:$G$13,10,0)," 3001KG+："&VLOOKUP("*"&$E$4&"*",'沃尔玛专线'!$A$12:$G$13,11,0)," 5001KG+："&VLOOKUP("*"&$E$4&"*",'沃尔玛专线'!$A$12:$G$13,12,0)),IF(AND($G$4="快递派",$F$4="KG",$C$4="珠三角",$D$4="亚马逊"),CONCATENATE("12KG+："&VLOOKUP("*"&$E$4&"*",'海运快递派'!$A$29:$F$32,3,0)," 51KG+："&VLOOKUP("*"&$E$4&"*",'海运快递派'!$A$29:$F$32,4,0)," 101KG+："&VLOOKUP("*"&$E$4&"*",'海运快递派'!$A$29:$F$32,5,0)),IF(AND($G$4="快递派",$F$4="KG",$C$4="汕头仓",$D$4="亚马逊"),CONCATENATE("12KG+："&VLOOKUP("*"&$E$4&"*",'海运快递派'!$A$29:$F$32,3,0)," 51KG+："&VLOOKUP("*"&$E$4&"*",'海运快递派'!$A$29:$F$32,4,0)," 101KG+："&VLOOKUP("*"&$E$4&"*",'海运快递派'!$A$29:$F$32,5,0)),IF(AND($G$4="快递派",$F$4="KG",$C$4="义乌仓",$D$4="亚马逊"),CONCATENATE("12KG+："&VLOOKUP("*"&$E$4&"*",'海运快递派'!$A$29:$F$32,3,0)," 51KG+："&VLOOKUP("*"&$E$4&"*",'海运快递派'!$A$29:$F$32,4,0)," 101KG+："&VLOOKUP("*"&$E$4&"*",'海运快递派'!$A$29:$F$32,5,0)),"-"))))))))))))),"-") | BN9: =IFERROR(IF($E$4="","-",IF(AND($G$4="卡派",$F$4="KG",$C$4="珠三角",$D$4="亚马逊"),VLOOKUP("*"&$E$4&"*",'美西快船专线'!$A$7:$E$19,4,0),IF(AND($G$4="卡派",$F$4="KG",$C$4="汕头仓",$D$4="亚马逊"),VLOOKUP("*"&$E$4&"*",'美西快船专线'!$A$7:$E$19,4,0),IF(AND($G$4="卡派",$F$4="KG",$C$4="义乌仓",$D$4="亚马逊"),VLOOKUP("*"&$E$4&"*",'美西快船专线'!$A$7:$E$19,4,0),IF(AND($G$4="卡派",$F$4="按方不包税",$C$4="珠三角",$D$4="亚马逊"),VLOOKUP("*"&$E$4&"*",'按方不包税'!$A$40:$E$48,4,0),IF(AND($G$4="卡派",$F$4="按方不包税",$C$4="汕头仓",$D$4="亚马逊"),VLOOKUP("*"&$E$4&"*",'按方不包税'!$A$40:$E$48,4,0),IF(AND($G$4="卡派",$F$4="按方不包税",$C$4="义乌仓",$D$4="亚马逊"),VLOOKUP("*"&$E$4&"*",'按方不包税'!$A$40:$E$48,4,0),IF(AND($G$4="卡派",$F$4="KG",$C$4="珠三角",$D$4="沃尔玛专线"),VLOOKUP("*"&$E$4&"*",'沃尔玛专线'!$A$12:$G$13,7,0),IF(AND($G$4="卡派",$F$4="KG",$C$4="汕头仓",$D$4="沃尔玛专线"),VLOOKUP("*"&$E$4&"*",'沃尔玛专线'!$A$12:$G$13,7,0),IF(AND($G$4="卡派",$F$4="KG",$C$4="义乌仓",$D$4="沃尔玛专线"),VLOOKUP("*"&$E$4&"*",'沃尔玛专线'!$A$10:$G$11,7,0),IF(AND($G$4="快递派",$F$4="KG",$C$4="珠三角",$D$4="亚马逊"),VLOOKUP("*"&$E$4&"*",'海运快递派'!$A$29:$F$32,6,0),IF(AND($G$4="快递派",$F$4="KG",$C$4="汕头仓",$D$4="亚马逊"),VLOOKUP("*"&$E$4&"*",'海运快递派'!$A$29:$F$32,6,0),IF(AND($G$4="快递派",$F$4="KG",$C$4="义乌仓",$D$4="亚马逊"),VLOOKUP("*"&$E$4&"*",'海运快递派'!$A$29:$F$32,6,0),"-"))))))))))))),"-") | BO9: =CONCATENATE("①",'海运船期表'!$B$7,"-"&'海运船期表'!$C$7," : ",TEXT('海运船期表'!$I$7,"MM-DD")," ②",'海运船期表'!$B$8,"-"&'海运船期表'!$C$8," : ",TEXT('海运船期表'!$I$8,"MM-DD")," ③",'海运船期表'!$B$9,"-"&'海运船期表'!$C$9," : ",TEXT('海运船期表'!$I$9,"MM-DD")) | BP9: =CONCATENATE("①",'海运船期表'!$B$7,"-"&'海运船期表'!$C$7," : ",TEXT('海运船期表'!$J$7,"MM-DD")," ②",'海运船期表'!$B$8,"-"&'海运船期表'!$C$8," : ",TEXT('海运船期表'!$J$8,"MM-DD")," ③",'海运船期表'!$B$9,"-"&'海运船期表'!$C$9," : ",TEXT('海运船期表'!$J$9,"MM-DD")) | BQ9: =CONCATENATE("①："&'海运船期表'!$K$7," ②："&'海运船期表'!$K$8," ③："&'海运船期表'!$K$9)
B10: 奥克兰744 | C10: =BM10 | D10: =BN10 | E10: =BO10 | F10: =BP10 | G10: =BQ10 | BL10: 奥克兰744 | BM10: =IFERROR(IF($E$4="","-",IF(AND($G$4="卡派",$F$4="KG",$C$4="珠三角",$D$4="亚马逊"),CONCATENATE("8KG+："&VLOOKUP("*"&$E$4&"*",'美西普船专线'!$F$7:$I$10,2,0)," 101KG+："&VLOOKUP("*"&$E$4&"*",'美西普船专线'!$F$7:$I$10,3,0)),IF(AND($G$4="卡派",$F$4="KG",$C$4="汕头仓",$D$4="亚马逊"),CONCATENATE("8KG+："&VLOOKUP("*"&$E$4&"*",'美西普船专线'!$F$7:$I$10,2,0)," 101KG+："&VLOOKUP("*"&$E$4&"*",'美西普船专线'!$F$7:$I$10,3,0)),IF(AND($G$4="卡派",$F$4="KG",$C$4="义乌仓",$D$4="亚马逊"),CONCATENATE("8KG+："&VLOOKUP("*"&$E$4&"*",'美西普船专线'!$F$7:$I$10,2,0)," 101KG+："&VLOOKUP("*"&$E$4&"*",'美西普船专线'!$A$7:$D$10,3,0)),IF(AND($G$4="卡派",$F$4="按方不包税",$C$4="珠三角",$D$4="亚马逊"),CONCATENATE("2CBM+："&VLOOKUP("*"&$E$4&"*",'按方不包税'!$A$63:$E$65,2,0)),IF(AND($G$4="卡派",$F$4="按方不包税",$C$4="汕头仓",$D$4="亚马逊"),CONCATENATE("2CBM+："&VLOOKUP("*"&$E$4&"*",'按方不包税'!$A$63:$E$65,2,0)),IF(AND($G$4="卡派",$F$4="按方不包税",$C$4="义乌仓",$D$4="亚马逊"),CONCATENATE("2CBM+："&VLOOKUP("*"&$E$4&"*",'按方不包税'!$A$63:$E$65,2,0)),"-"))))))),"-") | BN10: =IFERROR(IF($E$4="","-",IF(AND($G$4="卡派",$F$4="KG",$C$4="珠三角",$D$4="亚马逊"),VLOOKUP("*"&$E$4&"*",'美西普船专线'!$F$7:$I$10,4,0),IF(AND($G$4="卡派",$F$4="KG",$C$4="汕头仓",$D$4="亚马逊"),VLOOKUP("*"&$E$4&"*",'美西普船专线'!$F$7:$I$10,4,0),IF(AND($G$4="卡派",$F$4="KG",$C$4="义乌仓",$D$4="亚马逊"),VLOOKUP("*"&$E$4&"*",'美西普船专线'!$F$7:$I$10,4,0),IF(AND($G$4="卡派",$F$4="按方不包税KG",$C$4="珠三角",$D$4="亚马逊"),VLOOKUP("*"&$E$4&"*",'按方不包税'!$A$63:$E$65,4,0),IF(AND($G$4="卡派",$F$4="按方不包税",$C$4="汕头仓",$D$4="亚马逊"),VLOOKUP("*"&$E$4&"*",'按方不包税'!$A$63:$E$65,4,0),IF(AND($G$4="卡派",$F$4="按方不包税2CBM+",$C$4="义乌仓",$D$4="亚马逊"),VLOOKUP("*"&$E$4&"*",'按方不包税'!$A$63:$E$65,4,0),"-"))))))),"-") | BO10: =CONCATENATE("①",'海运船期表'!$B$12,"-"&'海运船期表'!$C$12," : ",TEXT('海运船期表'!$I$12,"MM-DD")," ②",'海运船期表'!$B$13,"-"&'海运船期表'!$C$13," : ",TEXT('海运船期表'!$I$13,"MM-DD")) | BP10: =CONCATENATE("①",'海运船期表'!$B$12,"-"&'海运船期表'!$C$12," : ",TEXT('海运船期表'!$J$12,"MM-DD")," ②",'海运船期表'!$B$13,"-"&'海运船期表'!$C$13," : ",TEXT('海运船期表'!$J$13,"MM-DD")) | BQ10: =CONCATENATE("①："&'海运船期表'!$K$12," ②："&'海运船期表'!$K$13)
B11: 洛杉矶768 | C11: =BM11 | D11: =BN11 | E11: =BO11 | F11: =BP11 | G11: =BQ11 | BL11: 洛杉矶768 | BM11: =IFERROR(IF($E$4="","-",IF(AND($G$4="卡派",$F$4="KG",$C$4="珠三角",$D$4="亚马逊"),CONCATENATE("8KG+："&VLOOKUP("*"&$E$4&"*",'美西普船专线'!$A$7:$D$10,2,0)," 101KG+："&VLOOKUP("*"&$E$4&"*",'美西普船专线'!$A$7:$D$10,3,0)),IF(AND($G$4="卡派",$F$4="KG",$C$4="汕头仓",$D$4="亚马逊"),CONCATENATE("8KG+："&VLOOKUP("*"&$E$4&"*",'美西普船专线'!$A$7:$D$10,2,0)," 101KG+："&VLOOKUP("*"&$E$4&"*",'美西普船专线'!$A$7:$D$10,3,0)),IF(AND($G$4="卡派",$F$4="KG",$C$4="义乌仓",$D$4="亚马逊"),CONCATENATE("8KG+："&VLOOKUP("*"&$E$4&"*",'美西普船专线'!$A$7:$D$10,2,0)," 101KG+："&VLOOKUP("*"&$E$4&"*",'美西普船专线'!$A$7:$D$10,3,0)),IF(AND($G$4="卡派",$F$4="按方不包税",$C$4="珠三角",$D$4="亚马逊"),CONCATENATE("2CBM+："&VLOOKUP("*"&$E$4&"*",'按方不包税'!$A$54:$E$55,2,0)),IF(AND($G$4="卡派",$F$4="按方不包税",$C$4="汕头仓",$D$4="亚马逊"),CONCATENATE("2CBM+："&VLOOKUP("*"&$E$4&"*",'按方不包税'!$A$54:$E$55,2,0)),IF(AND($G$4="卡派",$F$4="按方不包税",$C$4="义乌仓",$D$4="亚马逊"),CONCATENATE("2CBM+："&VLOOKUP("*"&$E$4&"*",'按方不包税'!$A$54:$E$55,2,0)),"-"))))))),"-") | BN11: =IFERROR(IF($E$4="","-",IF(AND($G$4="卡派",$F$4="KG",$C$4="珠三角",$D$4="亚马逊"),VLOOKUP("*"&$E$4&"*",'美西普船专线'!$A$7:$D$10,4,0),IF(AND($G$4="卡派",$F$4="KG",$C$4="汕头仓",$D$4="亚马逊"),VLOOKUP("*"&$E$4&"*",'美西普船专线'!$A$7:$D$10,4,0),IF(AND($G$4="卡派",$F$4="KG",$C$4="义乌仓",$D$4="亚马逊"),VLOOKUP("*"&$E$4&"*",'美西普船专线'!$A$7:$D$10,4,0),IF(AND($G$4="卡派",$F$4="按方不包税",$C$4="珠三角",$D$4="亚马逊"),VLOOKUP("*"&$E$4&"*",'按方不包税'!$A$55:$E$56,4,0),IF(AND($G$4="卡派",$F$4="按方不包税",$C$4="汕头仓",$D$4="亚马逊"),VLOOKUP("*"&$E$4&"*",'按方不包税'!$A$55:$E$56,4,0),IF(AND($G$4="卡派",$F$4="按方不包税",$C$4="义乌仓",$D$4="亚马逊"),VLOOKUP("*"&$E$4&"*",'按方不包税'!$A$55:$E$56,4,0),"-"))))))),"-") | BO11: =CONCATENATE("①",'海运船期表'!$B$14,"-"&'海运船期表'!$C$14," : ",TEXT('海运船期表'!$I$14,"MM-DD")," ②",'海运船期表'!$B$15,"-"&'海运船期表'!$C$15," : ",TEXT('海运船期表'!$I$15,"MM-DD")," ③",'海运船期表'!$B$16,"-"&'海运船期表'!$C$16," : ",TEXT('海运船期表'!$I$16,"MM-DD")) | BP11: =CONCATENATE("①",'海运船期表'!$B$14,"-"&'海运船期表'!$C$14," : ",TEXT('海运船期表'!$J$14,"MM-DD")," ②",'海运船期表'!$B$15,"-"&'海运船期表'!$C$15," : ",TEXT('海运船期表'!$J$15,"MM-DD")," ③",'海运船期表'!$B$16,"-"&'海运船期表'!$C$16," : ",TEXT('海运船期表'!$J$16,"MM-DD")) | BQ11: =CONCATENATE("①："&'海运船期表'!$K$14," ②："&'海运船期表'!$K$15," ③："&'海运船期表'!$K$16)
B12: 西雅图788 | C12: =BM12 | D12: =BN12 | E12: =BO12 | F12: =BP12 | G12: =BQ12 | BL12: 西雅图788 | BM12: =IFERROR(IF($E$4="","-",IF(AND($G$4="卡派",$F$4="KG",$C$4="珠三角",$D$4="亚马逊"),CONCATENATE("8KG+："&VLOOKUP("*"&$E$4&"*",'美西普船专线'!$K$7:$N$10,2,0)," 101KG+："&VLOOKUP("*"&$E$4&"*",'美西普船专线'!$K$7:$N$10,3,0)),IF(AND($G$4="卡派",$F$4="KG",$C$4="汕头仓",$D$4="亚马逊"),CONCATENATE("8KG+："&VLOOKUP("*"&$E$4&"*",'美西普船专线'!$K$7:$N$10,2,0)," 101KG+："&VLOOKUP("*"&$E$4&"*",'美西普船专线'!$K$7:$N$10,3,0)),IF(AND($G$4="卡派",$F$4="KG",$C$4="义乌仓",$D$4="亚马逊"),CONCATENATE("8KG+："&VLOOKUP("*"&$E$4&"*",'美西普船专线'!$K$7:$N$10,2,0)," 101KG+："&VLOOKUP("*"&$E$4&"*",'美西普船专线'!$K$7:$N$10,3,0)),IF(AND($G$4="卡派",$F$4="按方不包税",$C$4="珠三角",$D$4="亚马逊"),CONCATENATE("2CBM+："&VLOOKUP("*"&$E$4&"*",'按方不包税'!$A$71:$E$74,2,0)),IF(AND($G$4="卡派",$F$4="按方不包税",$C$4="汕头仓",$D$4="亚马逊"),CONCATENATE("2CBM+："&VLOOKUP("*"&$E$4&"*",'按方不包税'!$A$71:$E$74,2,0)),IF(AND($G$4="卡派",$F$4="按方不包税",$C$4="义乌仓",$D$4="亚马逊"),CONCATENATE("2CBM+："&VLOOKUP("*"&$E$4&"*",'按方不包税'!$A$71:$E$74,2,0)),"-"))))))),"-") | BN12: =IFERROR(IF($E$4="","-",IF(AND($G$4="卡派",$F$4="KG",$C$4="珠三角",$D$4="亚马逊"),VLOOKUP("*"&$E$4&"*",'美西普船专线'!$K$7:$N$10,4,0),IF(AND($G$4="卡派",$F$4="KG",$C$4="汕头仓",$D$4="亚马逊"),VLOOKUP("*"&$E$4&"*",'美西普船专线'!$K$7:$N$10,4,0),IF(AND($G$4="卡派",$F$4="KG",$C$4="义乌仓",$D$4="亚马逊"),VLOOKUP("*"&$E$4&"*",'美西普船专线'!$K$7:$N$10,4,0),IF(AND($G$4="卡派",$F$4="按方不包税KG",$C$4="珠三角",$D$4="亚马逊"),VLOOKUP("*"&$E$4&"*",'按方不包税'!$B$72:$E$75,4,0),IF(AND($G$4="卡派",$F$4="按方不包税",$C$4="汕头仓",$D$4="亚马逊"),VLOOKUP("*"&$E$4&"*",'按方不包税'!$B$72:$E$75,5,0),IF(AND($G$4="卡派",$F$4="按方不包税2CBM+",$C$4="义乌仓",$D$4="亚马逊"),VLOOKUP("*"&$E$4&"*",'按方不包税'!$B$72:$E$75,4,0),"-"))))))),"-") | BO12: =CONCATENATE("①",'海运船期表'!$B$17,"-"&'海运船期表'!$C$17," : ",TEXT('海运船期表'!$I$17,"MM-DD")," ②",'海运船期表'!$B$18,"-"&'海运船期表'!$C$18," : ",TEXT('海运船期表'!$I$18,"MM-DD")) | BP12: =CONCATENATE("①",'海运船期表'!$B$17,"-"&'海运船期表'!$C$17," : ",TEXT('海运船期表'!$J$17,"MM-DD")," ②",'海运船期表'!$B$18,"-"&'海运船期表'!$C$18," : ",TEXT('海运船期表'!$J$18,"MM-DD")) | BQ12: =CONCATENATE("①："&'海运船期表'!$K$17," ②："&'海运船期表'!$K$18)
B13: 芝加哥840 | C13: =BM13 | D13: =BN13 | E13: =BO13 | F13: =BP13 | G13: =BQ13 | BL13: 芝加哥840 | BM13: =IFERROR(IF($E$4="","-",IF(AND($G$4="卡派",$F$4="KG",$C$4="珠三角",$D$4="亚马逊"),CONCATENATE("8KG+："&VLOOKUP("*"&$E$4&"*",'美中普船专线'!$A$7:$D$11,2,0)," 101KG+："&VLOOKUP("*"&$E$4&"*",'美中普船专线'!$A$7:$D$11,3,0)),IF(AND($G$4="卡派",$F$4="KG",$C$4="汕头仓",$D$4="亚马逊"),CONCATENATE("8KG+："&VLOOKUP("*"&$E$4&"*",'美中普船专线'!$A$7:$D$11,2,0)," 101KG+："&VLOOKUP("*"&$E$4&"*",'美中普船专线'!$A$7:$D$11,3,0)),IF(AND($G$4="卡派",$F$4="KG",$C$4="义乌仓",$D$4="亚马逊"),CONCATENATE("8KG+："&VLOOKUP("*"&$E$4&"*",'美中普船专线'!$A$7:$D$11,3,0)," 101KG+："&VLOOKUP("*"&$E$4&"*",'美中普船专线'!$A$7:$D$11,3,0)),IF(AND($G$4="卡派",$F$4="按方不包税",$C$4="珠三角",$D$4="亚马逊"),CONCATENATE("2CBM+："&VLOOKUP("*"&$E$4&"*",'按方不包税'!$A$80:$E$82,2,0)),IF(AND($G$4="卡派",$F$4="按方不包税",$C$4="汕头仓",$D$4="亚马逊"),CONCATENATE("2CBM+："&VLOOKUP("*"&$E$4&"*",'按方不包税'!$A$80:$E$82,2,0)),IF(AND($G$4="卡派",$F$4="按方不包税",$C$4="义乌仓",$D$4="亚马逊"),CONCATENATE("2CBM+："&VLOOKUP("*"&$E$4&"*",'按方不包税'!$A$80:$E$82,2,0)),IF(AND($G$4="卡派",$F$4="KG",$C$4="珠三角",$D$4="沃尔玛专线"),CONCATENATE("501KG+："&VLOOKUP("*"&$E$4&"*",'沃尔玛专线'!$A$14:$G$16,4,0)," 3001KG+："&VLOOKUP("*"&$E$4&"*",'沃尔玛专线'!$A$14:$G$16,5,0)," 5001KG+："&VLOOKUP("*"&$E$4&"*",'沃尔玛专线'!$A$14:$G$16,6,0)),IF(AND($G$4="卡派",$F$4="KG",$C$4="汕头仓",$D$4="沃尔玛专线"),CONCATENATE("501kg+："&VLOOKUP("*"&$E$4&"*",'沃尔玛专线'!$A$14:$G$16,7,0)," 3001kg+："&VLOOKUP("*"&$E$4&"*",'沃尔玛专线'!$A$14:$G$16,8,0)," 5001kg+："&VLOOKUP("*"&$E$4&"*",'沃尔玛专线'!$A$14:$G$16,9,0)),IF(AND($G$4="卡派",$F$4="KG",$C$4="义乌仓",$D$4="沃尔玛专线"),CONCATENATE("501KG+："&VLOOKUP("*"&$E$4&"*",'沃尔玛专线'!$A$14:$G$16,10,0)," 3001KG+："&VLOOKUP("*"&$E$4&"*",'沃尔玛专线'!$A$14:$G$16,11,0)," 5001KG+："&VLOOKUP("*"&$E$4&"*",'沃尔玛专线'!$A$14:$G$16,12,0)),"-")))))))))),"-") | BN13: =IFERROR(IF($E$4="","-",IF(AND($G$4="卡派",$F$4="KG",$C$4="珠三角",$D$4="亚马逊"),VLOOKUP("*"&$E$4&"*",'美中普船专线'!$A$7:$D$11,4,0),IF(AND($G$4="卡派",$F$4="KG",$C$4="汕头仓",$D$4="亚马逊"),VLOOKUP("*"&$E$4&"*",'美中普船专线'!$A$7:$D$11,4,0),IF(AND($G$4="卡派",$F$4="KG",$C$4="义乌仓",$D$4="亚马逊"),VLOOKUP("*"&$E$4&"*",'美中普船专线'!$A$7:$D$11,4,0),IF(AND($G$4="卡派",$F$4="按方不包税",$C$4="珠三角",$D$4="亚马逊"),VLOOKUP("*"&$E$4&"*",'按方不包税'!$A$81:$E$83,4,0),IF(AND($G$4="卡派",$F$4="按方不包税",$C$4="汕头仓",$D$4="亚马逊"),VLOOKUP("*"&$E$4&"*",'按方不包税'!$A$81:$E$83,4,0),IF(AND($G$4="卡派",$F$4="按方不包税",$C$4="义乌仓",$D$4="亚马逊"),VLOOKUP("*"&$E$4&"*",'按方不包税'!$A$81:$E$83,4,0),IF(AND($G$4="卡派",$F$4="KG",$C$4="珠三角",$D$4="沃尔玛专线"),VLOOKUP("*"&$E$4&"*",'沃尔玛专线'!$A$14:$G$16,7,0),IF(AND($G$4="卡派",$F$4="KG",$C$4="汕头仓",$D$4="沃尔玛专线"),VLOOKUP("*"&$E$4&"*",'沃尔玛专线'!$A$14:$G$16,7,0),IF(AND($G$4="卡派",$F$4="KG",$C$4="义乌仓",$D$4="沃尔玛专线"),VLOOKUP("*"&$E$4&"*",'沃尔玛专线'!$A$14:$G$16,7,0),"-")))))))))),"-") | BO13: =CONCATENATE("①",'海运船期表'!$B$19,"-"&'海运船期表'!$C$19," : ",TEXT('海运船期表'!$I$19,"MM-DD")," ②",'海运船期表'!$B$20,"-"&'海运船期表'!$C$20," : ",TEXT('海运船期表'!$I$20,"MM-DD")) | BP13: =CONCATENATE("①",'海运船期表'!$B$19,"-"&'海运船期表'!$C$19," : ",TEXT('海运船期表'!$J$19,"MM-DD")," ②",'海运船期表'!$B$20,"-"&'海运船期表'!$C$20," : ",TEXT('海运船期表'!$J$20,"MM-DD")) | BQ13: =CONCATENATE("①："&'海运船期表'!$K$19," ②："&'海运船期表'!$K$20)
B14: 休斯顿866 | C14: =BM14 | D14: =BN14 | E14: =BO14 | F14: =BP14 | G14: =BQ14 | BL14: 休斯顿866 | BM14: =IFERROR(IF($E$4="","-",IF(AND($G$4="卡派",$F$4="KG",$C$4="珠三角",$D$4="亚马逊"),CONCATENATE("8KG+："&VLOOKUP("*"&$E$4&"*",'美中普船专线'!$F$7:$I$11,2,0)," 101KG+："&VLOOKUP("*"&$E$4&"*",'美中普船专线'!$F$7:$I$11,3,0)),IF(AND($G$4="卡派",$F$4="KG",$C$4="汕头仓",$D$4="亚马逊"),CONCATENATE("8KG+："&VLOOKUP("*"&$E$4&"*",'美中普船专线'!$F$7:$I$11,2,0)," 101KG+："&VLOOKUP("*"&$E$4&"*",'美中普船专线'!$F$7:$I$11,3,0)),IF(AND($G$4="卡派",$F$4="KG",$C$4="义乌仓",$D$4="亚马逊"),CONCATENATE("8KG+："&VLOOKUP("*"&$E$4&"*",'美中普船专线'!$F$7:$I$11,2,0)," 101KG+："&VLOOKUP("*"&$E$4&"*",'美中普船专线'!$F$7:$I$11,3,0)),IF(AND($G$4="卡派",$F$4="按方不包税",$C$4="珠三角",$D$4="亚马逊"),CONCATENATE("2CBM+："&VLOOKUP("*"&$E$4&"*",'按方不包税'!$A$89:$E$91,2,0)),IF(AND($G$4="卡派",$F$4="按方不包税",$C$4="汕头仓",$D$4="亚马逊"),CONCATENATE("2CBM+："&VLOOKUP("*"&$E$4&"*",'按方不包税'!$A$89:$E$91,2,0)),IF(AND($G$4="卡派",$F$4="按方不包税",$C$4="义乌仓",$D$4="亚马逊"),CONCATENATE("2CBM+："&VLOOKUP("*"&$E$4&"*",'按方不包税'!$A$89:$E$91,3,0)),IF(AND($G$4="卡派",$F$4="KG",$C$4="珠三角",$D$4="沃尔玛专线"),CONCATENATE("501KG+："&VLOOKUP("*"&$E$4&"*",'沃尔玛专线'!$A$17:$G$17,4,0)," 3001KG+："&VLOOKUP("*"&$E$4&"*",'沃尔玛专线'!$A$17:$G$17,5,0)," 5001KG+："&VLOOKUP("*"&$E$4&"*",'沃尔玛专线'!$A$17:$G$17,6,0)),IF(AND($G$4="卡派",$F$4="KG",$C$4="汕头仓",$D$4="沃尔玛专线"),CONCATENATE("501kg+："&VLOOKUP("*"&$E$4&"*",'沃尔玛专线'!$A$17:$G$17,4,0)," 3001kg+："&VLOOKUP("*"&$E$4&"*",'沃尔玛专线'!$A$17:$G$17,5,0)," 5001kg+："&VLOOKUP("*"&$E$4&"*",'沃尔玛专线'!$A$17:$G$17,6,0)),IF(AND($G$4="卡派",$F$4="KG",$C$4="义乌仓",$D$4="沃尔玛专线"),CONCATENATE("501KG+："&VLOOKUP("*"&$E$4&"*",'沃尔玛专线'!$A$17:$G$17,4,0)," 3001KG+："&VLOOKUP("*"&$E$4&"*",'沃尔玛专线'!$A$17:$G$17,5,0)," 5001KG+："&VLOOKUP("*"&$E$4&"*",'沃尔玛专线'!$A$17:$G$17,6,0)),"-")))))))))),"-") | BN14: =IFERROR(IF($E$4="","-",IF(AND($G$4="卡派",$F$4="KG",$C$4="珠三角",$D$4="亚马逊"),VLOOKUP("*"&$E$4&"*",'美中普船专线'!$F$7:$I$11,4,0),IF(AND($G$4="卡派",$F$4="KG",$C$4="汕头仓",$D$4="亚马逊"),VLOOKUP("*"&$E$4&"*",'美中普船专线'!$F$7:$I$11,4,0),IF(AND($G$4="卡派",$F$4="KG",$C$4="义乌仓",$D$4="亚马逊"),VLOOKUP("*"&$E$4&"*",'美中普船专线'!$F$7:$I$11,4,0),IF(AND($G$4="卡派",$F$4="按方不包税",$C$4="珠三角",$D$4="亚马逊"),VLOOKUP("*"&$E$4&"*",'按方不包税'!$A$90:$E$92,4,0),IF(AND($G$4="卡派",$F$4="按方不包税",$C$4="汕头仓",$D$4="亚马逊"),VLOOKUP("*"&$E$4&"*",'按方不包税'!$A$90:$E$92,4,0),IF(AND($G$4="卡派",$F$4="按方不包税",$C$4="义乌仓",$D$4="亚马逊"),VLOOKUP("*"&$E$4&"*",'按方不包税'!$A$90:$E$92,4,0),IF(AND($G$4="卡派",$F$4="KG",$C$4="珠三角",$D$4="沃尔玛专线"),VLOOKUP("*"&$E$4&"*",'沃尔玛专线'!$A$17:$G$17,7,0),IF(AND($G$4="卡派",$F$4="KG",$C$4="汕头仓",$D$4="沃尔玛专线"),VLOOKUP("*"&$E$4&"*",'沃尔玛专线'!$A$17:$G$17,7,0),IF(AND($G$4="卡派",$F$4="KG",$C$4="义乌仓",$D$4="沃尔玛专线"),VLOOKUP("*"&$E$4&"*",'沃尔玛专线'!$A$17:$G$17,7,0),"-")))))))))),"-") | BO14: =CONCATENATE("①",'海运船期表'!$B$21,"-"&'海运船期表'!$C$21," : ",TEXT('海运船期表'!$I$21,"MM-DD")," ②",'海运船期表'!$B$22,"-"&'海运船期表'!$C$22," : ",TEXT('海运船期表'!$I$22,"MM-DD")) | BP14: =CONCATENATE("①",'海运船期表'!$B$21,"-"&'海运船期表'!$C$21," : ",TEXT('海运船期表'!$J$21,"MM-DD")," ②",'海运船期表'!$B$22,"-"&'海运船期表'!$C$22," : ",TEXT('海运船期表'!$J$22,"MM-DD")) | BQ14: =CONCATENATE("①："&'海运船期表'!$K$21," ②："&'海运船期表'!$K$22)
B15: 萨凡纳888 | C15: =BM15 | D15: =BN15 | E15: =BO15 | F15: =BP15 | G15: =BQ15 | BL15: 萨凡纳888 | BM15: =IFERROR(IF($E$4="","-",IF(AND($G$4="卡派",$F$4="KG",$C$4="珠三角",$D$4="亚马逊"),CONCATENATE("8KG+："&VLOOKUP("*"&$E$4&"*",'美东普船专线'!$A$7:$D$12,2,0)," 101KG+："&VLOOKUP("*"&$E$4&"*",'美东普船专线'!$A$7:$D$12,3,0)),IF(AND($G$4="卡派",$F$4="KG",$C$4="汕头仓",$D$4="亚马逊"),CONCATENATE("8KG+："&VLOOKUP("*"&$E$4&"*",'美东普船专线'!$A$7:$D$12,2,0)," 101KG+："&VLOOKUP("*"&$E$4&"*",'美东普船专线'!$A$7:$D$12,3,0)),IF(AND($G$4="卡派",$F$4="KG",$C$4="义乌仓",$D$4="亚马逊"),CONCATENATE("8KG+："&VLOOKUP("*"&$E$4&"*",'美东普船专线'!$A$7:$D$12,2,0)," 101KG+："&VLOOKUP("*"&$E$4&"*",'美东普船专线'!$A$7:$D$12,3,0)),IF(AND($G$4="卡派",$F$4="按方不包税",$C$4="珠三角",$D$4="亚马逊"),CONCATENATE("2CBM+："&VLOOKUP("*"&$E$4&"*",'按方不包税'!$A$98:$E$100,2,0)),IF(AND($G$4="卡派",$F$4="按方不包税",$C$4="汕头仓",$D$4="亚马逊"),CONCATENATE("2CBM+："&VLOOKUP("*"&$E$4&"*",'按方不包税'!$A$98:$E$100,2,0)),IF(AND($G$4="卡派",$F$4="按方不包税",$C$4="义乌仓",$D$4="亚马逊"),CONCATENATE("2CBM+："&VLOOKUP("*"&$E$4&"*",'按方不包税'!$A$98:$E$100,2,0)),"-"))))))),"-") | BN15: =IFERROR(IF($E$4="","-",IF(AND($G$4="卡派",$F$4="KG",$C$4="珠三角",$D$4="亚马逊"),VLOOKUP("*"&$E$4&"*",'美东普船专线'!$A$7:$D$12,4,0),IF(AND($G$4="卡派",$F$4="KG",$C$4="汕头仓",$D$4="亚马逊"),VLOOKUP("*"&$E$4&"*",'美东普船专线'!$A$7:$D$12,4,0),IF(AND($G$4="卡派",$F$4="KG",$C$4="义乌仓",$D$4="亚马逊"),VLOOKUP("*"&$E$4&"*",'美东普船专线'!$A$7:$D$12,4,0),IF(AND($G$4="卡派",$F$4="按方不包税",$C$4="珠三角",$D$4="亚马逊"),VLOOKUP("*"&$E$4&"*",'按方不包税'!$A$98:$E$100,4,0),IF(AND($G$4="卡派",$F$4="按方不包税",$C$4="汕头仓",$D$4="亚马逊"),VLOOKUP("*"&$E$4&"*",'按方不包税'!$A$98:$E$100,4,0),IF(AND($G$4="卡派",$F$4="按方不包税",$C$4="义乌仓",$D$4="亚马逊"),VLOOKUP("*"&$E$4&"*",'按方不包税'!$A$98:$E$100,4,0),"-"))))))),"-") | BO15: =CONCATENATE("①",'海运船期表'!$B$23,"-"&'海运船期表'!$C$23," : ",TEXT('海运船期表'!$I$23,"MM-DD")," ②",'海运船期表'!$B$24,"-"&'海运船期表'!$C$24," : ",TEXT('海运船期表'!$I$24,"MM-DD")) | BP15: =CONCATENATE("①",'海运船期表'!$B$23,"-"&'海运船期表'!$C$23," : ",TEXT('海运船期表'!$J$23,"MM-DD")," ②",'海运船期表'!$B$24,"-"&'海运船期表'!$C$24," : ",TEXT('海运船期表'!$J$24,"MM-DD")) | BQ15: =CONCATENATE("①："&'海运船期表'!$K$23," ②："&'海运船期表'!$K$24)
B16: 纽约960 | C16: =BM16 | D16: =BN16 | E16: =BO16 | F16: =BP16 | G16: =BQ16 | BL16: 纽约960 | BM16: =IFERROR(IF($E$4="","-",IF(AND($G$4="卡派",$F$4="KG",$C$4="珠三角",$D$4="亚马逊"),CONCATENATE("8KG+："&VLOOKUP("*"&$E$4&"*",'美东普船专线'!$F$7:$I$13,2,0)," 101KG+："&VLOOKUP("*"&$E$4&"*",'美东普船专线'!$F$7:$I$13,3,0)),IF(AND($G$4="卡派",$F$4="KG",$C$4="汕头仓",$D$4="亚马逊"),CONCATENATE("8KG+："&VLOOKUP("*"&$E$4&"*",'美东普船专线'!$F$7:$I$13,2,0)," 101KG+："&VLOOKUP("*"&$E$4&"*",'美东普船专线'!$F$7:$I$13,3,0)),IF(AND($G$4="卡派",$F$4="KG",$C$4="义乌仓",$D$4="亚马逊"),CONCATENATE("8KG+："&VLOOKUP("*"&$E$4&"*",'美东普船专线'!$F$7:$I$13,2,0)," 101KG+："&VLOOKUP("*"&$E$4&"*",'美东普船专线'!$F$7:$I$13,3,0)),IF(AND($G$4="卡派",$F$4="按方不包税",$C$4="珠三角",$D$4="亚马逊"),CONCATENATE("2BCM+："&VLOOKUP("*"&$E$4&"*",'按方不包税'!$A$104:$E$109,2,0)),IF(AND($G$4="卡派",$F$4="按方不包税",$C$4="汕头仓",$D$4="亚马逊"),CONCATENATE("2BCM+："&VLOOKUP("*"&$E$4&"*",'按方不包税'!$A$104:$E$109,2,0)),IF(AND($G$4="卡派",$F$4="按方不包税",$C$4="义乌仓",$D$4="亚马逊"),CONCATENATE("2BCM+："&VLOOKUP("*"&$E$4&"*",'按方不包税'!$A$104:$E$109,2,0)),IF(AND($G$4="卡派",$F$4="KG",$C$4="珠三角",$D$4="沃尔玛专线"),CONCATENATE("501KG+："&VLOOKUP("*"&$E$4&"*",'沃尔玛专线'!$A$20:$G$22,4,0)," 3001KG+："&VLOOKUP("*"&$E$4&"*",'沃尔玛专线'!$A$20:$G$22,5,0)," 5001KG+："&VLOOKUP("*"&$E$4&"*",'沃尔玛专线'!$A$20:$G$22,6,0)),IF(AND($G$4="卡派",$F$4="KG",$C$4="汕头仓",$D$4="沃尔玛专线"),CONCATENATE("501KG+："&VLOOKUP("*"&$E$4&"*",'沃尔玛专线'!$A$20:$G$22,4,0)," 3001KG+："&VLOOKUP("*"&$E$4&"*",'沃尔玛专线'!$A$20:$G$22,5,0)," 5001KG+："&VLOOKUP("*"&$E$4&"*",'沃尔玛专线'!$A$20:$G$22,6,0)),IF(AND($G$4="卡派",$F$4="KG",$C$4="义乌仓",$D$4="沃尔玛专线"),CONCATENATE("501KG+："&VLOOKUP("*"&$E$4&"*",'沃尔玛专线'!$A$20:$G$22,4,0)," 3001KG+："&VLOOKUP("*"&$E$4&"*",'沃尔玛专线'!$A$20:$G$22,5,0)," 5001KG+："&VLOOKUP("*"&$E$4&"*",'沃尔玛专线'!$A$20:$G$22,5,0)),IF(AND($G$4="快递派",$F$4="KG",$C$4="珠三角",$D$4="亚马逊"),CONCATENATE("12KG+："&VLOOKUP("*"&$E$4&"*",'海运快递派'!$A$37:$F$38,3,0)," 51KG+："&VLOOKUP("*"&$E$4&"*",'海运快递派'!$A$37:$F$38,4,0)," 101KG+："&VLOOKUP("*"&$E$4&"*",'海运快递派'!$A$37:$F$38,5,0)),IF(AND($G$4="快递派",$F$4="KG",$C$4="汕头仓",$D$4="亚马逊"),CONCATENATE("12KG+："&VLOOKUP("*"&$E$4&"*",'海运快递派'!$A$37:$F$38,3,0)," 51KG+："&VLOOKUP("*"&$E$4&"*",'海运快递派'!$A$37:$F$38,4,0)," 101KG+："&VLOOKUP("*"&$E$4&"*",'海运快递派'!$A$37:$F$38,5,0)),IF(AND($G$4="快递派",$F$4="KG",$C$4="义乌仓",$D$4="亚马逊"),CONCATENATE("12KG+："&VLOOKUP("*"&$E$4&"*",'海运快递派'!$A$37:$F$38,3,0)," 51KG+："&VLOOKUP("*"&$E$4&"*",'海运快递派'!$A$37:$F$38,4,0)," 101KG+："&VLOOKUP("*"&$E$4&"*",'海运快递派'!$A$37:$F$38,5,0)),"-"))))))))))))),"-") | BN16: =IFERROR(IF($E$4="","-",IF(AND($G$4="卡派",$F$4="KG",$C$4="珠三角",$D$4="亚马逊"),VLOOKUP("*"&$E$4&"*",'美东普船专线'!$F$7:$I$14,4,0),IF(AND($G$4="卡派",$F$4="KG",$C$4="汕头仓",$D$4="亚马逊"),VLOOKUP("*"&$E$4&"*",'美东普船专线'!$F$7:$I$14,4,0),IF(AND($G$4="卡派",$F$4="KG",$C$4="义乌仓",$D$4="亚马逊"),VLOOKUP("*"&$E$4&"*",'美东普船专线'!$F$7:$I$14,4,0),IF(AND($G$4="卡派",$F$4="按方不包税",$C$4="珠三角",$D$4="亚马逊"),VLOOKUP("*"&$E$4&"*",'按方不包税'!$A$104:$E$110,4,0),IF(AND($G$4="卡派",$F$4="按方不包税",$C$4="汕头仓",$D$4="亚马逊"),VLOOKUP("*"&$E$4&"*",'按方不包税'!$A$104:$E$110,4,0),IF(AND($G$4="卡派",$F$4="按方不包税",$C$4="义乌仓",$D$4="亚马逊"),VLOOKUP("*"&$E$4&"*",'按方不包税'!$A$104:$E$110,4,0),IF(AND($G$4="卡派",$F$4="KG",$C$4="珠三角",$D$4="沃尔玛专线"),VLOOKUP("*"&$E$4&"*",'沃尔玛专线'!$A$20:$G$22,7,0),IF(AND($G$4="卡派",$F$4="KG",$C$4="汕头仓",$D$4="沃尔玛专线"),VLOOKUP("*"&$E$4&"*",'沃尔玛专线'!$A$20:$G$22,7,0),IF(AND($G$4="卡派",$F$4="KG",$C$4="义乌仓",$D$4="沃尔玛专线"),VLOOKUP("*"&$E$4&"*",'沃尔玛专线'!$A$20:$G$22,7,0),IF(AND($G$4="快递派",$F$4="KG",$C$4="珠三角",$D$4="亚马逊"),VLOOKUP("*"&$E$4&"*",'海运快递派'!$A$37:$F$38,6,0),IF(AND($G$4="快递派",$F$4="KG",$C$4="汕头仓",$D$4="亚马逊"),VLOOKUP("*"&$E$4&"*",'海运快递派'!$A$37:$F$38,6,0),IF(AND($G$4="快递派",$F$4="KG",$C$4="义乌仓",$D$4="亚马逊"),VLOOKUP("*"&$E$4&"*",'海运快递派'!$A$37:$F$38,6,0),"-"))))))))))))),"-") | BO16: =CONCATENATE("①",'海运船期表'!$B$25,"-"&'海运船期表'!$C$25," : ",TEXT('海运船期表'!$I$25,"MM-DD")," ②",'海运船期表'!$B$26,"-"&'海运船期表'!$C$26," : ",TEXT('海运船期表'!$I$26,"MM-DD")) | BP16: =CONCATENATE("①",'海运船期表'!$B$25,"-"&'海运船期表'!$C$25," : ",TEXT('海运船期表'!$J$25,"MM-DD")," ②",'海运船期表'!$B$26,"-"&'海运船期表'!$C$26," : ",TEXT('海运船期表'!$J$26,"MM-DD")) | BQ16: =CONCATENATE("①："&'海运船期表'!$K$25," ②："&'海运船期表'!$K$26)
B17: TY720-玩具专线 | C17: =BM17 | D17: =BN17 | E17: =BO17 | F17: =BP17 | G17: =BQ17 | BL17: TY720 | BM17: =IFERROR(IF($E$4="","-",IF(AND($G$4="卡派",$F$4="KG",$C$4="珠三角",$D$4="亚马逊"),CONCATENATE("8KG+："&VLOOKUP("*"&$E$4&"*",'普船玩具专线'!$A$5:$D$10,2,0)," 101KG+："&VLOOKUP("*"&$E$4&"*",'普船玩具专线'!$A$5:$D$10,3,0)),IF(AND($G$4="卡派",$F$4="KG",$C$4="汕头仓",$D$4="亚马逊"),CONCATENATE("8KG+："&VLOOKUP("*"&$E$4&"*",'普船玩具专线'!$A$5:$D$10,2,0)," 101KG+："&VLOOKUP("*"&$E$4&"*",'普船玩具专线'!$A$5:$D$10,3,0)),IF(AND($G$4="卡派",$F$4="KG",$C$4="义乌仓",$D$4="亚马逊"),CONCATENATE("8KG+："&VLOOKUP("*"&$E$4&"*",'普船玩具专线'!$A$5:$D$10,2,0)," 101KG+："&VLOOKUP("*"&$E$4&"*",'普船玩具专线'!$A$5:$D$10,3,0)),"-")))),"-") | BN17: =IFERROR(IF($E$4="","-",IF(AND($G$4="卡派",$F$4="KG",$C$4="珠三角",$D$4="亚马逊"),VLOOKUP("*"&$E$4&"*",'普船玩具专线'!$A$5:$D$10,4,0),IF(AND($G$4="卡派",$F$4="KG",$C$4="汕头仓",$D$4="亚马逊"),VLOOKUP("*"&$E$4&"*",'普船玩具专线'!$A$5:$D$10,4,0),IF(AND($G$4="卡派",$F$4="KG",$C$4="义乌仓",$D$4="亚马逊"),VLOOKUP("*"&$E$4&"*",'普船玩具专线'!$A$5:$D$10,4,0),"-")))),"-") | BO17: =CONCATENATE("①",'海运船期表'!$B$10,"-"&'海运船期表'!$C$10," : ",TEXT('海运船期表'!$I$10,"MM-DD")," ②",'海运船期表'!$B$11,"-"&'海运船期表'!$C$11," : ",TEXT('海运船期表'!$I$11,"MM-DD")) | BP17: =CONCATENATE("①",'海运船期表'!$B$10,"-"&'海运船期表'!$C$10," : ",TEXT('海运船期表'!$J$7,"MM-DD")," ②",'海运船期表'!$B$11,"-"&'海运船期表'!$C$11," : ",TEXT('海运船期表'!$J$11,"MM-DD")) | BQ17: =CONCATENATE("①："&'海运船期表'!$K$10," ②："&'海运船期表'!$K$11)
B18: 奥克兰744-玩具专线 | C18: =BM18 | D18: =BN18 | E18: =BO18 | F18: =BP18 | G18: =BQ18 | BL18: 奥克兰744 | BM18: =IFERROR(IF($E$4="","-",IF(AND($G$4="卡派",$F$4="KG",$C$4="珠三角",$D$4="亚马逊"),CONCATENATE("8KG+："&VLOOKUP("*"&$E$4&"*",'普船玩具专线'!$A$15:$D$17,2,0)," 101KG+："&VLOOKUP("*"&$E$4&"*",'普船玩具专线'!$A$15:$D$17,3,0)),IF(AND($G$4="卡派",$F$4="KG",$C$4="汕头仓",$D$4="亚马逊"),CONCATENATE("8KG+："&VLOOKUP("*"&$E$4&"*",'普船玩具专线'!$A$15:$D$17,2,0)," 101KG+："&VLOOKUP("*"&$E$4&"*",'普船玩具专线'!$A$15:$D$17,3,0)),IF(AND($G$4="卡派",$F$4="KG",$C$4="义乌仓",$D$4="亚马逊"),CONCATENATE("8KG+："&VLOOKUP("*"&$E$4&"*",'普船玩具专线'!$A$15:$D$17,2,0)," 101KG+："&VLOOKUP("*"&$E$4&"*",'普船玩具专线'!$A$15:$D$17,3,0)),"-")))),"-") | BN18: =IFERROR(IF($E$4="","-",IF(AND($G$4="卡派",$F$4="KG",$C$4="珠三角",$D$4="亚马逊"),VLOOKUP("*"&$E$4&"*",'普船玩具专线'!$A$15:$D$17,4,0),IF(AND($G$4="卡派",$F$4="KG",$C$4="汕头仓",$D$4="亚马逊"),VLOOKUP("*"&$E$4&"*",'普船玩具专线'!$A$15:$D$17,4,0),IF(AND($G$4="卡派",$F$4="KG",$C$4="义乌仓",$D$4="亚马逊"),VLOOKUP("*"&$E$4&"*",'普船玩具专线'!$A$15:$D$17,4,0),"-")))),"-") | BO18: =CONCATENATE("①",'海运船期表'!$B$12,"-"&'海运船期表'!$C$12," : ",TEXT('海运船期表'!$I$12,"MM-DD")," ②",'海运船期表'!$B$13,"-"&'海运船期表'!$C$13," : ",TEXT('海运船期表'!$I$13,"MM-DD")) | BP18: =CONCATENATE("①",'海运船期表'!$B$12,"-"&'海运船期表'!$C$12," : ",TEXT('海运船期表'!$J$12,"MM-DD")," ②",'海运船期表'!$B$13,"-"&'海运船期表'!$C$13," : ",TEXT('海运船期表'!$J$13,"MM-DD")) | BQ18: =CONCATENATE("①："&'海运船期表'!$K$12," ②："&'海运船期表'!$K$13)
B19: 芝加哥840-玩具专线 | C19: =BM19 | D19: =BN19 | E19: =BO19 | F19: =BP19 | G19: =BQ19 | BL19: 芝加哥840 | BM19: =IFERROR(IF($E$4="","-",IF(AND($G$4="卡派",$F$4="KG",$C$4="珠三角",$D$4="亚马逊"),CONCATENATE("8KG+："&VLOOKUP("*"&$E$4&"*",'普船玩具专线'!$A$22:$D$25,2,0)," 101KG+："&VLOOKUP("*"&$E$4&"*",'普船玩具专线'!$A$22:$D$25,3,0)),IF(AND($G$4="卡派",$F$4="KG",$C$4="汕头仓",$D$4="亚马逊"),CONCATENATE("8KG+："&VLOOKUP("*"&$E$4&"*",'普船玩具专线'!$A$22:$D$25,2,0)," 101KG+："&VLOOKUP("*"&$E$4&"*",'普船玩具专线'!$A$22:$D$25,3,0)),IF(AND($G$4="卡派",$F$4="KG",$C$4="义乌仓",$D$4="亚马逊"),CONCATENATE("8KG+："&VLOOKUP("*"&$E$4&"*",'普船玩具专线'!$A$22:$D$25,2,0)," 101KG+："&VLOOKUP("*"&$E$4&"*",'普船玩具专线'!$A$22:$D$25,3,0)),"-")))),"-") | BN19: =IFERROR(IF($E$4="","-",IF(AND($G$4="卡派",$F$4="KG",$C$4="珠三角",$D$4="亚马逊"),VLOOKUP("*"&$E$4&"*",'普船玩具专线'!$A$22:$D$25,4,0),IF(AND($G$4="卡派",$F$4="KG",$C$4="汕头仓",$D$4="亚马逊"),VLOOKUP("*"&$E$4&"*",'普船玩具专线'!$A$22:$D$25,4,0),IF(AND($G$4="卡派",$F$4="KG",$C$4="义乌仓",$D$4="亚马逊"),VLOOKUP("*"&$E$4&"*",'普船玩具专线'!$A$22:$D$25,4,0),"-")))),"-") | BO19: =CONCATENATE("①",'海运船期表'!$B$19,"-"&'海运船期表'!$C$19," : ",TEXT('海运船期表'!$I$19,"MM-DD")," ②",'海运船期表'!$B$20,"-"&'海运船期表'!$C$20," : ",TEXT('海运船期表'!$I$20,"MM-DD")) | BP19: =CONCATENATE("①",'海运船期表'!$B$19,"-"&'海运船期表'!$C$19," : ",TEXT('海运船期表'!$J$19,"MM-DD")," ②",'海运船期表'!$B$20,"-"&'海运船期表'!$C$20," : ",TEXT('海运船期表'!$J$20,"MM-DD")) | BQ19: =CONCATENATE("①："&'海运船期表'!$K$19," ②："&'海运船期表'!$K$20)
B20: 休斯顿866-玩具专线 | C20: =BM20 | D20: =BN20 | E20: =BO20 | F20: =BP20 | G20: =BQ20 | BL20: 休斯顿866 | BM20: =IFERROR(IF($E$4="","-",IF(AND($G$4="卡派",$F$4="KG",$C$4="珠三角",$D$4="亚马逊"),CONCATENATE("8KG+："&VLOOKUP("*"&$E$4&"*",'普船玩具专线'!$A$30:$D$32,2,0)," 101KG+："&VLOOKUP("*"&$E$4&"*",'普船玩具专线'!$A$30:$D$32,3,0)),IF(AND($G$4="卡派",$F$4="KG",$C$4="汕头仓",$D$4="亚马逊"),CONCATENATE("8KG+："&VLOOKUP("*"&$E$4&"*",'普船玩具专线'!$A$30:$D$32,2,0)," 101KG+："&VLOOKUP("*"&$E$4&"*",'普船玩具专线'!$A$30:$D$32,3,0)),IF(AND($G$4="卡派",$F$4="KG",$C$4="义乌仓",$D$4="亚马逊"),CONCATENATE("8KG+："&VLOOKUP("*"&$E$4&"*",'普船玩具专线'!$A$30:$D$32,2,0)," 101KG+："&VLOOKUP("*"&$E$4&"*",'普船玩具专线'!$A$30:$D$32,3,0)),"-")))),"-") | BN20: =IFERROR(IF($E$4="","-",IF(AND($G$4="卡派",$F$4="KG",$C$4="珠三角",$D$4="亚马逊"),VLOOKUP("*"&$E$4&"*",'普船玩具专线'!$A$31:$D$33,4,0),IF(AND($G$4="卡派",$F$4="KG",$C$4="汕头仓",$D$4="亚马逊"),VLOOKUP("*"&$E$4&"*",'普船玩具专线'!$A$31:$D$33,4,0),IF(AND($G$4="卡派",$F$4="KG",$C$4="义乌仓",$D$4="亚马逊"),VLOOKUP("*"&$E$4&"*",'普船玩具专线'!$A$31:$D$33,4,0),"-")))),"-") | BO20: =CONCATENATE("①",'海运船期表'!$B$21,"-"&'海运船期表'!$C$21," : ",TEXT('海运船期表'!$I$21,"MM-DD")," ②",'海运船期表'!$B$22,"-"&'海运船期表'!$C$22," : ",TEXT('海运船期表'!$I$22,"MM-DD")) | BP20: =CONCATENATE("①",'海运船期表'!$B$21,"-"&'海运船期表'!$C$21," : ",TEXT('海运船期表'!$J$21,"MM-DD")," ②",'海运船期表'!$B$22,"-"&'海运船期表'!$C$22," : ",TEXT('海运船期表'!$J$22,"MM-DD")) | BQ20: =CONCATENATE("①："&'海运船期表'!$K$21," ②："&'海运船期表'!$K$22)
B21: 萨凡纳888-玩具专线 | C21: =BM21 | D21: =BN21 | E21: =BO21 | F21: =BP21 | G21: =BQ21 | BL21: 萨凡纳888 | BM21: =IFERROR(IF($E$4="","-",IF(AND($G$4="卡派",$F$4="KG",$C$4="珠三角",$D$4="亚马逊"),CONCATENATE("8KG+："&VLOOKUP("*"&$E$4&"*",'普船玩具专线'!$A$37:$D$39,2,0)," 101KG+："&VLOOKUP("*"&$E$4&"*",'普船玩具专线'!$A$37:$D$39,3,0)),IF(AND($G$4="卡派",$F$4="KG",$C$4="汕头仓",$D$4="亚马逊"),CONCATENATE("8KG+："&VLOOKUP("*"&$E$4&"*",'普船玩具专线'!$A$37:$D$39,2,0)," 101KG+："&VLOOKUP("*"&$E$4&"*",'普船玩具专线'!$A$37:$D$39,3,0)),IF(AND($G$4="卡派",$F$4="KG",$C$4="义乌仓",$D$4="亚马逊"),CONCATENATE("8KG+："&VLOOKUP("*"&$E$4&"*",'普船玩具专线'!$A$37:$D$39,2,0)," 101KG+："&VLOOKUP("*"&$E$4&"*",'普船玩具专线'!$A$37:$D$39,3,0)),"-")))),"-") | BN21: =IFERROR(IF($E$4="","-",IF(AND($G$4="卡派",$F$4="KG",$C$4="珠三角",$D$4="亚马逊"),VLOOKUP("*"&$E$4&"*",'普船玩具专线'!$A$37:$D$39,4,0),IF(AND($G$4="卡派",$F$4="KG",$C$4="汕头仓",$D$4="亚马逊"),VLOOKUP("*"&$E$4&"*",'普船玩具专线'!$A$37:$D$39,4,0),IF(AND($G$4="卡派",$F$4="KG",$C$4="义乌仓",$D$4="亚马逊"),VLOOKUP("*"&$E$4&"*",'普船玩具专线'!$A$37:$D$39,4,0),"-")))),"-") | BO21: =CONCATENATE("①",'海运船期表'!$B$23,"-"&'海运船期表'!$C$23," : ",TEXT('海运船期表'!$I$23,"MM-DD")," ②",'海运船期表'!$B$24,"-"&'海运船期表'!$C$24," : ",TEXT('海运船期表'!$I$24,"MM-DD")) | BP21: =CONCATENATE("①",'海运船期表'!$B$23,"-"&'海运船期表'!$C$23," : ",TEXT('海运船期表'!$J$23,"MM-DD")," ②",'海运船期表'!$B$24,"-"&'海运船期表'!$C$24," : ",TEXT('海运船期表'!$J$24,"MM-DD")) | BQ21: =CONCATENATE("①："&'海运船期表'!$K$23," ②："&'海运船期表'!$K$24)
B22: 纽约960-玩具专线 | C22: =BM22 | D22: =BN22 | E22: =BO22 | F22: =BP22 | G22: =BQ22 | BL22: 纽约960 | BM22: =IFERROR(IF($E$4="","-",IF(AND($G$4="卡派",$F$4="KG",$C$4="珠三角",$D$4="亚马逊"),CONCATENATE("8KG+："&VLOOKUP("*"&$E$4&"*",'普船玩具专线'!$A$44:$D$49,2,0)," 101KG+："&VLOOKUP("*"&$E$4&"*",'普船玩具专线'!$A$44:$D$49,3,0)),IF(AND($G$4="卡派",$F$4="KG",$C$4="汕头仓",$D$4="亚马逊"),CONCATENATE("8KG+："&VLOOKUP("*"&$E$4&"*",'普船玩具专线'!$A$44:$D$49,2,0)," 101KG+："&VLOOKUP("*"&$E$4&"*",'普船玩具专线'!$A$44:$D$49,3,0)),IF(AND($G$4="卡派",$F$4="KG",$C$4="义乌仓",$D$4="亚马逊"),CONCATENATE("8KG+："&VLOOKUP("*"&$E$4&"*",'普船玩具专线'!$A$44:$D$49,3,0)," 101KG+："&VLOOKUP("*"&$E$4&"*",'普船玩具专线'!$A$44:$D$49,3,0)),IF(AND($G$4="快递派",$F$4="KG",$C$4="珠三角",$D$4="亚马逊"),CONCATENATE("12KG+："&VLOOKUP("*"&$E$4&"*",'海运快递派'!$A$37:$F$38,3,0)," 51KG+："&VLOOKUP("*"&$E$4&"*",'海运快递派'!$A$37:$F$38,4,0)," 101KG+："&VLOOKUP("*"&$E$4&"*",'海运快递派'!$A$37:$F$38,5,0)),IF(AND($G$4="快递派",$F$4="KG",$C$4="汕头仓",$D$4="亚马逊"),CONCATENATE("12KG+："&VLOOKUP("*"&$E$4&"*",'海运快递派'!$A$37:$F$38,3,0)," 51KG+："&VLOOKUP("*"&$E$4&"*",'海运快递派'!$A$37:$F$38,4,0)," 101KG+："&VLOOKUP("*"&$E$4&"*",'海运快递派'!$A$37:$F$38,5,0)),IF(AND($G$4="快递派",$F$4="KG",$C$4="义乌仓",$D$4="亚马逊"),CONCATENATE("12KG+："&VLOOKUP("*"&$E$4&"*",'海运快递派'!$A$37:$F$38,3,0)," 51KG+："&VLOOKUP("*"&$E$4&"*",'海运快递派'!$A$37:$F$38,4,0)," 101KG+："&VLOOKUP("*"&$E$4&"*",'海运快递派'!$A$37:$F$38,5,0)),"-"))))))),"-") | BN22: =IFERROR(IF($E$4="","-",IF(AND($G$4="卡派",$F$4="KG",$C$4="珠三角",$D$4="亚马逊"),VLOOKUP("*"&$E$4&"*",'普船玩具专线'!$A$44:$D$49,4,0),IF(AND($G$4="卡派",$F$4="KG",$C$4="汕头仓",$D$4="亚马逊"),VLOOKUP("*"&$E$4&"*",'普船玩具专线'!$A$44:$D$49,4,0),IF(AND($G$4="卡派",$F$4="KG",$C$4="义乌仓",$D$4="亚马逊"),VLOOKUP("*"&$E$4&"*",'普船玩具专线'!$A$44:$D$49,4,0),IF(AND($G$4="快递派",$F$4="KG",$C$4="珠三角",$D$4="亚马逊"),VLOOKUP("*"&$E$4&"*",'海运快递派'!$A$37:$F$38,6,0),IF(AND($G$4="快递派",$F$4="KG",$C$4="汕头仓",$D$4="亚马逊"),VLOOKUP("*"&$E$4&"*",'海运快递派'!$A$37:$F$38,6,0),IF(AND($G$4="快递派",$F$4="KG",$C$4="义乌仓",$D$4="亚马逊"),VLOOKUP("*"&$E$4&"*",'海运快递派'!$A$37:$F$38,6,0),"-"))))))),"-") | BO22: =CONCATENATE("①",'海运船期表'!$B$25,"-"&'海运船期表'!$C$25," : ",TEXT('海运船期表'!$I$25,"MM-DD")," ②",'海运船期表'!$B$26,"-"&'海运船期表'!$C$26," : ",TEXT('海运船期表'!$I$26,"MM-DD")) | BP22: =CONCATENATE("①",'海运船期表'!$B$25,"-"&'海运船期表'!$C$25," : ",TEXT('海运船期表'!$J$25,"MM-DD")," ②",'海运船期表'!$B$26,"-"&'海运船期表'!$C$26," : ",TEXT('海运船期表'!$J$26,"MM-DD")) | BQ22: =CONCATENATE("①："&'海运船期表'!$K$25," ②："&'海运船期表'!$K$26)

Sheet 美西特快专线
A2: 美森360 | I2: 美森432 | P2: EX456
A3: 热门卡派仓 | I3: 热门卡派仓 | P3: 热门卡派仓
B4: 珠三角/汕头交货价 | D4: 义乌交货价 | I4: 珠三角/汕头交货价 | K4: 义乌交货价 | P4: 珠三角/汕头/义乌交货价
A5: 仓库 重量段 | B5: 8KG+ | C5: 101KG+ | D5: 8KG+ | E5: 101KG+ | F5: 参考签收时效 （开船后） | G5: 理赔时效 （开船后第二天算起） | I5: 8KG+ | J5: 101KG+ | K5: 8KG+ | L5: 101KG+ | M5: 签收时效 （开船后） | N5: 理赔时效 （开船后第二天算起） | P5: 8KG+ | Q5: 101KG+ | R5: 签收时效 （开船后） | S5: 理赔时效 （开船后第二天算起）
A6: ONT8,LAX9,LGB8 | B6: 10.5 | C6: 10 | D6: 10.2 | E6: 9.7 | F6: 12-16个自然日 | G6: 13个工作日 | I6: 10.2 | J6: 9.7 | K6: 9.9 | L6: 9.4 | M6: 14-18个自然日 | N6: 15个工作日 | P6: 6.1 | Q6: 5.6 | R6: 16-20个自然日 | S6: 18个工作日
A7: SBD1,POC1,POC3 | B7: 10.8 | C7: 10.3 | D7: 10.5 | E7: 10 | F7: 12-16个自然日 | G7: 14个工作日 | I7: 10.5 | J7: 10 | K7: 10.2 | L7: 9.7 | M7: 14-18个自然日 | N7: 16个工作日 | P7: 6.4 | Q7: 5.9 | R7: 16-20个自然日 | S7: 19个工作日
A8: GYR3,GYR2,LAS1,VGT2,SMF3,SCK4 | B8: 11.3 | C8: 10.8 | D8: 11 | E8: 10.5 | F8: 13-17个自然日 | G8: 15个工作日 | I8: 11 | J8: 10.5 | K8: 10.7 | L8: 10.2 | M8: 15-19个自然日 | N8: 17个工作日 | P8: 6.9 | Q8: 6.4 | R8: 17-21个自然日 | S8: 20个工作日
A9: MIT2,GEU3,GEU5,GEU2,HLI2,TCY1,TCY2 | B9: 11.3 | C9: 10.8 | D9: 11 | E9: 10.5 | F9: 13-17个自然日 | G9: 17个工作日 | I9: 11 | J9: 10.5 | K9: 10.7 | L9: 10.2 | M9: 15-19个自然日 | N9: 19个工作日 | P9: 6.9 | Q9: 6.4 | R9: 17-21个自然日 | S9: 22个工作日
A10: FTW1,ABQ2,IAH3,PSC2 | B10: 13.1 | C10: 12.6 | D10: 12.8 | E10: 12.3 | F10: 15-19个自然日 | G10: 18个工作日 | I10: 12.8 | J10: 12.3 | K10: 12.5 | L10: 12 | M10: 17-21个自然日 | N10: 20个工作日 | P10: 8.6 | Q10: 8.1 | R10: 20-24个自然日 | S10: 23个工作日
A11: MQJ1,MEM1,FWA4,MDW2,IND9 | B11: 13.6 | C11: 13.1 | D11: 13.3 | E11: 12.8 | F11: 16-21个自然日 | G11: 19个工作日 | I11: 13.3 | J11: 12.8 | K11: 13 | L11: 12.5 | M11: 18-23个自然日 | N11: 21个工作日 | P11: 9.1 | Q11: 8.6 | R11: 20-25个自然日 | S11: 24个工作日
A12: CLT2,RDU2 | B12: 14.3 | C12: 13.8 | D12: 14 | E12: 13.5 | F12: 21-26个自然日 | G12: 20个工作日 | I12: 14 | J12: 13.5 | K12: 13.7 | L12: 13.2 | M12: 23-28个自然日 | N12: 22个工作日 | P12: 9.8 | Q12: 9.3 | R12: 25-30个自然日 | S12: 25个工作日
A13: ORF2,RMN3,TEB3,TEB9,ABE8,AVP1,AVP3,SWF1,SWF2 | B13: 14.8 | C13: 14.3 | D13: 14.5 | E13: 14 | F13: 22-27个自然日 | G13: 22个工作日 | I13: 14.5 | J13: 14 | K13: 14.2 | L13: 13.7 | M13: 24-29个自然日 | N13: 24个工作日 | P13: 10.3 | Q13: 9.8 | R13: 26-31个自然日 | S13: 27个工作日
A14: JOT1,POC2,IUSP,IUSQ,IUTI,IUSJ,IUSW,IUTF | B14: 10.8 | C14: 10.3 | D14: 10.5 | E14: 10 | F14: 13-17个自然日 | G14: 不参与时效延误赔付 | I14: 10.5 | J14: 10 | K14: 10.2 | L14: 9.7 | M14: 15-19个自然日 | N14: 不参与时效延误赔付 | P14: 6.4 | Q14: 5.9 | R14: 17-21个自然日 | S14: 不参与时效延误赔付
A15: SCK8,QXY5,QXY8,IUTE,MCC1,PSP3 | B15: 11.3 | C15: 10.8 | D15: 11 | E15: 10.5 | F15: 15-19个自然日 | G15: 不参与时效延误赔付 | I15: 11 | J15: 10.5 | K15: 10.7 | L15: 10.2 | M15: 17-21个自然日 | N15: 不参与时效延误赔付 | P15: 6.9 | Q15: 6.4 | R15: 19-23个自然日 | S15: 不参与时效延误赔付
A16: AMA1,SAT1,SAT4 | B16: 13.1 | C16: 12.6 | D16: 12.8 | E16: 12.3 | F16: 16-20个自然日 | G16: 不参与时效延误赔付 | I16: 12.8 | J16: 12.3 | K16: 12.5 | L16: 12 | M16: 18-22个自然日 | N16: 不参与时效延误赔付 | P16: 8.6 | Q16: 8.1 | R16: 20-24个自然日 | S16: 不参与时效延误赔付
A17: RFD2 | B17: 13.6 | C17: 13.1 | D17: 13.3 | E17: 12.8 | F17: 17-22个自然日 | G17: 不参与时效延误赔付 | I17: 13.3 | J17: 12.8 | K17: 13 | L17: 12.5 | M17: 19-24个自然日 | N17: 不参与时效延误赔付 | P17: 9.1 | Q17: 8.6 | R17: 21-26个自然日 | S17: 不参与时效延误赔付
A18: TPA2,TPA3 | B18: 14.3 | C18: 13.8 | D18: 14 | E18: 13.5 | F18: 22-27个自然日 | G18: 不参与时效延误赔付 | I18: 14 | J18: 13.5 | K18: 13.7 | L18: 13.2 | M18: 24-29个自然日 | N18: 不参与时效延误赔付 | P18: 9.8 | Q18: 9.3 | R18: 26-31个自然日 | S18: 不参与时效延误赔付
A19: 其他未开放卡派仓单询 | I19: 其他未开放卡派仓单询 | P19: 其他未开放卡派仓单询
